Workbook

Sheet モンスター
A1: ID | B1: 名前 | C1: 属性 | D1: 攻撃方式 | E1: 基礎HP | F1: 基礎MP | G1: 基礎攻撃力 | H1: 基礎魔力 | I1: 基礎防御力 | J1: 基礎魔防 | K1: クリ率 | L1: クリ倍 | M1: 移動速度 | N1: 攻撃速度 | O1: 攻撃範囲 | P1: 火耐性 | Q1: 水耐性 | R1: 風耐性 | S1: 雷耐性 | T1: 光耐性 | U1: 闇耐性 | V1: 索敵範囲 | W1: リス秒 | X1: 素材ID | Y1: 素材名 | Z1: 素材ドロ率 | AA1: 経験値 | AB1: 配合用値 | AC1: 出現ステージ | AD1: 魔弾Prefab名 | AE1: 魔弾速度 | AF1: 魔弾寿命秒数 | AG1: 魔弾追尾 | AH1: 称号ID | AI1: SkillIds
A2: MON_001 | B2: ブルースライム | C2: 水 | D2: Ranged | E2: =+[1]モンスター計算!E5 -> 82 | F2: =+[1]モンスター計算!F5 -> 13 | G2: =+[1]モンスター計算!G5 -> 10 | H2: =+[1]モンスター計算!H5 -> 22 | I2: =+[1]モンスター計算!I5 -> 7 | J2: =+[1]モンスター計算!J5 -> 8 | K2: =+[1]モンスター計算!K5 -> 0.05 | L2: =+[1]モンスター計算!L5 -> 1.5 | ... V2: =+[1]モンスター計算!V5 -> 4 | W2: 8 | X2: MAT_001 | Y2: 蒼澄の粘晶 | Z2: 1.2 | AA2: 5 | AB2: 10 | AC2: 1 | AD2: WaterBall | AE2: 7 | AF2: 3 | AG2: TRUE | AH2: TITLE_001 | AI2: 1;2;3;4;5;6;7;8;9;10;12;11;13;14;15;16;17;18;19;20;21;22;23;24;25;26;27;28;29;30;31;32;33;34;35;36;37;38
A3: MON_002 | B3: レッドスライム | C3: 火 | D3: Ranged | E3: =+[1]モンスター計算!E6 -> 112 | F3: =+[1]モンスター計算!F6 -> 20 | G3: =+[1]モンスター計算!G6 -> 5 | H3: =+[1]モンスター計算!H6 -> 16 | I3: =+[1]モンスター計算!I6 -> 16 | J3: =+[1]モンスター計算!J6 -> 6 | K3: =+[1]モンスター計算!K6 -> 0.055 | L3: =+[1]モンスター計算!L6 -> 1.5 | ... V3: =+[1]モンスター計算!V6 -> 4.2 | W3: 8 | X3: MAT_002 | Y3: 灼熱の粘晶 | Z3: 1.2 | AA3: 7 | AB3: 12 | AC3: 1 | AD3: FireBall | AE3: 7.5 | AF3: 3 | AG3: TRUE | AH3: TITLE_002 | AI3: 1;2;3;4;5;6;7;8;9;10;12;11
A4: MON_003 | B4: グリーンスライム | C4: 風 | D4: Ranged | E4: =+[1]モンスター計算!E7 -> 92 | F4: =+[1]モンスター計算!F7 -> 15 | G4: =+[1]モンスター計算!G7 -> 8 | H4: =+[1]モンスター計算!H7 -> 18 | I4: =+[1]モンスター計算!I7 -> 8 | J4: =+[1]モンスター計算!J7 -> 8 | K4: =+[1]モンスター計算!K7 -> 0.05 | L4: =+[1]モンスター計算!L7 -> 1.5 | ... V4: =+[1]モンスター計算!V7 -> 4 | W4: 9 | X4: MAT_003 | Y4: 翠命の粘晶 | Z4: 1.22 | AA4: 10 | AB4: 15 | AC4: 1 | AD4: WindBall | AE4: 8.5 | AF4: 3 | AG4: TRUE | AH4: TITLE_003 | AI4: 1;2;3;4;5;6;7;8;9;10;12;11
A5: MON_004 | B5: レッドボア | C5: 火 | D5: Melee | E5: =+[1]モンスター計算!E8 -> 127 | F5: =+[1]モンスター計算!F8 -> 5 | G5: =+[1]モンスター計算!G8 -> 27 | H5: =+[1]モンスター計算!H8 -> 8 | I5: =+[1]モンスター計算!I8 -> 8 | J5: =+[1]モンスター計算!J8 -> 7 | K5: =+[1]モンスター計算!K8 -> 0.06 | L5: =+[1]モンスター計算!L8 -> 2.15 | ... V5: =+[1]モンスター計算!V8 -> 4.4 | W5: 10 | X5: MAT_004 | Y5: 炎牙獣の猛牙 | Z5: 1.25 | AA5: 15 | AB5: 20 | AC5: 1 | AD5: None | AE5: 0 | AF5: 0 | AG5: FALSE | AH5: TITLE_004 | AI5: 1;2;3;4;5;6;7;8;9;10;12;11
A6: MON_005 | B6: ブルーボア | C6: 水 | D6: Melee | E6: =+[1]モンスター計算!E9 -> 92 | F6: =+[1]モンスター計算!F9 -> 6 | G6: =+[1]モンスター計算!G9 -> 22 | H6: =+[1]モンスター計算!H9 -> 8 | I6: =+[1]モンスター計算!I9 -> 7 | J6: =+[1]モンスター計算!J9 -> 7 | K6: =+[1]モンスター計算!K9 -> 0.07 | L6: =+[1]モンスター計算!L9 -> 1.6 | ... V6: =+[1]モンスター計算!V9 -> 5.6 | W6: 11 | X6: MAT_005 | Y6: 氷牙獣の凍牙 | Z6: 1.25 | AA6: 20 | AB6: 25 | AC6: 1 | AD6: None | AE6: 0 | AF6: 0 | AG6: FALSE | AH6: TITLE_005 | AI6: 1;2;3;4;5;6;7;8;9;10;12;11
A7: MON_006 | B7: スライムフォース | C7: 光 | D7: Ranged | E7: =+[1]モンスター計算!E10 -> 172 | F7: =+[1]モンスター計算!F10 -> 20 | G7: =+[1]モンスター計算!G10 -> 4 | H7: =+[1]モンスター計算!H10 -> 14 | I7: =+[1]モンスター計算!I10 -> 13 | J7: =+[1]モンスター計算!J10 -> 12 | K7: =+[1]モンスター計算!K10 -> 0.035 | L7: =+[1]モンスター計算!L10 -> 1.4 | ... V7: =+[1]モンスター計算!V10 -> 4.12 | W7: 15 | X7: MAT_006 | Y7: 虹幻の粘晶 | Z7: 1.3 | AA7: 40 | AB7: 40 | AC7: 1 | AD7: LightBall | AE7: 10 | AF7: 4 | AG7: TRUE | AH7: TITLE_006 | AI7: 1;2;3;4;5;6;7;8;9;10;12;11
A8: MON_007 | B8: ゴブリン | C8: 水 | D8: Ranged | E8: =+[1]モンスター計算!E11 -> 117 | F8: =+[1]モンスター計算!F11 -> 28 | G8: =+[1]モンスター計算!G11 -> 6 | H8: =+[1]モンスター計算!H11 -> 19 | I8: =+[1]モンスター計算!I11 -> 7 | J8: =+[1]モンスター計算!J11 -> 18 | K8: =+[1]モンスター計算!K11 -> 0.045 | L8: =+[1]モンスター計算!L11 -> 1.45 | ... V8: =+[1]モンスター計算!V11 -> 4.4 | W8: 8 | X8: MAT_001 | Y8: 蒼澄の粘晶 | Z8: 1.2 | AA8: 5 | AB8: =ROUNDUP(AB2*1.05,0) -> 11 | AC8: =+AC2+1 -> 2 | AD8: WaterBall | AE8: 7 | AF8: 3 | AG8: TRUE | AH8: TITLE_007 | AI8: 1;2;3;4;5;6;7;8;9;10;12;11
A9: MON_008 | B9: ゴブリンウォーリアー | C9: 火 | D9: Ranged | E9: =+[1]モンスター計算!E12 -> 61 | F9: =+[1]モンスター計算!F12 -> 24 | G9: =+[1]モンスター計算!G12 -> 11 | H9: =+[1]モンスター計算!H12 -> 31 | I9: =+[1]モンスター計算!I12 -> 13 | J9: =+[1]モンスター計算!J12 -> 20 | K9: =+[1]モンスター計算!K12 -> 0.04 | L9: =+[1]モンスター計算!L12 -> 1.38 | ... V9: =+[1]モンスター計算!V12 -> 4.48 | W9: 8 | X9: MAT_002 | Y9: 灼熱の粘晶 | Z9: 1.2 | AA9: 7 | AB9: =ROUNDUP(AB3*1.05,0) -> 13 | AC9: =+AC3+1 -> 2 | AD9: FireBall | AE9: 7.5 | AF9: 3 | AG9: TRUE | AH9: TITLE_008 | AI9: 1;2;3;4;5;6;7;8;9;10;12;11
A10: MON_009 | B10: ゴブリンメイジ | C10: 風 | D10: Ranged | E10: =+[1]モンスター計算!E13 -> 110 | F10: =+[1]モンスター計算!F13 -> 23 | G10: =+[1]モンスター計算!G13 -> 9 | H10: =+[1]モンスター計算!H13 -> 19 | I10: =+[1]モンスター計算!I13 -> 9 | J10: =+[1]モンスター計算!J13 -> 11 | K10: =+[1]モンスター計算!K13 -> 0.06 | L10: =+[1]モンスター計算!L13 -> 1.4 | ... V10: =+[1]モンスター計算!V13 -> 4.8 | W10: 9 | X10: MAT_003 | Y10: 翠命の粘晶 | Z10: 1.22 | AA10: 10 | AB10: =ROUNDUP(AB4*1.05,0) -> 16 | AC10: =+AC4+1 -> 2 | AD10: WindBall | AE10: 8.5 | AF10: 3 | AG10: TRUE | AH10: TITLE_009 | AI10: 1;2;3;4;5;6;7;8;9;10;12;11
A11: MON_010 | B11: ボブゴブリン | C11: 火 | D11: Melee | E11: =+[1]モンスター計算!E14 -> 130 | F11: =+[1]モンスター計算!F14 -> 7 | G11: =+[1]モンスター計算!G14 -> 18 | H11: =+[1]モンスター計算!H14 -> 6 | I11: =+[1]モンスター計算!I14 -> 10 | J11: =+[1]モンスター計算!J14 -> 10 | K11: =+[1]モンスター計算!K14 -> 0.04 | L11: =+[1]モンスター計算!L14 -> 1.43 | ... V11: =+[1]モンスター計算!V14 -> 3.8 | W11: 10 | X11: MAT_004 | Y11: 炎牙獣の猛牙 | Z11: 1.25 | AA11: 15 | AB11: =ROUNDUP(AB5*1.05,0) -> 21 | AC11: =+AC5+1 -> 2 | AD11: None | AE11: 0 | AF11: 0 | AG11: FALSE | AH11: TITLE_010 | AI11: 1;2;3;4;5;6;7;8;9;10;12;11
A12: MON_011 | B12: マテリアスライム | C12: 水 | D12: Melee | E12: =+[1]モンスター計算!E15 -> 96 | F12: =+[1]モンスター計算!F15 -> 5 | G12: =+[1]モンスター計算!G15 -> 19 | H12: =+[1]モンスター計算!H15 -> 6 | I12: =+[1]モンスター計算!I15 -> 8 | J12: =+[1]モンスター計算!J15 -> 7 | K12: =+[1]モンスター計算!K15 -> 0.27 | L12: =+[1]モンスター計算!L15 -> 2.03 | ... V12: =+[1]モンスター計算!V15 -> 4.2 | W12: 11 | X12: MAT_005 | Y12: 氷牙獣の凍牙 | Z12: 1.25 | AA12: 20 | AB12: =ROUNDUP(AB6*1.05,0) -> 27 | AC12: =+AC6+1 -> 2 | AD12: None | AE12: 0 | AF12: 0 | AG12: FALSE | AH12: TITLE_011 | AI12: 1;2;3;4;5;6;7;8;9;10;12;11
A13: MON_012 | B13: ゴブリンキング | C13: 光 | D13: Ranged | E13: =+[1]モンスター計算!E16 -> 110 | F13: =+[1]モンスター計算!F16 -> 18 | G13: =+[1]モンスター計算!G16 -> 8 | H13: =+[1]モンスター計算!H16 -> 18 | I13: =+[1]モンスター計算!I16 -> 8 | J13: =+[1]モンスター計算!J16 -> 10 | K13: =+[1]モンスター計算!K16 -> 0.07 | L13: =+[1]モンスター計算!L16 -> 1.55 | ... V13: =+[1]モンスター計算!V16 -> 4 | W13: 15 | X13: MAT_006 | Y13: 虹幻の粘晶 | Z13: 1.3 | AA13: 40 | AB13: =ROUNDUP(AB7*1.05,0) -> 42 | AC13: =+AC7+1 -> 2 | AD13: LightBall | AE13: 10 | AF13: 4 | AG13: TRUE | AH13: TITLE_012 | AI13: 1;2;3;4;5;6;7;8;9;10;12;11
A14: MON_013 | B14: ルーインズスラッグ | C14: 水 | D14: Ranged | E14: =+[1]モンスター計算!E17 -> 169 | F14: =+[1]モンスター計算!F17 -> 39 | G14: =+[1]モンスター計算!G17 -> 6 | H14: =+[1]モンスター計算!H17 -> 17 | I14: =+[1]モンスター計算!I17 -> 9 | J14: =+[1]モンスター計算!J17 -> 16 | K14: =+[1]モンスター計算!K17 -> 0.115 | L14: =+[1]モンスター計算!L17 -> 1.95 | ... V14: =+[1]モンスター計算!V17 -> 5 | W14: 8 | X14: MAT_001 | Y14: 蒼澄の粘晶 | Z14: 1.2 | AA14: 5 | AB14: =ROUNDUP(AB8*1.05,0) -> 12 | AC14: =+AC8+1 -> 3 | AD14: WaterBall | AE14: 7 | AF14: 3 | AG14: TRUE | AH14: TITLE_013 | AI14: 1;2;3;4;5;6;7;8;9;10;12;11
A15: MON_014 | B15: ライティングスラッグ | C15: 火 | D15: Ranged | E15: =+[1]モンスター計算!E18 -> 94 | F15: =+[1]モンスター計算!F18 -> 20 | G15: =+[1]モンスター計算!G18 -> 12 | H15: =+[1]モンスター計算!H18 -> 26 | I15: =+[1]モンスター計算!I18 -> 7 | J15: =+[1]モンスター計算!J18 -> 8 | K15: =+[1]モンスター計算!K18 -> 0.11 | L15: =+[1]モンスター計算!L18 -> 1.65 | ... V15: =+[1]モンスター計算!V18 -> 4.2 | W15: 8 | X15: MAT_002 | Y15: 灼熱の粘晶 | Z15: 1.2 | AA15: 7 | AB15: =ROUNDUP(AB9*1.05,0) -> 14 | AC15: =+AC9+1 -> 3 | AD15: FireBall | AE15: 7.5 | AF15: 3 | AG15: TRUE | AH15: TITLE_014 | AI15: 1;2;3;4;5;6;7;8;9;10;12;11
A16: MON_015 | B16: 幽霊 | C16: 風 | D16: Ranged | E16: =+[1]モンスター計算!E19 -> 208 | F16: =+[1]モンスター計算!F19 -> 24 | G16: =+[1]モンスター計算!G19 -> 5 | H16: =+[1]モンスター計算!H19 -> 17 | I16: =+[1]モンスター計算!I19 -> 16 | J16: =+[1]モンスター計算!J19 -> 15 | K16: =+[1]モンスター計算!K19 -> 0.035 | L16: =+[1]モンスター計算!L19 -> 1.4 | ... V16: =+[1]モンスター計算!V19 -> 4.12 | W16: 9 | X16: MAT_003 | Y16: 翠命の粘晶 | Z16: 1.22 | AA16: 10 | AB16: =ROUNDUP(AB10*1.05,0) -> 17 | AC16: =+AC10+1 -> 3 | AD16: WindBall | AE16: 8.5 | AF16: 3 | AG16: TRUE | AH16: TITLE_015 | AI16: 1;2;3;4;5;6;7;8;9;10;12;11
A17: MON_016 | B17: 怨念 | C17: 火 | D17: Melee | E17: =+[1]モンスター計算!E20 -> 248 | F17: =+[1]モンスター計算!F20 -> 5 | G17: =+[1]モンスター計算!G20 -> 19 | H17: =+[1]モンスター計算!H20 -> 8 | I17: =+[1]モンスター計算!I20 -> 15 | J17: =+[1]モンスター計算!J20 -> 13 | K17: =+[1]モンスター計算!K20 -> 0.025 | L17: =+[1]モンスター計算!L20 -> 1.35 | ... V17: =+[1]モンスター計算!V20 -> 3.2 | W17: 10 | X17: MAT_004 | Y17: 炎牙獣の猛牙 | Z17: 1.25 | AA17: 15 | AB17: =ROUNDUP(AB11*1.05,0) -> 23 | AC17: =+AC11+1 -> 3 | AD17: None | AE17: 0 | AF17: 0 | AG17: FALSE | AH17: TITLE_016 | AI17: 1;2;3;4;5;6;7;8;9;10;12;11
A18: MON_017 | B18: ドラゴンゾンビ | C18: 水 | D18: Melee | E18: =+[1]モンスター計算!E21 -> 163 | F18: =+[1]モンスター計算!F21 -> 7 | G18: =+[1]モンスター計算!G21 -> 14 | H18: =+[1]モンスター計算!H21 -> 6 | I18: =+[1]モンスター計算!I21 -> 14 | J18: =+[1]モンスター計算!J21 -> 10 | K18: =+[1]モンスター計算!K21 -> 0.08 | L18: =+[1]モンスター計算!L21 -> 1.6 | ... V18: =+[1]モンスター計算!V21 -> 4 | W18: 11 | X18: MAT_005 | Y18: 氷牙獣の凍牙 | Z18: 1.25 | AA18: 20 | AB18: =ROUNDUP(AB12*1.05,0) -> 29 | AC18: =+AC12+1 -> 3 | AD18: None | AE18: 0 | AF18: 0 | AG18: FALSE | AH18: TITLE_017 | AI18: 1;2;3;4;5;6;7;8;9;10;12;11
A19: MON_018 | B19: エクリス・カース | C19: 光 | D19: Ranged | E19: =+[1]モンスター計算!E22 -> 90 | F19: =+[1]モンスター計算!F22 -> 17 | G19: =+[1]モンスター計算!G22 -> 6 | H19: =+[1]モンスター計算!H22 -> 21 | I19: =+[1]モンスター計算!I22 -> 7 | J19: =+[1]モンスター計算!J22 -> 8 | K19: =+[1]モンスター計算!K22 -> 0.05 | L19: =+[1]モンスター計算!L22 -> 1.4 | ... V19: =+[1]モンスター計算!V22 -> 4 | W19: 15 | X19: MAT_006 | Y19: 虹幻の粘晶 | Z19: 1.3 | AA19: 40 | AB19: =ROUNDUP(AB13*1.05,0) -> 45 | AC19: =+AC13+1 -> 3 | AD19: LightBall | AE19: 10 | AF19: 4 | AG19: TRUE | AH19: TITLE_018 | AI19: 1;2;3;4;5;6;7;8;9;10;12;11
... A367: MON_366 | B367: アステルヴェイン | C367: 風 | D367: Ranged | E367: =+[1]モンスター計算!E370 -> 30448 | F367: =+[1]モンスター計算!F370 -> 6437 | G367: =+[1]モンスター計算!G370 -> 2444 | H367: =+[1]モンスター計算!H370 -> 5431 | I367: =+[1]モンスター計算!I370 -> 2436 | J367: =+[1]モンスター計算!J370 -> 2923 | K367: =+[1]モンスター計算!K370 -> 0.06 | L367: =+[1]モンスター計算!L370 -> 1.4 | ... V367: =+[1]モンスター計算!V370 -> 4.8 | W367: 9 | X367: MAT_003 | Y367: 翠命の粘晶 | Z367: 1.22 | AA367: 10 | AB367: =ROUNDUP(AB361*1.05,0) -> 912 | AC367: =+AC361+1 -> 61 | AD367: WindBall | AE367: 8.5 | AF367: 3 | AG367: TRUE | AH367: TITLE_366 | AI367: 1;2;3;4;5;6;7;8;9;10;12;11

Sheet 特殊配合
A1: 親A | B1: 親B | C1: 配合結果
A2: MON_002 | B2: MON_008 | C2: MON_015

Sheet 称号
A1: ID | B1: 名前 | C1: 基礎HP | D1: 基礎MP | E1: 基礎攻撃力 | F1: 基礎魔力 | G1: 基礎防御力 | H1: 基礎魔防 | I1: クリ率 | J1: クリ倍 | K1: 移動速度 | L1: 攻撃速度 | M1: 攻撃範囲 | N1: 火耐性 | O1: 水耐性 | P1: 風耐性 | Q1: 雷耐性 | R1: 光耐性 | S1: 闇耐性 | T1: 素材ドロ率 | U1: 抽選ウェイト
A2: TITLE_001 | B2: 静水の微笑み | C2: =+[2]称号計算!I7 -> 0.1416 | D2: =+[2]称号計算!J7 -> 0.1554 | E2: =+[2]称号計算!K7 -> 0.0392 | F2: =+[2]称号計算!L7 -> 0.3925 | G2: =+[2]称号計算!M7 -> 0.1134 | H2: =+[2]称号計算!N7 -> 0.1334 | I2: =+[2]称号計算!O7 -> 0.0863 | J2: =+[2]称号計算!P7 -> 0.102 | ... T2: =+[2]称号計算!Z7 -> 0.4667 | U2: 1
A3: TITLE_002 | B3: 灼熱のご機嫌 | C3: =+[2]称号計算!I8 -> 0.179 | D3: =+[2]称号計算!J8 -> 0.2157 | E3: =+[2]称号計算!K8 -> 0.024 | F3: =+[2]称号計算!L8 -> 0.3632 | G3: =+[2]称号計算!M8 -> 0.2408 | H3: =+[2]称号計算!N8 -> 0.0889 | I3: =+[2]称号計算!O8 -> 0.0879 | J3: =+[2]称号計算!P8 -> 0.0944 | ... T3: =+[2]称号計算!Z8 -> 0.4769 | U3: 1
A4: TITLE_003 | B4: 芽吹く生命の笑顔 | C4: =+[2]称号計算!I9 -> 0.1678 | D4: =+[2]称号計算!J9 -> 0.1824 | E4: =+[2]称号計算!K9 -> 0.0414 | F4: =+[2]称号計算!L9 -> 0.4145 | G4: =+[2]称号計算!M9 -> 0.1339 | H4: =+[2]称号計算!N9 -> 0.148 | I4: =+[2]称号計算!O9 -> 0.0912 | J4: =+[2]称号計算!P9 -> 0.1078 | ... T4: =+[2]称号計算!Z9 -> 0.5133 | U4: 0.9
A5: TITLE_004 | B5: 紅蓮に吼える突進獣 | C5: =+[2]称号計算!I10 -> 0.2553 | D5: =+[2]称号計算!J10 -> 0.0704 | E5: =+[2]称号計算!K10 -> 0.4569 | F5: =+[2]称号計算!L10 -> 0.0297 | G5: =+[2]称号計算!M10 -> 0.1631 | H5: =+[2]称号計算!N10 -> 0.1367 | I5: =+[2]称号計算!O10 -> 0.1206 | J5: =+[2]称号計算!P10 -> 0.1703 | ... T5: =+[2]称号計算!Z10 -> 0.5031 | U5: 0.55
A6: TITLE_005 | B6: 蒼氷を纏う沈黙の獣 | C6: =+[2]称号計算!I11 -> 0.1835 | D6: =+[2]称号計算!J11 -> 0.0897 | E6: =+[2]称号計算!K11 -> 0.4533 | F6: =+[2]称号計算!L11 -> 0.0363 | G6: =+[2]称号計算!M11 -> 0.1418 | H6: =+[2]称号計算!N11 -> 0.131 | I6: =+[2]称号計算!O11 -> 0.1396 | J6: =+[2]称号計算!P11 -> 0.1257 | ... T6: =+[2]称号計算!Z11 -> 0.605 | U6: 0.5
A7: TITLE_006 | B7: 重なりし彩層の主 | C7: =+[2]称号計算!I12 -> 0.3074 | D7: =+[2]称号計算!J12 -> 0.2413 | E7: =+[2]称号計算!K12 -> 0.0264 | F7: =+[2]称号計算!L12 -> 0.4062 | G7: =+[2]称号計算!M12 -> 0.2265 | H7: =+[2]称号計算!N12 -> 0.2141 | I7: =+[2]称号計算!O12 -> 0.0626 | J7: =+[2]称号計算!P12 -> 0.0986 | ... T7: =+[2]称号計算!Z12 -> 0.5313 | U7: 0.25
A8: TITLE_007 | B8: 緑影の小狩人 | C8: =+[2]称号計算!I13 -> 0.1613 | D8: =+[2]称号計算!J13 -> 0.2664 | E8: =+[2]称号計算!K13 -> 0.0225 | F8: =+[2]称号計算!L13 -> 0.3459 | G8: =+[2]称号計算!M13 -> 0.0906 | H8: =+[2]称号計算!N13 -> 0.2411 | I8: =+[2]称号計算!O13 -> 0.0685 | J8: =+[2]称号計算!P13 -> 0.0869 | ... T8: =+[2]称号計算!Z13 -> 0.4767 | U8: 1
A9: TITLE_008 | B9: 鉄刃の蛮戦士 | C9: =+[2]称号計算!I14 -> 0.0871 | D9: =+[2]称号計算!J14 -> 0.2374 | E9: =+[2]称号計算!K14 -> 0.0288 | F9: =+[2]称号計算!L14 -> 0.3597 | G9: =+[2]称号計算!M14 -> 0.1773 | H9: =+[2]称号計算!N14 -> 0.2752 | I9: =+[2]称号計算!O14 -> 0.0633 | J9: =+[2]称号計算!P14 -> 0.086 | ... T9: =+[2]称号計算!Z14 -> 0.5278 | U9: 1
A10: TITLE_009 | B10: 呪紋の邪術士 | C10: =+[2]称号計算!I15 -> 0.1748 | D10: =+[2]称号計算!J15 -> 0.2535 | E10: =+[2]称号計算!K15 -> 0.0397 | F10: =+[2]称号計算!L15 -> 0.3973 | G10: =+[2]称号計算!M15 -> 0.1351 | H10: =+[2]称号計算!N15 -> 0.1621 | I10: =+[2]称号計算!O15 -> 0.1049 | J10: =+[2]称号計算!P15 -> 0.0964 | ... T10: =+[2]称号計算!Z15 -> 0.5434 | U10: 0.9
A11: TITLE_010 | B11: 肥大せし凶腕 | C11: =+[2]称号計算!I16 -> 0.2434 | D11: =+[2]称号計算!J16 -> 0.1083 | E11: =+[2]称号計算!K16 -> 0.4688 | F11: =+[2]称号計算!L16 -> 0.0328 | G11: =+[2]称号計算!M16 -> 0.1817 | H11: =+[2]称号計算!N16 -> 0.1817 | I11: =+[2]称号計算!O16 -> 0.0825 | J11: =+[2]称号計算!P16 -> 0.1162 | ... T11: =+[2]称号計算!Z16 -> 0.5731 | U11: 0.55
A12: TITLE_011 | B12: 錬成されし粘塊 | C12: =+[2]称号計算!I17 -> 0.1543 | D12: =+[2]称号計算!J17 -> 0.0639 | E12: =+[2]称号計算!K17 -> 0.4031 | F12: =+[2]称号計算!L17 -> 0.0262 | G12: =+[2]称号計算!M17 -> 0.1179 | H12: =+[2]称号計算!N17 -> 0.1055 | I12: =+[2]称号計算!O17 -> 0.4789 | J12: =+[2]称号計算!P17 -> 0.1418 | ... T12: =+[2]称号計算!Z17 -> 0.6604 | U12: 0.5
A13: TITLE_012 | B13: 王冠を戴く略奪王 | C13: =+[2]称号計算!I18 -> 0.2022 | D13: =+[2]称号計算!J18 -> 0.2225 | E13: =+[2]称号計算!K18 -> 0.046 | F13: =+[2]称号計算!L18 -> 0.4596 | G13: =+[2]称号計算!M18 -> 0.1485 | H13: =+[2]称号計算!N18 -> 0.1719 | I13: =+[2]称号計算!O18 -> 0.1416 | J13: =+[2]称号計算!P18 -> 0.1235 | ... T13: =+[2]称号計算!Z18 -> 0.6392 | U13: 0.25
... A367: TITLE_366 | B367: 終晶を超越せし者 | C367: =+[2]称号計算!I372 -> 2.0092 | D367: =+[2]称号計算!J372 -> 2.9133 | E367: =+[2]称号計算!K372 -> 0.4566 | F367: =+[2]称号計算!L372 -> 4.5664 | G367: =+[2]称号計算!M372 -> 1.5526 | H367: =+[2]称号計算!N372 -> 1.8631 | I367: =+[2]称号計算!O372 -> 1.2055 | J367: =+[2]称号計算!P372 -> 1.1081 | ... T367: =+[2]称号計算!Z372 -> 6.246 | U367: 0.9

Sheet 装備
A1: ID | B1: 名前 | C1: 種類 | D1: 説明 | E1: 基礎HP | F1: 基礎MP | G1: 基礎攻撃力 | H1: 基礎魔力 | I1: 基礎防御力 | J1: 基礎魔防 | K1: クリ率 | L1: クリ倍 | M1: 移動速度 | N1: 攻撃速度 | O1: 攻撃範囲 | P1: 火耐性 | Q1: 水耐性 | R1: 風耐性 | S1: 雷耐性 | T1: 光耐性 | U1: 闇耐性 | V1: 素材ドロ率
A2: EQP_001 | B2: 訓練の剣 | C2: 武器 | D2: 冒険者のための初歩的な剣 | E2: 0 | F2: 0 | G2: 0.1 | H2: 0 | I2: 0 | J2: 0 | K2: 0 | L2: 0 | M2: 0 | N2: 0 | O2: 0 | P2: 0 | Q2: 0 | R2: 0 | S2: 0 | T2: 0 | U2: 0 | V2: 0
A3: EQP_002 | B3: 旅人のローブ | C3: 防具 | D3: 軽く扱いやすい旅装 | E3: 0.05 | F3: 0.05 | G3: 0 | H3: 0 | I3: 0.05 | J3: 0.05 | K3: 0 | L3: 0 | M3: 0 | N3: 0 | O3: 0 | P3: 0 | Q3: 0 | R3: 0 | S3: 0 | T3: 0 | U3: 0 | V3: 0
A4: EQP_003 | B4: 草原の獣牙剣 | C4: 武器 | D4: 草原の魔獣の牙を鍛えた剣 | E4: 0 | F4: 0 | G4: 0.004 | H4: 0 | I4: 0 | J4: 0 | K4: 0.0004 | L4: 0 | M4: 0 | N4: 0 | O4: 0 | P4: 0 | Q4: 0 | R4: 0 | S4: 0 | T4: 0 | U4: 0 | V4: 0
A5: EQP_004 | B5: 草原の翠護衣 | C5: 防具 | D5: 草原の生命力を宿した守護衣 | E5: 0.003 | F5: 0 | G5: 0 | H5: 0 | I5: 0.002 | J5: 0.002 | K5: 0 | L5: 0 | M5: 0 | N5: 0 | O5: 0 | P5: 0 | Q5: 0 | R5: 0 | S5: 0 | T5: 0 | U5: 0 | V5: 0
A6: EQP_005 | B6: 草原の魔導環 | C6: アクセサリー | D6: 平野の魔力を集める小さな装飾品 | E6: 0 | F6: 0.002 | G6: 0 | H6: 0.004 | I6: 0 | J6: 0 | K6: 0 | L6: 0 | M6: 0 | N6: 0 | O6: 0 | P6: 0 | Q6: 0 | R6: 0 | S6: 0 | T6: 0 | U6: 0 | V6: 0

Sheet スキル
A1: ID | B1: 名前 | C1: 説明 | D1: 必要レベル | E1: 習得ポイント | F1: 消費MP | G1: 再使用時間秒 | H1: 詠唱時間秒 | I1: 共通待機時間秒 | J1: 射程 | K1: 対象 | L1: 基本効果 | M1: 参照能力 | N1: 倍率 | O1: 固定値 | P1: 属性 | Q1: 会心有効 | R1: 適用先 | S1: 範囲半径 | T1: 命中上限 | U1: 発動形式 | V1: 発射物速度 | W1: 発射物寿命秒 | X1: 追尾 | Y1: 画像パス | Z1: 演出パス | AA1: 追加効果1_種別 | AB1: 追加効果1_対象能力 | AC1: 追加効果1_変化方式 | AD1: 追加効果1_効果量 | AE1: 追加効果1_持続秒 | AF1: 追加効果1_付与確率％ | AG1: 追加効果1_状態異常 | AH1: 追加効果1_継続間隔秒 | AI1: 追加効果1_重複方式 | AJ1: 追加効果1_重複上限 | AK1: 追加効果2_種別 | AL1: 追加効果2_対象能力 | AM1: 追加効果2_変化方式 | AN1: 追加効果2_効果量 | AO1: 追加効果2_持続秒 | AP1: 追加効果2_付与確率％ | AQ1: 追加効果2_状態異常 | AR1: 追加効果2_継続間隔秒 | AS1: 追加効果2_重複方式 | AT1: 追加効果2_重複上限 | AU1: 追加効果3_種別 | AV1: 追加効果3_対象能力 | AW1: 追加効果3_変化方式 | AX1: 追加効果3_効果量 | AY1: 追加効果3_持続秒 | AZ1: 追加効果3_付与確率％ | BA1: 追加効果3_状態異常 | BB1: 追加効果3_継続間隔秒 | BC1: 追加効果3_重複方式 | BD1: 追加効果3_重複上限 | BE1: 発射物速度入力 | BF1: 発射物寿命入力秒 | BG1: 追尾入力 | BH1: 発射物プレファブパス | BI1: 発射物_貫通 | BJ1: 発射物_回転 | BK1: 発射物_回転速度 | BL1: 発射物_蛇行 | BM1: 発射物_蛇行幅 | BN1: 発射物_蛇行回数 | BO1: 発射物_加速 | BP1: 発射物_加速度 | BQ1: 発射物_最高速度 | BR1: 発射物_命中半径 | BS1: 発射物_移動タイプ | BT1: 発射物_追尾旋回速度 | BU1: 発射物_拡大速度 | BV1: 発射物_最大拡大倍率 | BW1: 発射物_直進秒 | BX1: 発射物_帰還速度 | BY1: 発射物_周回秒 | BZ1: 発射物_周回半径 | CA1: 発射物_周回角速度 | CB1: 発射物_追尾開始秒 | CC1: 発射物_螺旋角速度 | CD1: 発射物_螺旋拡大速度 | CE1: 発射物_往復距離 | CF1: 発射物_反転回数 | CG1: 発射物_反転終了で消滅 | CH1: 発射物_使用者に追従 | CI1: 発射物_再命中 | CJ1: 発射物_再命中間隔秒 | CK1: 発射物_収束秒 | CL1: 発射物_収束最大拡大倍率 | CM1: 発射物_収束最大威力倍率 | CN1: 発射物_時間切替 | CO1: 発射物_切替秒 | CP1: 発射物_切替後移動タイプ | CQ1: 発射物_切替後速度 | CR1: 発射物_連鎖 | CS1: 発射物_連鎖回数 | CT1: 発射物_連鎖半径 | CU1: 発射物_連鎖威力倍率 | CV1: 発射物_分裂 | CW1: 発射物_子弾数 | CX1: 発射物_分裂角度 | CY1: 発射物_子弾威力倍率 | CZ1: 発射物_分裂世代数 | DA1: 発射物_命中時爆発 | DB1: 発射物_停止時爆発 | DC1: 発射物_爆発半径 | DD1: 発射物_爆発表示秒 | DE1: 発射物_表示倍率 | DF1: 発射物_色 | DG1: 発射物_描画順 | DH1: 発射物_画像角度 | DI1: スキル種別 | DJ1: 生成位置 | DK1: 追従先 | DL1: 効果発生タイミング | DM1: 効果間隔秒 | DN1: パッシブ1_効果 | DO1: パッシブ1_効果量 | DP1: パッシブ2_効果 | DQ1: パッシブ2_効果量 | DR1: パッシブ3_効果 | DS1: パッシブ3_効果量 | DT1: 発射物_素材 | DU1: 発射物_範囲に表示を合わせる | DV1: 発射物_爆発拡大秒 | DW1: 発射物_爆発開始倍率 | DX1: 発射物_固有スプライト
A2: 1 | B2: ファイアボール | C2: 敵一体へ火属性の魔弾を放つ | D2: 1 | E2: 1 | F2: 10 | G2: 5 | H2: 0 | I2: 0.2 | J2: 6 | K2: 敵一体 | L2: ダメージ | M2: 魔法攻撃力 | N2: 2 | O2: 0 | P2: 火 | Q2: 有効 | R2: 選択対象 | S2: 0 | T2: 1 | U2: 発射物 | V2: 8 | W2: 3 | X2: 有効 | AA2: なし | AB2: なし | AC2: なし | AD2: 0 | AE2: 0 | AF2: 0 | AG2: なし | AH2: 0 | AI2: 時間更新 | AJ2: 1 | AK2: なし | AL2: なし | AM2: なし | AN2: 0 | AO2: 0 | AP2: 0 | AQ2: なし | AR2: 0 | AS2: 時間更新 | AT2: 1 | AU2: なし | AV2: なし | AW2: なし | AX2: 0 | AY2: 0 | AZ2: 0 | BA2: なし | BB2: 0 | BC2: 時間更新 | BD2: 1 | BE2: 8 | BF2: 3 | BG2: 有効 | BI2: 無効 | BJ2: 無効 | BK2: 360 | BL2: 無効 | BM2: 0.3 | BN2: 2 | BO2: 無効 | BP2: 3 | BQ2: 50 | BR2: 0.3 | BS2: 直進 | BT2: 8 | BU2: 0.8 | BV2: 2 | BW2: 0.8 | BX2: 12 | BY2: 0.8 | BZ2: 1.5 | CA2: 720 | CB2: 0.6 | CC2: 540 | CD2: 1.8 | CE2: 4 | CF2: 4 | CG2: 有効 | CH2: 無効 | CI2: 無効 | CJ2: 0.5 | CK2: 1.5 | CL2: 2.5 | CM2: 2.5 | CN2: 無効 | CO2: 1 | CP2: 追尾 | CQ2: 10 | CR2: 無効 | CS2: 4 | CT2: 8 | CU2: 0.85 | CV2: 無効 | CW2: 2 | CX2: 50 | CY2: 0.5 | CZ2: 1 | DA2: 無効 | DB2: 有効 | DC2: 2 | DD2: 0.4 | DE2: 0.3 | DF2: #FF703FFF | DG2: 60 | DH2: 0 | DI2: アクティブ | DJ2: 使用者 | DK2: 追従なし | DL2: 命中時 | DM2: 1 | DT2: 光の弾 | DU2: 有効 | DV2: 0.35 | DW2: 0.1
A3: 2 | B3: ヒーリング | C3: 自分または味方一体の体力を回復する | D3: 1 | E3: 1 | F3: 15 | G3: 8 | H3: 0 | I3: 0.2 | J3: 5 | K3: 味方一体 | L3: 回復 | M3: 魔法攻撃力 | N3: 1.5 | O3: 200 | P3: 使用者と同じ | Q3: 無効 | R3: 選択対象 | S3: 0 | T3: 1 | U3: 発射物 | V3: 1 | W3: 0.8 | X3: 無効 | AA3: なし | AB3: なし | AC3: なし | AD3: 0 | AE3: 0 | AF3: 0 | AG3: なし | AH3: 0 | AI3: 時間更新 | AJ3: 1 | AK3: なし | AL3: なし | AM3: なし | AN3: 0 | AO3: 0 | AP3: 0 | AQ3: なし | AR3: 0 | AS3: 時間更新 | AT3: 1 | AU3: なし | AV3: なし | AW3: なし | AX3: 0 | AY3: 0 | AZ3: 0 | BA3: なし | BB3: 0 | BC3: 時間更新 | BD3: 1 | BE3: 1 | BF3: 0.8 | BG3: 無効 | BI3: 無効 | BJ3: 無効 | BK3: 360 | BL3: 無効 | BM3: 0.3 | BN3: 2 | BO3: 無効 | BP3: 3 | BQ3: 50 | BR3: 0.3 | BS3: その場 | BT3: 8 | BU3: 0.8 | BV3: 2 | BW3: 0.8 | BX3: 12 | BY3: 0.8 | BZ3: 1.5 | CA3: 720 | CB3: 0.6 | CC3: 540 | CD3: 1.8 | CE3: 4 | CF3: 4 | CG3: 有効 | CH3: 無効 | CI3: 無効 | CJ3: 0.5 | CK3: 1.5 | CL3: 2.5 | CM3: 2.5 | CN3: 無効 | CO3: 1 | CP3: 追尾 | CQ3: 10 | CR3: 無効 | CS3: 4 | CT3: 8 | CU3: 0.85 | CV3: 無効 | CW3: 2 | CX3: 50 | CY3: 0.5 | CZ3: 1 | DA3: 無効 | DB3: 有効 | DC3: 2 | DD3: 0.4 | DE3: 0.3 | DF3: #76FFB0FF | DG3: 60 | DH3: 0 | DI3: アクティブ | DJ3: 対象 | DK3: 対象 | DL3: 生成時 | DM3: 1 | DT3: 回復 | DU3: 有効 | DV3: 0.35 | DW3: 0.1
A4: 3 | B4: 衝撃波 | C4: 自身の周囲の敵に物理ダメージ | D4: 5 | E4: 2 | F4: 20 | G4: 10 | H4: 0.3 | I4: 0.2 | J4: 0 | K4: 自身中心 | L4: ダメージ | M4: 攻撃力 | N4: 1.5 | O4: 0 | P4: 使用者と同じ | Q4: 有効 | R4: 範囲内の敵 | S4: 3 | T4: 0 | U4: 発射物 | V4: 1 | W4: 0.45 | X4: 無効 | AA4: なし | AB4: なし | AC4: なし | AD4: 0 | AE4: 0 | AF4: 0 | AG4: なし | AH4: 0 | AI4: 時間更新 | AJ4: 1 | AK4: なし | AL4: なし | AM4: なし | AN4: 0 | AO4: 0 | AP4: 0 | AQ4: なし | AR4: 0 | AS4: 時間更新 | AT4: 1 | AU4: なし | AV4: なし | AW4: なし | AX4: 0 | AY4: 0 | AZ4: 0 | BA4: なし | BB4: 0 | BC4: 時間更新 | BD4: 1 | BE4: 1 | BF4: 0.45 | BG4: 無効 | BI4: 有効 | BJ4: 無効 | BK4: 360 | BL4: 無効 | BM4: 0.3 | BN4: 2 | BO4: 無効 | BP4: 3 | BQ4: 50 | BR4: 0.3 | BS4: 爆発 | BT4: 8 | BU4: 0.8 | BV4: 2 | BW4: 0.8 | BX4: 12 | BY4: 0.8 | BZ4: 1.5 | CA4: 720 | CB4: 0.6 | CC4: 540 | CD4: 1.8 | CE4: 4 | CF4: 4 | CG4: 有効 | CH4: 無効 | CI4: 無効 | CJ4: 0.5 | CK4: 1.5 | CL4: 2.5 | CM4: 2.5 | CN4: 無効 | CO4: 1 | CP4: 追尾 | CQ4: 10 | CR4: 無効 | CS4: 4 | CT4: 8 | CU4: 0.85 | CV4: 無効 | CW4: 2 | CX4: 50 | CY4: 0.5 | CZ4: 1 | DA4: 無効 | DB4: 無効 | DC4: 2 | DD4: 0.4 | DE4: 0.3 | DF4: #FFE6A6FF | DG4: 60 | DH4: 0 | DI4: アクティブ | DJ4: 使用者 | DK4: 追従なし | DL4: 生成時 | DM4: 1 | DT4: 衝撃波 | DU4: 有効 | DV4: 0.35 | DW4: 0.1
A5: 4 | B5: 剛力の加護 | C5: 味方一体の攻撃力を20％上昇 | D5: 1 | E5: 1 | F5: 10 | G5: 5 | H5: 0 | I5: 0.2 | J5: 6 | K5: 味方一体 | L5: なし | M5: なし | N5: 0 | O5: 0 | P5: 使用者と同じ | Q5: 無効 | R5: 選択対象 | S5: 0 | T5: 1 | U5: 発射物 | V5: 1 | W5: 0.8 | X5: 無効 | AA5: バフ | AB5: 攻撃力 | AC5: 割合変化 | AD5: 20 | AE5: 10 | AF5: 100 | AG5: なし | AH5: 0 | AI5: 時間更新 | AJ5: 1 | AK5: なし | AL5: なし | AM5: なし | AN5: 0 | AO5: 0 | AP5: 0 | AQ5: なし | AR5: 0 | AS5: 時間更新 | AT5: 1 | AU5: なし | AV5: なし | AW5: なし | AX5: 0 | AY5: 0 | AZ5: 0 | BA5: なし | BB5: 0 | BC5: 時間更新 | BD5: 1 | BE5: 1 | BF5: 0.8 | BG5: 無効 | BI5: 無効 | BJ5: 無効 | BK5: 360 | BL5: 無効 | BM5: 0.3 | BN5: 2 | BO5: 無効 | BP5: 3 | BQ5: 50 | BR5: 0.3 | BS5: その場 | BT5: 8 | BU5: 0.8 | BV5: 2 | BW5: 0.8 | BX5: 12 | BY5: 0.8 | BZ5: 1.5 | CA5: 720 | CB5: 0.6 | CC5: 540 | CD5: 1.8 | CE5: 4 | CF5: 4 | CG5: 有効 | CH5: 無効 | CI5: 無効 | CJ5: 0.5 | CK5: 1.5 | CL5: 2.5 | CM5: 2.5 | CN5: 無効 | CO5: 1 | CP5: 追尾 | CQ5: 10 | CR5: 無効 | CS5: 4 | CT5: 8 | CU5: 0.85 | CV5: 無効 | CW5: 2 | CX5: 50 | CY5: 0.5 | CZ5: 1 | DA5: 無効 | DB5: 有効 | DC5: 2 | DD5: 0.4 | DE5: 0.3 | DF5: #FFBE55FF | DG5: 60 | DH5: 0 | DI5: アクティブ | DJ5: 対象 | DK5: 対象 | DL5: 生成時 | DM5: 1 | DT5: バフ | DU5: 有効 | DV5: 0.35 | DW5: 0.1
A6: 5 | B6: 疾風の光弾 | C6: 味方へ命中すると移動速度が30％上昇 | D6: 1 | E6: 1 | F6: 10 | G6: 5 | H6: 0 | I6: 0.2 | J6: 6 | K6: 味方一体 | L6: なし | M6: なし | N6: 0 | O6: 0 | P6: 使用者と同じ | Q6: 無効 | R6: 選択対象 | S6: 0 | T6: 1 | U6: 発射物 | V6: 1 | W6: 0.8 | X6: 無効 | AA6: バフ | AB6: 移動速度 | AC6: 割合変化 | AD6: 30 | AE6: 10 | AF6: 100 | AG6: なし | AH6: 0 | AI6: 時間更新 | AJ6: 1 | AK6: なし | AL6: なし | AM6: なし | AN6: 0 | AO6: 0 | AP6: 0 | AQ6: なし | AR6: 0 | AS6: 時間更新 | AT6: 1 | AU6: なし | AV6: なし | AW6: なし | AX6: 0 | AY6: 0 | AZ6: 0 | BA6: なし | BB6: 0 | BC6: 時間更新 | BD6: 1 | BE6: 1 | BF6: 0.8 | BG6: 無効 | BI6: 無効 | BJ6: 無効 | BK6: 360 | BL6: 無効 | BM6: 0.3 | BN6: 2 | BO6: 無効 | BP6: 3 | BQ6: 50 | BR6: 0.3 | BS6: その場 | BT6: 8 | BU6: 0.8 | BV6: 2 | BW6: 0.8 | BX6: 12 | BY6: 0.8 | BZ6: 1.5 | CA6: 720 | CB6: 0.6 | CC6: 540 | CD6: 1.8 | CE6: 4 | CF6: 4 | CG6: 有効 | CH6: 無効 | CI6: 無効 | CJ6: 0.5 | CK6: 1.5 | CL6: 2.5 | CM6: 2.5 | CN6: 無効 | CO6: 1 | CP6: 追尾 | CQ6: 10 | CR6: 無効 | CS6: 4 | CT6: 8 | CU6: 0.85 | CV6: 無効 | CW6: 2 | CX6: 50 | CY6: 0.5 | CZ6: 1 | DA6: 無効 | DB6: 有効 | DC6: 2 | DD6: 0.4 | DE6: 0.3 | DF6: #8EEDCFFF | DG6: 60 | DH6: 0 | DI6: アクティブ | DJ6: 対象 | DK6: 対象 | DL6: 生成時 | DM6: 1 | DT6: デバフ | DU6: 有効 | DV6: 0.35 | DW6: 0.1
A7: 6 | B7: 破甲弾 | C7: 敵に命中すると防御力が20％低下 | D7: 1 | E7: 1 | F7: 10 | G7: 5 | H7: 0 | I7: 0.2 | J7: 6 | K7: 敵一体 | L7: ダメージ | M7: 魔法攻撃力 | N7: 2 | O7: 0 | P7: 使用者と同じ | Q7: 有効 | R7: 選択対象 | S7: 0 | T7: 1 | U7: 発射物 | V7: 8 | W7: 3 | X7: 有効 | AA7: デバフ | AB7: 防御力 | AC7: 割合変化 | AD7: 20 | AE7: 8 | AF7: 100 | AG7: なし | AH7: 0 | AI7: 時間更新 | AJ7: 1 | AK7: なし | AL7: なし | AM7: なし | AN7: 0 | AO7: 0 | AP7: 0 | AQ7: なし | AR7: 0 | AS7: 時間更新 | AT7: 1 | AU7: なし | AV7: なし | AW7: なし | AX7: 0 | AY7: 0 | AZ7: 0 | BA7: なし | BB7: 0 | BC7: 時間更新 | BD7: 1 | BE7: 8 | BF7: 3 | BG7: 有効 | BI7: 無効 | BJ7: 無効 | BK7: 360 | BL7: 無効 | BM7: 0.3 | BN7: 2 | BO7: 無効 | BP7: 3 | BQ7: 50 | BR7: 0.3 | BS7: 直進 | BT7: 8 | BU7: 0.8 | BV7: 2 | BW7: 0.8 | BX7: 12 | BY7: 0.8 | BZ7: 1.5 | CA7: 720 | CB7: 0.6 | CC7: 540 | CD7: 1.8 | CE7: 4 | CF7: 4 | CG7: 有効 | CH7: 無効 | CI7: 無効 | CJ7: 0.5 | CK7: 1.5 | CL7: 2.5 | CM7: 2.5 | CN7: 無効 | CO7: 1 | CP7: 追尾 | CQ7: 10 | CR7: 無効 | CS7: 4 | CT7: 8 | CU7: 0.85 | CV7: 無効 | CW7: 2 | CX7: 50 | CY7: 0.5 | CZ7: 1 | DA7: 無効 | DB7: 有効 | DC7: 2 | DD7: 0.4 | DE7: 0.3 | DF7: #E3A15CFF | DG7: 60 | DH7: 0 | DI7: アクティブ | DJ7: 使用者 | DK7: 追従なし | DL7: 命中時 | DM7: 1 | DT7: 光の弾 | DU7: 有効 | DV7: 0.35 | DW7: 0.1
A8: 7 | B8: 鈍足の陣 | C8: 周囲の敵の移動速度を30％低下 | D8: 1 | E8: 1 | F8: 10 | G8: 5 | H8: 0 | I8: 0.2 | J8: 0 | K8: 自身中心 | L8: なし | M8: なし | N8: 0 | O8: 0 | P8: 使用者と同じ | Q8: 無効 | R8: 範囲内の敵 | S8: 3 | T8: 0 | U8: 発射物 | V8: 1 | W8: 5 | X8: 無効 | AA8: デバフ | AB8: 移動速度 | AC8: 割合変化 | AD8: 30 | AE8: 8 | AF8: 100 | AG8: なし | AH8: 0 | AI8: 時間更新 | AJ8: 1 | AK8: なし | AL8: なし | AM8: なし | AN8: 0 | AO8: 0 | AP8: 0 | AQ8: なし | AR8: 0 | AS8: 時間更新 | AT8: 1 | AU8: なし | AV8: なし | AW8: なし | AX8: 0 | AY8: 0 | AZ8: 0 | BA8: なし | BB8: 0 | BC8: 時間更新 | BD8: 1 | BE8: 1 | BF8: 5 | BG8: 無効 | BI8: 有効 | BJ8: 無効 | BK8: 360 | BL8: 無効 | BM8: 0.3 | BN8: 2 | BO8: 無効 | BP8: 3 | BQ8: 50 | BR8: 0.3 | BS8: その場 | BT8: 8 | BU8: 0.8 | BV8: 2 | BW8: 0.8 | BX8: 12 | BY8: 0.8 | BZ8: 1.5 | CA8: 720 | CB8: 0.6 | CC8: 540 | CD8: 1.8 | CE8: 4 | CF8: 4 | CG8: 有効 | CH8: 無効 | CI8: 無効 | CJ8: 0.5 | CK8: 1.5 | CL8: 2.5 | CM8: 2.5 | CN8: 無効 | CO8: 1 | CP8: 追尾 | CQ8: 10 | CR8: 無効 | CS8: 4 | CT8: 8 | CU8: 0.85 | CV8: 無効 | CW8: 2 | CX8: 50 | CY8: 0.5 | CZ8: 1 | DA8: 無効 | DB8: 無効 | DC8: 2 | DD8: 0.4 | DE8: 0.3 | DF8: #B492FFB3 | DG8: 60 | DH8: 0 | DI8: アクティブ | DJ8: 使用者 | DK8: 追従なし | DL8: 一定間隔 | DM8: 1 | DT8: 魔方陣 | DU8: 有効 | DV8: 0.35 | DW8: 0.1
A9: 8 | B9: 毒弾 | C9: 命中時に毒。最大体力の1％を2秒ごとに与える | D9: 1 | E9: 1 | F9: 10 | G9: 5 | H9: 0 | I9: 0.2 | J9: 6 | K9: 敵一体 | L9: ダメージ | M9: 魔法攻撃力 | N9: 2 | O9: 0 | P9: 使用者と同じ | Q9: 有効 | R9: 選択対象 | S9: 0 | T9: 1 | U9: 発射物 | V9: 8 | W9: 3 | X9: 有効 | AA9: 状態異常 | AB9: なし | AC9: 最大体力割合 | AD9: 1 | AE9: 10 | AF9: 80 | AG9: 毒 | AH9: 2 | AI9: 時間更新 | AJ9: 1 | AK9: なし | AL9: なし | AM9: なし | AN9: 0 | AO9: 0 | AP9: 0 | AQ9: なし | AR9: 0 | AS9: 時間更新 | AT9: 1 | AU9: なし | AV9: なし | AW9: なし | AX9: 0 | AY9: 0 | AZ9: 0 | BA9: なし | BB9: 0 | BC9: 時間更新 | BD9: 1 | BE9: 8 | BF9: 3 | BG9: 有効 | BI9: 無効 | BJ9: 無効 | BK9: 360 | BL9: 無効 | BM9: 0.3 | BN9: 2 | BO9: 無効 | BP9: 3 | BQ9: 50 | BR9: 0.3 | BS9: 直進 | BT9: 8 | BU9: 0.8 | BV9: 2 | BW9: 0.8 | BX9: 12 | BY9: 0.8 | BZ9: 1.5 | CA9: 720 | CB9: 0.6 | CC9: 540 | CD9: 1.8 | CE9: 4 | CF9: 4 | CG9: 有効 | CH9: 無効 | CI9: 無効 | CJ9: 0.5 | CK9: 1.5 | CL9: 2.5 | CM9: 2.5 | CN9: 無効 | CO9: 1 | CP9: 追尾 | CQ9: 10 | CR9: 無効 | CS9: 4 | CT9: 8 | CU9: 0.85 | CV9: 無効 | CW9: 2 | CX9: 50 | CY9: 0.5 | CZ9: 1 | DA9: 無効 | DB9: 有効 | DC9: 2 | DD9: 0.4 | DE9: 0.3 | DF9: #9DFF57FF | DG9: 60 | DH9: 0 | DI9: アクティブ | DJ9: 使用者 | DK9: 追従なし | DL9: 命中時 | DM9: 1 | DT9: 光の弾 | DU9: 有効 | DV9: 0.35 | DW9: 0.1
A10: 9 | B10: 灼熱弾 | C10: 火傷により固定50ダメージを1秒ごとに与える | D10: 1 | E10: 1 | F10: 10 | G10: 5 | H10: 0 | I10: 0.2 | J10: 6 | K10: 敵一体 | L10: ダメージ | M10: 魔法攻撃力 | N10: 2 | O10: 0 | P10: 火 | Q10: 有効 | R10: 選択対象 | S10: 0 | T10: 1 | U10: 発射物 | V10: 8 | W10: 3 | X10: 有効 | AA10: 状態異常 | AB10: なし | AC10: 固定ダメージ | AD10: 50 | AE10: 5 | AF10: 100 | AG10: 火傷 | AH10: 1 | AI10: 時間更新 | AJ10: 1 | AK10: なし | AL10: なし | AM10: なし | AN10: 0 | AO10: 0 | AP10: 0 | AQ10: なし | AR10: 0 | AS10: 時間更新 | AT10: 1 | AU10: なし | AV10: なし | AW10: なし | AX10: 0 | AY10: 0 | AZ10: 0 | BA10: なし | BB10: 0 | BC10: 時間更新 | BD10: 1 | BE10: 8 | BF10: 3 | BG10: 有効 | BI10: 無効 | BJ10: 無効 | BK10: 360 | BL10: 無効 | BM10: 0.3 | BN10: 2 | BO10: 無効 | BP10: 3 | BQ10: 50 | BR10: 0.3 | BS10: 直進 | BT10: 8 | BU10: 0.8 | BV10: 2 | BW10: 0.8 | BX10: 12 | BY10: 0.8 | BZ10: 1.5 | CA10: 720 | CB10: 0.6 | CC10: 540 | CD10: 1.8 | CE10: 4 | CF10: 4 | CG10: 有効 | CH10: 無効 | CI10: 無効 | CJ10: 0.5 | CK10: 1.5 | CL10: 2.5 | CM10: 2.5 | CN10: 無効 | CO10: 1 | CP10: 追尾 | CQ10: 10 | CR10: 無効 | CS10: 4 | CT10: 8 | CU10: 0.85 | CV10: 無効 | CW10: 2 | CX10: 50 | CY10: 0.5 | CZ10: 1 | DA10: 無効 | DB10: 有効 | DC10: 2 | DD10: 0.4 | DE10: 0.3 | DF10: #FF5030FF | DG10: 60 | DH10: 0 | DI10: アクティブ | DJ10: 使用者 | DK10: 追従なし | DL10: 命中時 | DM10: 1 | DT10: 光の弾 | DU10: 有効 | DV10: 0.35 | DW10: 0.1
A11: 10 | B11: 凍結弾 | C11: 命中時に3秒間凍結させる | D11: 1 | E11: 1 | F11: 10 | G11: 5 | H11: 0 | I11: 0.2 | J11: 6 | K11: 敵一体 | L11: ダメージ | M11: 魔法攻撃力 | N11: 2 | O11: 0 | P11: 水 | Q11: 有効 | R11: 選択対象 | S11: 0 | T11: 1 | U11: 発射物 | V11: 8 | W11: 3 | X11: 有効 | AA11: 状態異常 | AB11: なし | AC11: なし | AD11: 0 | AE11: 3 | AF11: 50 | AG11: 凍結 | AH11: 0 | AI11: 時間更新 | AJ11: 1 | AK11: なし | AL11: なし | AM11: なし | AN11: 0 | AO11: 0 | AP11: 0 | AQ11: なし | AR11: 0 | AS11: 時間更新 | AT11: 1 | AU11: なし | AV11: なし | AW11: なし | AX11: 0 | AY11: 0 | AZ11: 0 | BA11: なし | BB11: 0 | BC11: 時間更新 | BD11: 1 | BE11: 8 | BF11: 3 | BG11: 有効 | BI11: 無効 | BJ11: 無効 | BK11: 360 | BL11: 無効 | BM11: 0.3 | BN11: 2 | BO11: 無効 | BP11: 3 | BQ11: 50 | BR11: 0.3 | BS11: 直進 | BT11: 8 | BU11: 0.8 | BV11: 2 | BW11: 0.8 | BX11: 12 | BY11: 0.8 | BZ11: 1.5 | CA11: 720 | CB11: 0.6 | CC11: 540 | CD11: 1.8 | CE11: 4 | CF11: 4 | CG11: 有効 | CH11: 無効 | CI11: 無効 | CJ11: 0.5 | CK11: 1.5 | CL11: 2.5 | CM11: 2.5 | CN11: 無効 | CO11: 1 | CP11: 追尾 | CQ11: 10 | CR11: 無効 | CS11: 4 | CT11: 8 | CU11: 0.85 | CV11: 無効 | CW11: 2 | CX11: 50 | CY11: 0.5 | CZ11: 1 | DA11: 無効 | DB11: 有効 | DC11: 2 | DD11: 0.4 | DE11: 0.3 | DF11: #72DBFFFF | DG11: 60 | DH11: 0 | DI11: アクティブ | DJ11: 使用者 | DK11: 追従なし | DL11: 命中時 | DM11: 1 | DT11: 光の弾 | DU11: 有効 | DV11: 0.35 | DW11: 0.1
A12: 11 | B12: 封魔 | C12: 敵一体のスキル使用を5秒間封じる | D12: 1 | E12: 1 | F12: 10 | G12: 5 | H12: 0 | I12: 0.2 | J12: 6 | K12: 敵一体 | L12: なし | M12: なし | N12: 0 | O12: 0 | P12: 使用者と同じ | Q12: 無効 | R12: 選択対象 | S12: 0 | T12: 1 | U12: 発射物 | V12: 1 | W12: 0.8 | X12: 無効 | AA12: 状態異常 | AB12: なし | AC12: なし | AD12: 0 | AE12: 5 | AF12: 70 | AG12: 沈黙 | AH12: 0 | AI12: 時間更新 | AJ12: 1 | AK12: なし | AL12: なし | AM12: なし | AN12: 0 | AO12: 0 | AP12: 0 | AQ12: なし | AR12: 0 | AS12: 時間更新 | AT12: 1 | AU12: なし | AV12: なし | AW12: なし | AX12: 0 | AY12: 0 | AZ12: 0 | BA12: なし | BB12: 0 | BC12: 時間更新 | BD12: 1 | BE12: 1 | BF12: 0.8 | BG12: 無効 | BI12: 有効 | BJ12: 無効 | BK12: 360 | BL12: 無効 | BM12: 0.3 | BN12: 2 | BO12: 無効 | BP12: 3 | BQ12: 50 | BR12: 0.3 | BS12: その場 | BT12: 8 | BU12: 0.8 | BV12: 2 | BW12: 0.8 | BX12: 12 | BY12: 0.8 | BZ12: 1.5 | CA12: 720 | CB12: 0.6 | CC12: 540 | CD12: 1.8 | CE12: 4 | CF12: 4 | CG12: 有効 | CH12: 無効 | CI12: 無効 | CJ12: 0.5 | CK12: 1.5 | CL12: 2.5 | CM12: 2.5 | CN12: 無効 | CO12: 1 | CP12: 追尾 | CQ12: 10 | CR12: 無効 | CS12: 4 | CT12: 8 | CU12: 0.85 | CV12: 無効 | CW12: 2 | CX12: 50 | CY12: 0.5 | CZ12: 1 | DA12: 無効 | DB12: 無効 | DC12: 2 | DD12: 0.4 | DE12: 0.3 | DF12: #C18AFFCC | DG12: 60 | DH12: 0 | DI12: アクティブ | DJ12: 対象 | DK12: 対象 | DL12: 生成時 | DM12: 1 | DT12: 魔方陣 | DU12: 有効 | DV12: 0.35 | DW12: 0.1
A13: 12 | B13: 腐食毒弾 | C13: ダメージと同時に防御力低下と毒を付与 | D13: 1 | E13: 1 | F13: 10 | G13: 5 | H13: 0 | I13: 0.2 | J13: 6 | K13: 敵一体 | L13: ダメージ | M13: 魔法攻撃力 | N13: 2 | O13: 0 | P13: 使用者と同じ | Q13: 有効 | R13: 選択対象 | S13: 0 | T13: 1 | U13: 発射物 | V13: 8 | W13: 3 | X13: 有効 | AA13: デバフ | AB13: 防御力 | AC13: 割合変化 | AD13: 20 | AE13: 10 | AF13: 100 | AG13: なし | AH13: 0 | AI13: 時間更新 | AJ13: 1 | AK13: 状態異常 | AL13: なし | AM13: 最大体力割合 | AN13: 1 | AO13: 10 | AP13: 80 | AQ13: 毒 | AR13: 2 | AS13: 時間更新 | AT13: 1 | AU13: なし | AV13: なし | AW13: なし | AX13: 0 | AY13: 0 | AZ13: 0 | BA13: なし | BB13: 0 | BC13: 時間更新 | BD13: 1 | BE13: 8 | BF13: 3 | BG13: 有効 | BI13: 無効 | BJ13: 無効 | BK13: 360 | BL13: 無効 | BM13: 0.3 | BN13: 2 | BO13: 無効 | BP13: 3 | BQ13: 50 | BR13: 0.3 | BS13: 直進 | BT13: 8 | BU13: 0.8 | BV13: 2 | BW13: 0.8 | BX13: 12 | BY13: 0.8 | BZ13: 1.5 | CA13: 720 | CB13: 0.6 | CC13: 540 | CD13: 1.8 | CE13: 4 | CF13: 4 | CG13: 有効 | CH13: 無効 | CI13: 無効 | CJ13: 0.5 | CK13: 1.5 | CL13: 2.5 | CM13: 2.5 | CN13: 無効 | CO13: 1 | CP13: 追尾 | CQ13: 10 | CR13: 無効 | CS13: 4 | CT13: 8 | CU13: 0.85 | CV13: 無効 | CW13: 2 | CX13: 50 | CY13: 0.5 | CZ13: 1 | DA13: 無効 | DB13: 有効 | DC13: 2 | DD13: 0.4 | DE13: 0.3 | DF13: #BD70FFFF | DG13: 60 | DH13: 0 | DI13: アクティブ | DJ13: 使用者 | DK13: 追従なし | DL13: 命中時 | DM13: 1 | DT13: 光の弾 | DU13: 有効 | DV13: 0.35 | DW13: 0.1
A14: 13 | B14: 最大HP＋10％ | C14: 枠にセット中のみ有効。 | D14: 1 | E14: 1 | F14: 0 | G14: 0 | H14: 0 | I14: 0 | J14: 0 | K14: 自身 | L14: なし | M14: なし | N14: 0 | O14: 0 | P14: 使用者と同じ | Q14: 無効 | R14: 自身 | S14: 0 | T14: 1 | U14: 即時 | V14: 0 | W14: 0 | X14: 無効 | DI14: パッシブ | DJ14: 使用者 | DK14: 追従なし | DL14: 命中時 | DM14: 1 | DN14: 最大HP | DO14: 10 | DP14: なし | DQ14: 0 | DR14: なし | DS14: 0
A15: 14 | B15: 最大MP＋10％ | C15: 枠にセット中のみ有効。 | D15: 1 | E15: 1 | F15: 0 | G15: 0 | H15: 0 | I15: 0 | J15: 0 | K15: 自身 | L15: なし | M15: なし | N15: 0 | O15: 0 | P15: 使用者と同じ | Q15: 無効 | R15: 自身 | S15: 0 | T15: 1 | U15: 即時 | V15: 0 | W15: 0 | X15: 無効 | DI15: パッシブ | DJ15: 使用者 | DK15: 追従なし | DL15: 命中時 | DM15: 1 | DN15: 最大MP | DO15: 10 | DP15: なし | DQ15: 0 | DR15: なし | DS15: 0
A16: 15 | B16: 攻撃力＋10％ | C16: 枠にセット中のみ有効。 | D16: 1 | E16: 1 | F16: 0 | G16: 0 | H16: 0 | I16: 0 | J16: 0 | K16: 自身 | L16: なし | M16: なし | N16: 0 | O16: 0 | P16: 使用者と同じ | Q16: 無効 | R16: 自身 | S16: 0 | T16: 1 | U16: 即時 | V16: 0 | W16: 0 | X16: 無効 | DI16: パッシブ | DJ16: 使用者 | DK16: 追従なし | DL16: 命中時 | DM16: 1 | DN16: 攻撃力 | DO16: 10 | DP16: なし | DQ16: 0 | DR16: なし | DS16: 0
A17: 16 | B17: 魔法攻撃力＋10％ | C17: 枠にセット中のみ有効。 | D17: 1 | E17: 1 | F17: 0 | G17: 0 | H17: 0 | I17: 0 | J17: 0 | K17: 自身 | L17: なし | M17: なし | N17: 0 | O17: 0 | P17: 使用者と同じ | Q17: 無効 | R17: 自身 | S17: 0 | T17: 1 | U17: 即時 | V17: 0 | W17: 0 | X17: 無効 | DI17: パッシブ | DJ17: 使用者 | DK17: 追従なし | DL17: 命中時 | DM17: 1 | DN17: 魔法攻撃力 | DO17: 10 | DP17: なし | DQ17: 0 | DR17: なし | DS17: 0
A18: 17 | B18: 防御力＋10％ | C18: 枠にセット中のみ有効。 | D18: 1 | E18: 1 | F18: 0 | G18: 0 | H18: 0 | I18: 0 | J18: 0 | K18: 自身 | L18: なし | M18: なし | N18: 0 | O18: 0 | P18: 使用者と同じ | Q18: 無効 | R18: 自身 | S18: 0 | T18: 1 | U18: 即時 | V18: 0 | W18: 0 | X18: 無効 | DI18: パッシブ | DJ18: 使用者 | DK18: 追従なし | DL18: 命中時 | DM18: 1 | DN18: 防御力 | DO18: 10 | DP18: なし | DQ18: 0 | DR18: なし | DS18: 0
A19: 18 | B19: 魔法防御力＋10％ | C19: 枠にセット中のみ有効。 | D19: 1 | E19: 1 | F19: 0 | G19: 0 | H19: 0 | I19: 0 | J19: 0 | K19: 自身 | L19: なし | M19: なし | N19: 0 | O19: 0 | P19: 使用者と同じ | Q19: 無効 | R19: 自身 | S19: 0 | T19: 1 | U19: 即時 | V19: 0 | W19: 0 | X19: 無効 | DI19: パッシブ | DJ19: 使用者 | DK19: 追従なし | DL19: 命中時 | DM19: 1 | DN19: 魔法防御力 | DO19: 10 | DP19: なし | DQ19: 0 | DR19: なし | DS19: 0
A20: 19 | B20: 移動速度＋10％ | C20: 枠にセット中のみ有効。 | D20: 1 | E20: 1 | F20: 0 | G20: 0 | H20: 0 | I20: 0 | J20: 0 | K20: 自身 | L20: なし | M20: なし | N20: 0 | O20: 0 | P20: 使用者と同じ | Q20: 無効 | R20: 自身 | S20: 0 | T20: 1 | U20: 即時 | V20: 0 | W20: 0 | X20: 無効 | DI20: パッシブ | DJ20: 使用者 | DK20: 追従なし | DL20: 命中時 | DM20: 1 | DN20: 移動速度 | DO20: 10 | DP20: なし | DQ20: 0 | DR20: なし | DS20: 0
A21: 20 | B21: 攻撃速度＋10％ | C21: 枠にセット中のみ有効。 | D21: 1 | E21: 1 | F21: 0 | G21: 0 | H21: 0 | I21: 0 | J21: 0 | K21: 自身 | L21: なし | M21: なし | N21: 0 | O21: 0 | P21: 使用者と同じ | Q21: 無効 | R21: 自身 | S21: 0 | T21: 1 | U21: 即時 | V21: 0 | W21: 0 | X21: 無効 | DI21: パッシブ | DJ21: 使用者 | DK21: 追従なし | DL21: 命中時 | DM21: 1 | DN21: 攻撃速度 | DO21: 10 | DP21: なし | DQ21: 0 | DR21: なし | DS21: 0
A22: 21 | B22: 攻撃範囲＋10％ | C22: 枠にセット中のみ有効。 | D22: 1 | E22: 1 | F22: 0 | G22: 0 | H22: 0 | I22: 0 | J22: 0 | K22: 自身 | L22: なし | M22: なし | N22: 0 | O22: 0 | P22: 使用者と同じ | Q22: 無効 | R22: 自身 | S22: 0 | T22: 1 | U22: 即時 | V22: 0 | W22: 0 | X22: 無効 | DI22: パッシブ | DJ22: 使用者 | DK22: 追従なし | DL22: 命中時 | DM22: 1 | DN22: 攻撃範囲 | DO22: 10 | DP22: なし | DQ22: 0 | DR22: なし | DS22: 0
A23: 22 | B23: 会心率＋10％ | C23: 枠にセット中のみ有効。 | D23: 1 | E23: 1 | F23: 0 | G23: 0 | H23: 0 | I23: 0 | J23: 0 | K23: 自身 | L23: なし | M23: なし | N23: 0 | O23: 0 | P23: 使用者と同じ | Q23: 無効 | R23: 自身 | S23: 0 | T23: 1 | U23: 即時 | V23: 0 | W23: 0 | X23: 無効 | DI23: パッシブ | DJ23: 使用者 | DK23: 追従なし | DL23: 命中時 | DM23: 1 | DN23: 会心率 | DO23: 10 | DP23: なし | DQ23: 0 | DR23: なし | DS23: 0
A24: 23 | B24: 会心倍率＋10％ | C24: 枠にセット中のみ有効。 | D24: 1 | E24: 1 | F24: 0 | G24: 0 | H24: 0 | I24: 0 | J24: 0 | K24: 自身 | L24: なし | M24: なし | N24: 0 | O24: 0 | P24: 使用者と同じ | Q24: 無効 | R24: 自身 | S24: 0 | T24: 1 | U24: 即時 | V24: 0 | W24: 0 | X24: 無効 | DI24: パッシブ | DJ24: 使用者 | DK24: 追従なし | DL24: 命中時 | DM24: 1 | DN24: 会心倍率 | DO24: 10 | DP24: なし | DQ24: 0 | DR24: なし | DS24: 0
A25: 24 | B25: 素材ドロップ率＋10％ | C25: 枠にセット中のみ有効。 | D25: 1 | E25: 1 | F25: 0 | G25: 0 | H25: 0 | I25: 0 | J25: 0 | K25: 自身 | L25: なし | M25: なし | N25: 0 | O25: 0 | P25: 使用者と同じ | Q25: 無効 | R25: 自身 | S25: 0 | T25: 1 | U25: 即時 | V25: 0 | W25: 0 | X25: 無効 | DI25: パッシブ | DJ25: 使用者 | DK25: 追従なし | DL25: 命中時 | DM25: 1 | DN25: 素材ドロップ率 | DO25: 10 | DP25: なし | DQ25: 0 | DR25: なし | DS25: 0
... A39: 38 | B39: 敵リスポーン速度＋10％ | C39: 枠にセット中のみ有効。 | D39: 1 | E39: 1 | F39: 0 | G39: 0 | H39: 0 | I39: 0 | J39: 0 | K39: 自身 | L39: なし | M39: なし | N39: 0 | O39: 0 | P39: 使用者と同じ | Q39: 無効 | R39: 自身 | S39: 0 | T39: 1 | U39: 即時 | V39: 0 | W39: 0 | X39: 無効 | DI39: パッシブ | DJ39: 使用者 | DK39: 追従なし | DL39: 命中時 | DM39: 1 | DN39: 敵リスポーン速度 | DO39: 10 | DP39: なし | DQ39: 0 | DR39: なし | DS39: 0
A40: 39 | B40: 衝撃波 | C40: 使用者の位置に衝撃波を表示し、半径3の敵へ一度だけダメージを与える。 | D40: 1 | E40: 1 | F40: 10 | G40: 8 | H40: 0 | I40: 0.2 | J40: 6 | K40: 自身 | L40: ダメージ | M40: 攻撃力 | N40: 1.5 | O40: 0 | P40: 使用者と同じ | Q40: 無効 | R40: 範囲内の敵 | S40: 3 | T40: 0 | U40: 発射物 | V40: 1 | W40: 0.35 | X40: 無効 | AA40: なし | AB40: なし | AC40: なし | AD40: 0 | AE40: 0 | AF40: 0 | AG40: なし | AH40: 0 | AI40: 時間更新 | AJ40: 1 | AK40: なし | AL40: なし | AM40: なし | AN40: 0 | AO40: 0 | AP40: 0 | AQ40: なし | AR40: 0 | AS40: 時間更新 | AT40: 1 | AU40: なし | AV40: なし | AW40: なし | AX40: 0 | AY40: 0 | AZ40: 0 | BA40: なし | BB40: 0 | BC40: 時間更新 | BD40: 1 | BE40: 1 | BF40: 0.35 | BG40: 無効 | BI40: 有効 | BJ40: 無効 | BK40: 360 | BL40: 無効 | BM40: 0.3 | BN40: 2 | BO40: 無効 | BP40: 3 | BQ40: 50 | BR40: 3 | BS40: 爆発 | BT40: 8 | BU40: 0.8 | BV40: 2 | BW40: 0.8 | BX40: 12 | BY40: 0.8 | BZ40: 1.5 | CA40: 720 | CB40: 0.6 | CC40: 540 | CD40: 1.8 | CE40: 4 | CF40: 4 | CG40: 有効 | CH40: 無効 | CI40: 無効 | CJ40: 0.5 | CK40: 1.5 | CL40: 2.5 | CM40: 2.5 | CN40: 無効 | CO40: 1 | CP40: 追尾 | CQ40: 10 | CR40: 無効 | CS40: 4 | CT40: 8 | CU40: 0.85 | CV40: 無効 | CW40: 2 | CX40: 50 | CY40: 0.5 | CZ40: 1 | DA40: 無効 | DB40: 無効 | DC40: 2 | DD40: 0.4 | DE40: 3 | DF40: #FFE6A6FF | DG40: 60 | DH40: 0 | DI40: アクティブ | DJ40: 使用者 | DK40: 追従なし | DL40: 生成時 | DM40: 1 | DN40: なし | DO40: 0 | DP40: なし | DQ40: 0 | DR40: なし | DS40: 0 | DT40: 衝撃波 | DU40: 有効 | DV40: 0.35 | DW40: 0.1
A41: 40 | B41: 炎の陣 | C41: 使用した地点に5秒残り、0.5秒ごとに半径3の敵へ火属性ダメージを与える。 | D41: 1 | E41: 1 | F41: 10 | G41: 8 | H41: 0 | I41: 0.2 | J41: 6 | K41: 自身 | L41: ダメージ | M41: 魔法攻撃力 | N41: 0.5 | O41: 0 | P41: 火 | Q41: 無効 | R41: 範囲内の敵 | S41: 3 | T41: 0 | U41: 発射物 | V41: 1 | W41: 5 | X41: 無効 | AA41: なし | AB41: なし | AC41: なし | AD41: 0 | AE41: 0 | AF41: 0 | AG41: なし | AH41: 0 | AI41: 時間更新 | AJ41: 1 | AK41: なし | AL41: なし | AM41: なし | AN41: 0 | AO41: 0 | AP41: 0 | AQ41: なし | AR41: 0 | AS41: 時間更新 | AT41: 1 | AU41: なし | AV41: なし | AW41: なし | AX41: 0 | AY41: 0 | AZ41: 0 | BA41: なし | BB41: 0 | BC41: 時間更新 | BD41: 1 | BE41: 1 | BF41: 5 | BG41: 無効 | BI41: 有効 | BJ41: 無効 | BK41: 360 | BL41: 無効 | BM41: 0.3 | BN41: 2 | BO41: 無効 | BP41: 3 | BQ41: 50 | BR41: 3 | BS41: その場 | BT41: 8 | BU41: 0.8 | BV41: 2 | BW41: 0.8 | BX41: 12 | BY41: 0.8 | BZ41: 1.5 | CA41: 720 | CB41: 0.6 | CC41: 540 | CD41: 1.8 | CE41: 4 | CF41: 4 | CG41: 有効 | CH41: 無効 | CI41: 無効 | CJ41: 0.5 | CK41: 1.5 | CL41: 2.5 | CM41: 2.5 | CN41: 無効 | CO41: 1 | CP41: 追尾 | CQ41: 10 | CR41: 無効 | CS41: 4 | CT41: 8 | CU41: 0.85 | CV41: 無効 | CW41: 2 | CX41: 50 | CY41: 0.5 | CZ41: 1 | DA41: 無効 | DB41: 無効 | DC41: 2 | DD41: 0.4 | DE41: 3 | DF41: #FF6B38CC | DG41: 60 | DH41: 0 | DI41: アクティブ | DJ41: 使用者 | DK41: 追従なし | DL41: 一定間隔 | DM41: 0.5 | DN41: なし | DO41: 0 | DP41: なし | DQ41: 0 | DR41: なし | DS41: 0 | DT41: 魔方陣 | DU41: 有効 | DV41: 0.35 | DW41: 0.1
A42: 41 | B42: 癒しの陣 | C42: 使用した地点に5秒残り、1秒ごとに半径3の味方を回復する。 | D42: 1 | E42: 1 | F42: 10 | G42: 8 | H42: 0 | I42: 0.2 | J42: 6 | K42: 自身 | L42: 回復 | M42: 魔法攻撃力 | N42: 0.8 | O42: 0 | P42: 使用者と同じ | Q42: 無効 | R42: 範囲内の味方 | S42: 3 | T42: 0 | U42: 発射物 | V42: 1 | W42: 5 | X42: 無効 | AA42: なし | AB42: なし | AC42: なし | AD42: 0 | AE42: 0 | AF42: 0 | AG42: なし | AH42: 0 | AI42: 時間更新 | AJ42: 1 | AK42: なし | AL42: なし | AM42: なし | AN42: 0 | AO42: 0 | AP42: 0 | AQ42: なし | AR42: 0 | AS42: 時間更新 | AT42: 1 | AU42: なし | AV42: なし | AW42: なし | AX42: 0 | AY42: 0 | AZ42: 0 | BA42: なし | BB42: 0 | BC42: 時間更新 | BD42: 1 | BE42: 1 | BF42: 5 | BG42: 無効 | BI42: 有効 | BJ42: 無効 | BK42: 360 | BL42: 無効 | BM42: 0.3 | BN42: 2 | BO42: 無効 | BP42: 3 | BQ42: 50 | BR42: 3 | BS42: その場 | BT42: 8 | BU42: 0.8 | BV42: 2 | BW42: 0.8 | BX42: 12 | BY42: 0.8 | BZ42: 1.5 | CA42: 720 | CB42: 0.6 | CC42: 540 | CD42: 1.8 | CE42: 4 | CF42: 4 | CG42: 有効 | CH42: 無効 | CI42: 無効 | CJ42: 0.5 | CK42: 1.5 | CL42: 2.5 | CM42: 2.5 | CN42: 無効 | CO42: 1 | CP42: 追尾 | CQ42: 10 | CR42: 無効 | CS42: 4 | CT42: 8 | CU42: 0.85 | CV42: 無効 | CW42: 2 | CX42: 50 | CY42: 0.5 | CZ42: 1 | DA42: 無効 | DB42: 無効 | DC42: 2 | DD42: 0.4 | DE42: 3 | DF42: #70FFACB3 | DG42: 60 | DH42: 0 | DI42: アクティブ | DJ42: 使用者 | DK42: 追従なし | DL42: 一定間隔 | DM42: 1 | DN42: なし | DO42: 0 | DP42: なし | DQ42: 0 | DR42: なし | DS42: 0 | DT42: 魔方陣 | DU42: 有効 | DV42: 0.35 | DW42: 0.1
A43: 42 | B43: 守護の陣 | C43: 使用した地点に5秒残り、1秒ごとに半径3の味方へ防御力＋30％を1.5秒付与する。 | D43: 1 | E43: 1 | F43: 10 | G43: 8 | H43: 0 | I43: 0.2 | J43: 6 | K43: 自身 | L43: なし | M43: なし | N43: 0 | O43: 0 | P43: 使用者と同じ | Q43: 無効 | R43: 範囲内の味方 | S43: 3 | T43: 0 | U43: 発射物 | V43: 1 | W43: 5 | X43: 無効 | AA43: バフ | AB43: 防御力 | AC43: 割合変化 | AD43: 30 | AE43: 1.5 | AF43: 100 | AG43: なし | AH43: 0 | AI43: 時間更新 | AJ43: 1 | AK43: なし | AL43: なし | AM43: なし | AN43: 0 | AO43: 0 | AP43: 0 | AQ43: なし | AR43: 0 | AS43: 時間更新 | AT43: 1 | AU43: なし | AV43: なし | AW43: なし | AX43: 0 | AY43: 0 | AZ43: 0 | BA43: なし | BB43: 0 | BC43: 時間更新 | BD43: 1 | BE43: 1 | BF43: 5 | BG43: 無効 | BI43: 有効 | BJ43: 無効 | BK43: 360 | BL43: 無効 | BM43: 0.3 | BN43: 2 | BO43: 無効 | BP43: 3 | BQ43: 50 | BR43: 3 | BS43: その場 | BT43: 8 | BU43: 0.8 | BV43: 2 | BW43: 0.8 | BX43: 12 | BY43: 0.8 | BZ43: 1.5 | CA43: 720 | CB43: 0.6 | CC43: 540 | CD43: 1.8 | CE43: 4 | CF43: 4 | CG43: 有効 | CH43: 無効 | CI43: 無効 | CJ43: 0.5 | CK43: 1.5 | CL43: 2.5 | CM43: 2.5 | CN43: 無効 | CO43: 1 | CP43: 追尾 | CQ43: 10 | CR43: 無効 | CS43: 4 | CT43: 8 | CU43: 0.85 | CV43: 無効 | CW43: 2 | CX43: 50 | CY43: 0.5 | CZ43: 1 | DA43: 無効 | DB43: 無効 | DC43: 2 | DD43: 0.4 | DE43: 3 | DF43: #83BCFFB3 | DG43: 60 | DH43: 0 | DI43: アクティブ | DJ43: 使用者 | DK43: 追従なし | DL43: 一定間隔 | DM43: 1 | DN43: なし | DO43: 0 | DP43: なし | DQ43: 0 | DR43: なし | DS43: 0 | DT43: 魔方陣 | DU43: 有効 | DV43: 0.35 | DW43: 0.1
V44: =IF($A44="","",IF(AND($U44="発射物",$DI44<>"パッシブ"),$BE44,0)) | W44: =IF($A44="","",IF(AND($U44="発射物",$DI44<>"パッシブ"),$BF44,0)) | X44: =IF($A44="","",IF(AND($U44="発射物",$DI44<>"パッシブ"),IF($BG44="有効","有効","無効"),"無効"))
V45: =IF($A45="","",IF(AND($U45="発射物",$DI45<>"パッシブ"),$BE45,0)) | W45: =IF($A45="","",IF(AND($U45="発射物",$DI45<>"パッシブ"),$BF45,0)) | X45: =IF($A45="","",IF(AND($U45="発射物",$DI45<>"パッシブ"),IF($BG45="有効","有効","無効"),"無効"))
V46: =IF($A46="","",IF(AND($U46="発射物",$DI46<>"パッシブ"),$BE46,0)) | W46: =IF($A46="","",IF(AND($U46="発射物",$DI46<>"パッシブ"),$BF46,0)) | X46: =IF($A46="","",IF(AND($U46="発射物",$DI46<>"パッシブ"),IF($BG46="有効","有効","無効"),"無効"))
V47: =IF($A47="","",IF(AND($U47="発射物",$DI47<>"パッシブ"),$BE47,0)) | W47: =IF($A47="","",IF(AND($U47="発射物",$DI47<>"パッシブ"),$BF47,0)) | X47: =IF($A47="","",IF(AND($U47="発射物",$DI47<>"パッシブ"),IF($BG47="有効","有効","無効"),"無効"))
V48: =IF($A48="","",IF(AND($U48="発射物",$DI48<>"パッシブ"),$BE48,0)) | W48: =IF($A48="","",IF(AND($U48="発射物",$DI48<>"パッシブ"),$BF48,0)) | X48: =IF($A48="","",IF(AND($U48="発射物",$DI48<>"パッシブ"),IF($BG48="有効","有効","無効"),"無効"))
V49: =IF($A49="","",IF(AND($U49="発射物",$DI49<>"パッシブ"),$BE49,0)) | W49: =IF($A49="","",IF(AND($U49="発射物",$DI49<>"パッシブ"),$BF49,0)) | X49: =IF($A49="","",IF(AND($U49="発射物",$DI49<>"パッシブ"),IF($BG49="有効","有効","無効"),"無効"))
V50: =IF($A50="","",IF(AND($U50="発射物",$DI50<>"パッシブ"),$BE50,0)) | W50: =IF($A50="","",IF(AND($U50="発射物",$DI50<>"パッシブ"),$BF50,0)) | X50: =IF($A50="","",IF(AND($U50="発射物",$DI50<>"パッシブ"),IF($BG50="有効","有効","無効"),"無効"))
V51: =IF($A51="","",IF(AND($U51="発射物",$DI51<>"パッシブ"),$BE51,0)) | W51: =IF($A51="","",IF(AND($U51="発射物",$DI51<>"パッシブ"),$BF51,0)) | X51: =IF($A51="","",IF(AND($U51="発射物",$DI51<>"パッシブ"),IF($BG51="有効","有効","無効"),"無効"))
V52: =IF($A52="","",IF(AND($U52="発射物",$DI52<>"パッシブ"),$BE52,0)) | W52: =IF($A52="","",IF(AND($U52="発射物",$DI52<>"パッシブ"),$BF52,0)) | X52: =IF($A52="","",IF(AND($U52="発射物",$DI52<>"パッシブ"),IF($BG52="有効","有効","無効"),"無効"))
V53: =IF($A53="","",IF(AND($U53="発射物",$DI53<>"パッシブ"),$BE53,0)) | W53: =IF($A53="","",IF(AND($U53="発射物",$DI53<>"パッシブ"),$BF53,0)) | X53: =IF($A53="","",IF(AND($U53="発射物",$DI53<>"パッシブ"),IF($BG53="有効","有効","無効"),"無効"))
...

Sheet 素材
A1: ID | B1: 名前 | C1: 種別
A2: MAT_001 | B2: 蒼澄の粘晶 | C2: Monster
A3: MAT_002 | B3: 灼熱の粘晶 | C3: Monster
A4: MAT_003 | B4: 翠命の粘晶 | C4: Monster
A5: MAT_004 | B5: 炎牙獣の猛牙 | C5: Monster
A6: MAT_005 | B6: 氷牙獣の凍牙 | C6: Monster
A7: MAT_006 | B7: 虹幻の粘晶 | C7: Monster
A8: MATD_001 | B8: 翠泉の霊鉱 | C8: Dungeon

Sheet マップ
A1: MapID | B1: マップの説明 | C1: マップの説明 | D1: サムネイル画像 | E1: 地形生成用JSON名 | F1: ノーマルモンスター1 | G1: ノーマルモンスター2 | H1: ノーマルモンスター3 | I1: ノーマルモンスター4 | J1: ノーマルモンスター5 | K1: ボスモンスター | L1: ダンジョン固有素材ID | M1: ダンジョン固有装備1 | N1: ダンジョン固有装備2 | O1: ダンジョン固有装備3 | P1: 推奨レベル | Q1: 通常モンスターの出現レベル | R1: 強敵の出現レベル
A2: MAP_001 | B2: 始まりの平野 | C2: スライムとボアが生息する平原 | D2: 1 | E2: 平野1 | F2: MON_001 | G2: MON_002 | H2: MON_003 | I2: MON_004 | J2: MON_005 | K2: MON_006 | L2: MATD_001 | M2: EQP_003 | N2: EQP_004 | O2: EQP_005 | P2: 1 | Q2: 1 | R2: 5

Sheet マップ地形
A1: 地形生成用JSON名 | B1: 幅 | C1: 高さ | D1: Seed | E1: マス | F1: 種類 | G1: 素材名 | H1: 配置率 | I1: 上出入口 | J1: 下出入口 | K1: 左出入口 | L1: 右出入口
A2: 平野1 | B2: 51 | C2: 51 | D2: 12345 | E2: 1*1 | F2: 地面 | G2: 平野_芝 | H2: 100 | I2: FALSE | J2: TRUE | K2: FALSE | L2: TRUE
A3: 平野1 | B3: 51 | C3: 51 | D3: 12345 | E3: 1*1 | F3: 道 | G3: 平野_土_十字 | H3: 3 | I3: FALSE | J3: TRUE | K3: FALSE | L3: TRUE
A4: 平野1 | B4: 51 | C4: 51 | D4: 12345 | E4: 1*1 | F4: 道 | G4: 平野_土_縦 | H4: 2 | I4: FALSE | J4: TRUE | K4: FALSE | L4: TRUE
A5: 平野1 | B5: 51 | C5: 51 | D5: 12345 | E5: 1*1 | F5: 道 | G5: 平野_土_横 | H5: 2 | I5: FALSE | J5: TRUE | K5: FALSE | L5: TRUE
A6: 平野1 | B6: 51 | C6: 51 | D6: 12345 | E6: 1*1 | F6: 当たり判定なしobject | G6: 平野_花 | H6: 1 | I6: FALSE | J6: TRUE | K6: FALSE | L6: TRUE
A7: 平野1 | B7: 51 | C7: 51 | D7: 12345 | E7: 1*1 | F7: コリジョン | G7: 平野_切り株 | H7: 1 | I7: FALSE | J7: TRUE | K7: FALSE | L7: TRUE
A8: 平野1 | B8: 51 | C8: 51 | D8: 12345 | E8: 1*1 | F8: コリジョン | G8: 平野_水溜り | H8: 1 | I8: FALSE | J8: TRUE | K8: FALSE | L8: TRUE
A9: 平野1 | B9: 51 | C9: 51 | D9: 12345 | E9: 2*2 | F9: コリジョン | G9: 平野_池 | H9: 1 | I9: FALSE | J9: TRUE | K9: FALSE | L9: TRUE

Sheet GPTマップ作製
A1: 村 | B1: ファイル名コピペ用
A2: 31*31 | C2: 地面
A3: 地面 | C3: 1*1 | D3: 芝
A4: =C3&" "&$A$1&"_"&D3 -> 1*1 村_芝 | B4: =$A$1&"_"&D3 -> 村_芝 | C4: 1*1 | D4: 石畳
A5: =C4&" "&$A$1&"_"&D4 -> 1*1 村_石畳 | B5: =$A$1&"_"&D4 -> 村_石畳
C6: コリジョン | F6: =+A19 -> 当たり判定なしObject
A7: 道 | C7: 2*2 | D7: 井戸 | E7: 30.31.38.39 | F7: 1*1 | G7: ピンク花 | H7: 3
A8: ="1*1 "&$A$1&"_道_十字" -> 1*1 村_道_十字 | B8: =$A$1&"_道_十字" -> 村_道_十字 | C8: 2*1 | D8: 薪 | E8: 28.29 | F8: 1*1 | G8: 黄色花 | H8: 4
A9: ="1*1 "&$A$1&"_道_縦" -> 1*1 村_道_縦 | B9: =$A$1&"_道_縦" -> 村_道_縦 | C9: 1*1 | D9: 墓 | E9: 26 | F9: 1*1 | G9: 紫花 | H9: 6
A10: ="1*1 "&$A$1&"_道_横" -> 1*1 村_道_横 | B10: =$A$1&"_道_横" -> 村_道_横 | C10: 1*2 | D10: 薪割株 | E10: 13.21 | F10: 1*1 | G10: 青草 | H10: 8
C11: 1*1 | D11: 水汲み桶 | E11: 24 | F11: 1*1 | G11: 枝 | H11: 16
A12: コリジョン
A13: =C7&" "&$A$1&"_"&D7 -> 2*2 村_井戸 | B13: =$A$1&"_"&D7&"_" -> 村_井戸_
A14: =C8&" "&$A$1&"_"&D8 -> 2*1 村_薪 | B14: =$A$1&"_"&D8&"_" -> 村_薪_
A15: =C9&" "&$A$1&"_"&D9 -> 1*1 村_墓 | B15: =$A$1&"_"&D9&"_" -> 村_墓_
A16: =C10&" "&$A$1&"_"&D10 -> 1*2 村_薪割株 | B16: =$A$1&"_"&D10&"_" -> 村_薪割株_
A17: =C11&" "&$A$1&"_"&D11 -> 1*1 村_水汲み桶 | B17: =$A$1&"_"&D11&"_" -> 村_水汲み桶_
A19: 当たり判定なしObject
A20: =F7&" "&$A$1&"_"&G7 -> 1*1 村_ピンク花 | B20: =$A$1&"_"&G7&"_" -> 村_ピンク花_
A21: =F8&" "&$A$1&"_"&G8 -> 1*1 村_黄色花 | B21: =$A$1&"_"&G8&"_" -> 村_黄色花_
A22: =F9&" "&$A$1&"_"&G9 -> 1*1 村_紫花 | B22: =$A$1&"_"&G9&"_" -> 村_紫花_
A23: =F10&" "&$A$1&"_"&G10 -> 1*1 村_青草 | B23: =$A$1&"_"&G10&"_" -> 村_青草_
A24: =F11&" "&$A$1&"_"&G11 -> 1*1 村_枝 | B24: =$A$1&"_"&G11&"_" -> 村_枝_

Sheet 必要経験値
A1: Level | B1: PlayerRequiredExp | C1: MonsterRequiredExp
A2: 1 | B2: 10 | C2: 10
A3: 2 | B3: 40 | C3: 40
A4: 3 | B4: 90 | C4: 90
A5: 4 | B5: 160 | C5: 160
A6: 5 | B6: 250 | C6: 250
A7: 6 | B7: 360 | C7: 360
A8: 7 | B8: 490 | C8: 490
A9: 8 | B9: 640 | C9: 640
A10: 9 | B10: 810 | C10: 810
A11: 10 | B11: 1000 | C11: 1000
A12: 11 | B12: 1210 | C12: 1210
A13: 12 | B13: 1440 | C13: 1440
... A10000: 9999 | B10000: 0 | C10000: 0

Sheet 入力規制リスト
A1: 火 | B1: FireBall | C1: Melee | D1: TRUE | E1: 武器
A2: 水 | B2: WaterBall | C2: Ranged | D2: FALSE | E2: 防具
A3: 風 | B3: WindBall | E3: アクセサリー
A4: 雷 | B4: LightningBall
A5: 光 | B5: LightBall
A6: 闇 | B6: DarkBall
A7: None | B7: None

Sheet 画像編集用

Sheet やることリスト
A1: ・消耗品ショップの実装
A2: HP回復ポーション(3段階）MP回復ポーション(3段階）魔寄せの鈴(1分間マップ上の全敵がこちらに向かってくる)
A8: ・スキルの実装
A9: スキルはプレイヤーはトリガーとボタンで発動する。トリガーは様々な条件を設定でき、その条件を満たしたら自動で発動させる形式にする。
A10: モンスターのスキルは仲間側はトリガーを設定でき、その条件を満たしたときに自動で発動する。敵側は、ボスモンスター等にスキルを設定してクールダウン後、自動発動するようにする。
A11: スキルは、プレイヤー、全モンスターで共通のものにし、同じ挙動をするようにする。
