Workbook

Sheet 使い方
A1: モンスター戦闘力 自動配分シート
A3: はじめに | B3: いただいた『モンスター計算シート.csv』をベースに、同Stage6体の目標戦闘力を揃えた試算です。
A4: ① 成長倍率 | B4: 『モンスター計算』D2（初期値1.10）を変更 → 全モンスターの目標戦闘力と基礎値を再計算。
A5: ② 目標戦闘力 | B5: 各Stage = 『設定』初期戦闘力 × 成長倍率^(Stage-1)。同Stageは同じ値。
A6: ③ 個性調整 | B6: AM列で50種類から個性タイプを選択。係数・耐性が連動します。
A7: ④ 自動配分 | B7: タイプを変更すると各ステータスを自動配分します。
A8: 個性タイプを選ぶ | B8: 『モンスター計算』AM列をプルダウン選択。HP・防御・攻速・射程・会心・移動速度・MPなどが連動。
A9: 属性を選ぶ | B9: 『モンスター計算』C列をプルダウン選択。属性耐性マスタの6属性耐性を参照して自動配分。
A10: タイプを編集 | B10: 『個性タイプマスタ』A5:P30のタイプ定義を調整。同じタイプの全モンスターに反映。空欄行は新タイプ用。
A11: 耐性を編集 | B11: 『属性耐性マスタ』の行＝属性、列＝耐性。個性タイプの一律耐性補正を足した結果がP:Uに出ます。
A12: 自動計算の範囲 | B12: 攻撃方式X、HP等の指数Y:AD、クリ率K・クリ倍L・移速M、耐性P:U、索敵Vを自動化。
A13: CSV出力 | B13: Windows版Excelで保存→『ExportToCSV.bat』で再計算・CSV出力。モンスター.csvを横に置くとUnity用をマージ。
A14: 注意事項 | B14: タイプの数値はバランス調整用の試算。親密度の実装は別工程。CSVで差し替えると既存の種族基礎値が変更されます。
... A18: 推定戦闘力 | B18: 戦闘力はDPS×耐久の目安で、耐性も一部評価。実戦のスキル・射程・属性相性までは完全再現しません。

Sheet 設定
A1: バランス設定（青色セルは変更可）
A4: 成長倍率（参照） | B4: =モンスター計算!$D$2 -> 1.1 | C4: 『モンスター計算』D2を編集
A5: Stage1基準戦闘力 | B5: 100 | C5: 通常100
A6: 基準HP | B6: 100 | C6: 戦闘力100の耐久基準
A7: 基準主攻撃力 | B7: 18 | C7: 魔法型の魔力／近接型の攻撃力に対応
A8: 基準物理防御 | B8: 8 | C8: 強さ推定用・CSV出力
A9: 基準魔法防御 | B9: 8 | C9: 強さ推定用・CSV出力
A10: 基準攻撃速度 | B10: 1 | C10: 攻撃ゲージ/秒
A11: 基準クリティカル率 | B11: 0.05 | C11: 0.05=5%
A12: 基準クリ倍率 | B12: 1.5 | C12: 1.5倍
A13: 防御評価係数 | B13: 0.3 | C13: 推定耐久指数への重み
A14: 射程評価係数 | B14: 0.12 | C14: 基準射程からの差の重み
A15: MP配分係数 | B15: 0.6 | C15: 魔法型のMPは追加係数1.35
A16: 副攻撃力の比率 | B16: 0.45 | C16: 普段使わない攻撃/魔力も残す
... A19: 索敵範囲の標準値 | B19: 4 | C19: 各個性タイプの索敵倍率を掛ける基準

Sheet モンスター計算
A1: MONSTER POWER BALANCER | D1: 成長倍率（編集）
D2: 1.1
A3: 水色＝タイプ・属性・成長倍率を編集 / 緑色＝自動計算 / 個性タイプマスタ・属性耐性マスタで一括調整
A4: ID | B4: 名前 | C4: 属性 | D4: 戦闘力 | E4: 基礎HP | F4: 基礎MP | G4: 基礎攻撃力 | H4: 基礎魔力 | I4: 基礎防御力 | J4: 基礎魔防 | K4: クリ率 | L4: クリ倍 | M4: 移動速度 | N4: 攻撃速度 | O4: 攻撃範囲 | P4: 火耐性 | Q4: 水耐性 | R4: 風耐性 | S4: 雷耐性 | T4: 光耐性 | U4: 闇耐性 | V4: 索敵範囲 | W4: 出現ステージ | X4: 攻撃方式 | Y4: HP個性倍率 | Z4: 物防個性倍率 | AA4: 魔防個性倍率 | AB4: 攻速個性倍率 | AC4: 射程個性倍率 | AD4: 親密度Lv1戦闘力比 | AE4: ステージ倍率 | AF4: 防御補正指数 | AG4: 射程補正指数 | AH4: 想定DPS | AI4: 想定耐久値 | AJ4: 推定総合戦闘力 | AK4: 目標差率 | AL4: 親密度Lv1想定戦闘力 | AM4: 個性タイプ | AN4: 必要主攻撃値 | AO4: タイプ照合 | AP4: 属性照合
A5: MON_001 | B5: ブルースライム | C5: 水 | D5: =ROUND(設定!$B$5*POWER($D$2,W5-1),2) -> 100 | E5: =MAX(1,ROUND(設定!$B$6*AE5*Y5,0)) -> 82 | F5: =MAX(0,ROUND(設定!$B$7*AE5*設定!$B$15*IF(X5="Melee",0.6,1.35)*IFERROR(VLOOKUP($AM5,個性タイプマスタ!$A$5:$P$100,14,FALSE),1),0)) -> 13 | G5: =IF(X5="Melee",AN5,MAX(1,ROUND(AN5*設定!$B$16*IFERROR(VLOOKUP($AM5,個性タイプマスタ!$A$5:$P$100,15,FALSE),1),0))) -> 10 | H5: =IF(X5="Ranged",AN5,MAX(1,ROUND(AN5*設定!$B$16*IFERROR(VLOOKUP($AM5,個性タイプマスタ!$A$5:$P$100,15,FALSE),1),0))) -> 22 | I5: =MAX(0,ROUND(設定!$B$8*AE5*Z5,0)) -> 7 | J5: =MAX(0,ROUND(設定!$B$9*AE5*AA5,0)) -> 8 | K5: =IFERROR(VLOOKUP($AM5,個性タイプマスタ!$A$5:$P$100,9,FALSE),0.05) -> 0.05 | L5: =IFERROR(VLOOKUP($AM5,個性タイプマスタ!$A$5:$P$100,10,FALSE),1.5) -> 1.5 | M5: =IFERROR(VLOOKUP($AM5,個性タイプマスタ!$A$5:$P$100,11,FALSE),2) -> 2 | N5: =MAX(0.1,ROUND(設定!$B$10*AB5,3)) -> 1 | O5: =MAX(0.1,ROUND(IF(X5="Melee",1.5,2.5)*AC5,3)) -> 2.5 | P5: =MAX(-10,MIN(0.8,IFERROR(INDEX(属性耐性マスタ!$B$5:$G$11,MATCH($C5,属性耐性マスタ!$A$5:$A$11,0),1),0)+IFERROR(VLOOKUP($AM5,個性タイプマスタ!$A$5:$P$100,12,FALSE),0))) -> -0.12 | Q5: =MAX(-10,MIN(0.8,IFERROR(INDEX(属性耐性マスタ!$B$5:$G$11,MATCH($C5,属性耐性マスタ!$A$5:$A$11,0),2),0)+IFERROR(VLOOKUP($AM5,個性タイプマスタ!$A$5:$P$100,12,FALSE),0))) -> 0.18 | R5: =MAX(-10,MIN(0.8,IFERROR(INDEX(属性耐性マスタ!$B$5:$G$11,MATCH($C5,属性耐性マスタ!$A$5:$A$11,0),3),0)+IFERROR(VLOOKUP($AM5,個性タイプマスタ!$A$5:$P$100,12,FALSE),0))) -> -0.02 | S5: =MAX(-10,MIN(0.8,IFERROR(INDEX(属性耐性マスタ!$B$5:$G$11,MATCH($C5,属性耐性マスタ!$A$5:$A$11,0),4),0)+IFERROR(VLOOKUP($AM5,個性タイプマスタ!$A$5:$P$100,12,FALSE),0))) -> -0.02 | T5: =MAX(-10,MIN(0.8,IFERROR(INDEX(属性耐性マスタ!$B$5:$G$11,MATCH($C5,属性耐性マスタ!$A$5:$A$11,0),5),0)+IFERROR(VLOOKUP($AM5,個性タイプマスタ!$A$5:$P$100,12,FALSE),0))) -> -0.02 | U5: =MAX(-10,MIN(0.8,IFERROR(INDEX(属性耐性マスタ!$B$5:$G$11,MATCH($C5,属性耐性マスタ!$A$5:$A$11,0),6),0)+IFERROR(VLOOKUP($AM5,個性タイプマスタ!$A$5:$P$100,12,FALSE),0))) -> -0.02 | V5: =ROUND(設定!$B$19*IFERROR(VLOOKUP($AM5,個性タイプマスタ!$A$5:$P$100,13,FALSE),1),2) -> 4 | W5: 1 | X5: =IFERROR(VLOOKUP($AM5,個性タイプマスタ!$A$5:$P$100,2,FALSE),"Ranged") -> Ranged | Y5: =IFERROR(VLOOKUP($AM5,個性タイプマスタ!$A$5:$P$100,3,FALSE),1) -> 0.82 | Z5: =IFERROR(VLOOKUP($AM5,個性タイプマスタ!$A$5:$P$100,4,FALSE),1) -> 0.85 | AA5: =IFERROR(VLOOKUP($AM5,個性タイプマスタ!$A$5:$P$100,5,FALSE),1) -> 1 | AB5: =IFERROR(VLOOKUP($AM5,個性タイプマスタ!$A$5:$P$100,6,FALSE),1) -> 1 | AC5: =IFERROR(VLOOKUP($AM5,個性タイプマスタ!$A$5:$P$100,7,FALSE),1) -> 1 | AD5: =IFERROR(VLOOKUP($AM5,個性タイプマスタ!$A$5:$P$100,8,FALSE),1) -> 0.68 | AE5: =IFERROR(D5/設定!$B$5,1) -> 1 | AF5: =1+設定!$B$13*((I5/設定!$B$8+J5/設定!$B$9)/(2*AE5)) -> 1.28125 | AG5: =MAX(0.7,1+設定!$B$14*(O5/IF(X5="Melee",1.5,2.5)-1)) -> 1 | AH5: =IF(X5="Melee",G5,H5)*N5*(1+K5*(L5-1))*AG5 -> 22.55 | AI5: =E5*AF5*(1+設定!$B$18*AVERAGE(P5:U5)) -> 104.90491 | AJ5: =設定!$B$5*SQRT((AH5/(設定!$B$7*設定!$B$10*(1+設定!$B$11*(設定!$B$12-1))))*(AI5/(設定!$B$6*(1+設定!$B$13)))) -> 99.311905 | AK5: =IF(D5=0,0,AJ5/D5-1) -> -0.0068809521 | AL5: =D5*AD5 -> 68 | AM5: 魔法・軽量 | AN5: =MAX(1,ROUND((設定!$B$7*設定!$B$10*(1+設定!$B$11*(設定!$B$12-1)))*AE5^2*(設定!$B$6*(1+設定!$B$13))/(AI5*N5*(1+K5*(L5-1))*AG5),0)) -> 22 | AO5: =IF($A5="","",IF(COUNTIF(個性タイプマスタ!$A$5:$A$100,$AM5)>0,"OK","未登録")) -> OK | AP5: =IF($A5="","",IF(COUNTIF(属性耐性マスタ!$A$5:$A$11,$C5)>0,"OK","未登録")) -> OK
A6: MON_002 | B6: レッドスライム | C6: 火 | D6: =ROUND(設定!$B$5*POWER($D$2,W6-1),2) -> 100 | E6: =MAX(1,ROUND(設定!$B$6*AE6*Y6,0)) -> 112 | F6: =MAX(0,ROUND(設定!$B$7*AE6*設定!$B$15*IF(X6="Melee",0.6,1.35)*IFERROR(VLOOKUP($AM6,個性タイプマスタ!$A$5:$P$100,14,FALSE),1),0)) -> 20 | G6: =IF(X6="Melee",AN6,MAX(1,ROUND(AN6*設定!$B$16*IFERROR(VLOOKUP($AM6,個性タイプマスタ!$A$5:$P$100,15,FALSE),1),0))) -> 5 | H6: =IF(X6="Ranged",AN6,MAX(1,ROUND(AN6*設定!$B$16*IFERROR(VLOOKUP($AM6,個性タイプマスタ!$A$5:$P$100,15,FALSE),1),0))) -> 16 | I6: =MAX(0,ROUND(設定!$B$8*AE6*Z6,0)) -> 16 | J6: =MAX(0,ROUND(設定!$B$9*AE6*AA6,0)) -> 6 | K6: =IFERROR(VLOOKUP($AM6,個性タイプマスタ!$A$5:$P$100,9,FALSE),0.05) -> 0.055 | L6: =IFERROR(VLOOKUP($AM6,個性タイプマスタ!$A$5:$P$100,10,FALSE),1.5) -> 1.5 | M6: =IFERROR(VLOOKUP($AM6,個性タイプマスタ!$A$5:$P$100,11,FALSE),2) -> 1.85 | N6: =MAX(0.1,ROUND(設定!$B$10*AB6,3)) -> 0.87 | O6: =MAX(0.1,ROUND(IF(X6="Melee",1.5,2.5)*AC6,3)) -> 2.35 | P6: =MAX(-10,MIN(0.8,IFERROR(INDEX(属性耐性マスタ!$B$5:$G$11,MATCH($C6,属性耐性マスタ!$A$5:$A$11,0),1),0)+IFERROR(VLOOKUP($AM6,個性タイプマスタ!$A$5:$P$100,12,FALSE),0))) -> 0.265 | Q6: =MAX(-10,MIN(0.8,IFERROR(INDEX(属性耐性マスタ!$B$5:$G$11,MATCH($C6,属性耐性マスタ!$A$5:$A$11,0),2),0)+IFERROR(VLOOKUP($AM6,個性タイプマスタ!$A$5:$P$100,12,FALSE),0))) -> -0.035 | R6: =MAX(-10,MIN(0.8,IFERROR(INDEX(属性耐性マスタ!$B$5:$G$11,MATCH($C6,属性耐性マスタ!$A$5:$A$11,0),3),0)+IFERROR(VLOOKUP($AM6,個性タイプマスタ!$A$5:$P$100,12,FALSE),0))) -> 0.065 | S6: =MAX(-10,MIN(0.8,IFERROR(INDEX(属性耐性マスタ!$B$5:$G$11,MATCH($C6,属性耐性マスタ!$A$5:$A$11,0),4),0)+IFERROR(VLOOKUP($AM6,個性タイプマスタ!$A$5:$P$100,12,FALSE),0))) -> 0.065 | T6: =MAX(-10,MIN(0.8,IFERROR(INDEX(属性耐性マスタ!$B$5:$G$11,MATCH($C6,属性耐性マスタ!$A$5:$A$11,0),5),0)+IFERROR(VLOOKUP($AM6,個性タイプマスタ!$A$5:$P$100,12,FALSE),0))) -> 0.065 | U6: =MAX(-10,MIN(0.8,IFERROR(INDEX(属性耐性マスタ!$B$5:$G$11,MATCH($C6,属性耐性マスタ!$A$5:$A$11,0),6),0)+IFERROR(VLOOKUP($AM6,個性タイプマスタ!$A$5:$P$100,12,FALSE),0))) -> 0.065 | V6: =ROUND(設定!$B$19*IFERROR(VLOOKUP($AM6,個性タイプマスタ!$A$5:$P$100,13,FALSE),1),2) -> 4.2 | W6: 1 | X6: =IFERROR(VLOOKUP($AM6,個性タイプマスタ!$A$5:$P$100,2,FALSE),"Ranged") -> Ranged | Y6: =IFERROR(VLOOKUP($AM6,個性タイプマスタ!$A$5:$P$100,3,FALSE),1) -> 1.12 | Z6: =IFERROR(VLOOKUP($AM6,個性タイプマスタ!$A$5:$P$100,4,FALSE),1) -> 1.95 | AA6: =IFERROR(VLOOKUP($AM6,個性タイプマスタ!$A$5:$P$100,5,FALSE),1) -> 0.72 | AB6: =IFERROR(VLOOKUP($AM6,個性タイプマスタ!$A$5:$P$100,6,FALSE),1) -> 0.87 | AC6: =IFERROR(VLOOKUP($AM6,個性タイプマスタ!$A$5:$P$100,7,FALSE),1) -> 0.94 | AD6: =IFERROR(VLOOKUP($AM6,個性タイプマスタ!$A$5:$P$100,8,FALSE),1) -> 0.82 | AE6: =IFERROR(D6/設定!$B$5,1) -> 1 | AF6: =1+設定!$B$13*((I6/設定!$B$8+J6/設定!$B$9)/(2*AE6)) -> 1.4125 | AG6: =MAX(0.7,1+設定!$B$14*(O6/IF(X6="Melee",1.5,2.5)-1)) -> 0.9928 | AH6: =IF(X6="Melee",G6,H6)*N6*(1+K6*(L6-1))*AG6 -> 14.19982 | AI6: =E6*AF6*(1+設定!$B$18*AVERAGE(P6:U6)) -> 164.01385 | AJ6: =設定!$B$5*SQRT((AH6/(設定!$B$7*設定!$B$10*(1+設定!$B$11*(設定!$B$12-1))))*(AI6/(設定!$B$6*(1+設定!$B$13)))) -> 98.539832 | AK6: =IF(D6=0,0,AJ6/D6-1) -> -0.01460168 | AL6: =D6*AD6 -> 82 | AM6: 魔法・物防障壁 | AN6: =MAX(1,ROUND((設定!$B$7*設定!$B$10*(1+設定!$B$11*(設定!$B$12-1)))*AE6^2*(設定!$B$6*(1+設定!$B$13))/(AI6*N6*(1+K6*(L6-1))*AG6),0)) -> 16 | AO6: =IF($A6="","",IF(COUNTIF(個性タイプマスタ!$A$5:$A$100,$AM6)>0,"OK","未登録")) -> OK | AP6: =IF($A6="","",IF(COUNTIF(属性耐性マスタ!$A$5:$A$11,$C6)>0,"OK","未登録")) -> OK
A7: MON_003 | B7: グリーンスライム | C7: 風 | D7: =ROUND(設定!$B$5*POWER($D$2,W7-1),2) -> 100 | E7: =MAX(1,ROUND(設定!$B$6*AE7*Y7,0)) -> 92 | F7: =MAX(0,ROUND(設定!$B$7*AE7*設定!$B$15*IF(X7="Melee",0.6,1.35)*IFERROR(VLOOKUP($AM7,個性タイプマスタ!$A$5:$P$100,14,FALSE),1),0)) -> 15 | G7: =IF(X7="Melee",AN7,MAX(1,ROUND(AN7*設定!$B$16*IFERROR(VLOOKUP($AM7,個性タイプマスタ!$A$5:$P$100,15,FALSE),1),0))) -> 8 | H7: =IF(X7="Ranged",AN7,MAX(1,ROUND(AN7*設定!$B$16*IFERROR(VLOOKUP($AM7,個性タイプマスタ!$A$5:$P$100,15,FALSE),1),0))) -> 18 | I7: =MAX(0,ROUND(設定!$B$8*AE7*Z7,0)) -> 8 | J7: =MAX(0,ROUND(設定!$B$9*AE7*AA7,0)) -> 8 | K7: =IFERROR(VLOOKUP($AM7,個性タイプマスタ!$A$5:$P$100,9,FALSE),0.05) -> 0.05 | L7: =IFERROR(VLOOKUP($AM7,個性タイプマスタ!$A$5:$P$100,10,FALSE),1.5) -> 1.5 | M7: =IFERROR(VLOOKUP($AM7,個性タイプマスタ!$A$5:$P$100,11,FALSE),2) -> 2 | N7: =MAX(0.1,ROUND(設定!$B$10*AB7,3)) -> 1.05 | O7: =MAX(0.1,ROUND(IF(X7="Melee",1.5,2.5)*AC7,3)) -> 2.5 | P7: =MAX(-10,MIN(0.8,IFERROR(INDEX(属性耐性マスタ!$B$5:$G$11,MATCH($C7,属性耐性マスタ!$A$5:$A$11,0),1),0)+IFERROR(VLOOKUP($AM7,個性タイプマスタ!$A$5:$P$100,12,FALSE),0))) -> 0 | Q7: =MAX(-10,MIN(0.8,IFERROR(INDEX(属性耐性マスタ!$B$5:$G$11,MATCH($C7,属性耐性マスタ!$A$5:$A$11,0),2),0)+IFERROR(VLOOKUP($AM7,個性タイプマスタ!$A$5:$P$100,12,FALSE),0))) -> 0 | R7: =MAX(-10,MIN(0.8,IFERROR(INDEX(属性耐性マスタ!$B$5:$G$11,MATCH($C7,属性耐性マスタ!$A$5:$A$11,0),3),0)+IFERROR(VLOOKUP($AM7,個性タイプマスタ!$A$5:$P$100,12,FALSE),0))) -> 0.2 | S7: =MAX(-10,MIN(0.8,IFERROR(INDEX(属性耐性マスタ!$B$5:$G$11,MATCH($C7,属性耐性マスタ!$A$5:$A$11,0),4),0)+IFERROR(VLOOKUP($AM7,個性タイプマスタ!$A$5:$P$100,12,FALSE),0))) -> -0.1 | T7: =MAX(-10,MIN(0.8,IFERROR(INDEX(属性耐性マスタ!$B$5:$G$11,MATCH($C7,属性耐性マスタ!$A$5:$A$11,0),5),0)+IFERROR(VLOOKUP($AM7,個性タイプマスタ!$A$5:$P$100,12,FALSE),0))) -> 0 | U7: =MAX(-10,MIN(0.8,IFERROR(INDEX(属性耐性マスタ!$B$5:$G$11,MATCH($C7,属性耐性マスタ!$A$5:$A$11,0),6),0)+IFERROR(VLOOKUP($AM7,個性タイプマスタ!$A$5:$P$100,12,FALSE),0))) -> 0 | V7: =ROUND(設定!$B$19*IFERROR(VLOOKUP($AM7,個性タイプマスタ!$A$5:$P$100,13,FALSE),1),2) -> 4 | W7: 1 | X7: =IFERROR(VLOOKUP($AM7,個性タイプマスタ!$A$5:$P$100,2,FALSE),"Ranged") -> Ranged | Y7: =IFERROR(VLOOKUP($AM7,個性タイプマスタ!$A$5:$P$100,3,FALSE),1) -> 0.92 | Z7: =IFERROR(VLOOKUP($AM7,個性タイプマスタ!$A$5:$P$100,4,FALSE),1) -> 0.95 | AA7: =IFERROR(VLOOKUP($AM7,個性タイプマスタ!$A$5:$P$100,5,FALSE),1) -> 1.05 | AB7: =IFERROR(VLOOKUP($AM7,個性タイプマスタ!$A$5:$P$100,6,FALSE),1) -> 1.05 | AC7: =IFERROR(VLOOKUP($AM7,個性タイプマスタ!$A$5:$P$100,7,FALSE),1) -> 1 | AD7: =IFERROR(VLOOKUP($AM7,個性タイプマスタ!$A$5:$P$100,8,FALSE),1) -> 0.74 | AE7: =IFERROR(D7/設定!$B$5,1) -> 1 | AF7: =1+設定!$B$13*((I7/設定!$B$8+J7/設定!$B$9)/(2*AE7)) -> 1.3 | AG7: =MAX(0.7,1+設定!$B$14*(O7/IF(X7="Melee",1.5,2.5)-1)) -> 1 | AH7: =IF(X7="Melee",G7,H7)*N7*(1+K7*(L7-1))*AG7 -> 19.3725 | AI7: =E7*AF7*(1+設定!$B$18*AVERAGE(P7:U7)) -> 120.497 | AJ7: =設定!$B$5*SQRT((AH7/(設定!$B$7*設定!$B$10*(1+設定!$B$11*(設定!$B$12-1))))*(AI7/(設定!$B$6*(1+設定!$B$13)))) -> 98.65318 | AK7: =IF(D7=0,0,AJ7/D7-1) -> -0.013468196 | AL7: =D7*AD7 -> 74 | AM7: 魔法・均衡 | AN7: =MAX(1,ROUND((設定!$B$7*設定!$B$10*(1+設定!$B$11*(設定!$B$12-1)))*AE7^2*(設定!$B$6*(1+設定!$B$13))/(AI7*N7*(1+K7*(L7-1))*AG7),0)) -> 18 | AO7: =IF($A7="","",IF(COUNTIF(個性タイプマスタ!$A$5:$A$100,$AM7)>0,"OK","未登録")) -> OK | AP7: =IF($A7="","",IF(COUNTIF(属性耐性マスタ!$A$5:$A$11,$C7)>0,"OK","未登録")) -> OK
A8: MON_004 | B8: レッドボア | C8: 火 | D8: =ROUND(設定!$B$5*POWER($D$2,W8-1),2) -> 100 | E8: =MAX(1,ROUND(設定!$B$6*AE8*Y8,0)) -> 127 | F8: =MAX(0,ROUND(設定!$B$7*AE8*設定!$B$15*IF(X8="Melee",0.6,1.35)*IFERROR(VLOOKUP($AM8,個性タイプマスタ!$A$5:$P$100,14,FALSE),1),0)) -> 5 | G8: =IF(X8="Melee",AN8,MAX(1,ROUND(AN8*設定!$B$16*IFERROR(VLOOKUP($AM8,個性タイプマスタ!$A$5:$P$100,15,FALSE),1),0))) -> 25 | H8: =IF(X8="Ranged",AN8,MAX(1,ROUND(AN8*設定!$B$16*IFERROR(VLOOKUP($AM8,個性タイプマスタ!$A$5:$P$100,15,FALSE),1),0))) -> 7 | I8: =MAX(0,ROUND(設定!$B$8*AE8*Z8,0)) -> 8 | J8: =MAX(0,ROUND(設定!$B$9*AE8*AA8,0)) -> 7 | K8: =IFERROR(VLOOKUP($AM8,個性タイプマスタ!$A$5:$P$100,9,FALSE),0.05) -> 0.06 | L8: =IFERROR(VLOOKUP($AM8,個性タイプマスタ!$A$5:$P$100,10,FALSE),1.5) -> 2.15 | M8: =IFERROR(VLOOKUP($AM8,個性タイプマスタ!$A$5:$P$100,11,FALSE),2) -> 1.65 | N8: =MAX(0.1,ROUND(設定!$B$10*AB8,3)) -> 0.53 | O8: =MAX(0.1,ROUND(IF(X8="Melee",1.5,2.5)*AC8,3)) -> 1.86 | P8: =MAX(-10,MIN(0.8,IFERROR(INDEX(属性耐性マスタ!$B$5:$G$11,MATCH($C8,属性耐性マスタ!$A$5:$A$11,0),1),0)+IFERROR(VLOOKUP($AM8,個性タイプマスタ!$A$5:$P$100,12,FALSE),0))) -> 0.175 | Q8: =MAX(-10,MIN(0.8,IFERROR(INDEX(属性耐性マスタ!$B$5:$G$11,MATCH($C8,属性耐性マスタ!$A$5:$A$11,0),2),0)+IFERROR(VLOOKUP($AM8,個性タイプマスタ!$A$5:$P$100,12,FALSE),0))) -> -0.125 | R8: =MAX(-10,MIN(0.8,IFERROR(INDEX(属性耐性マスタ!$B$5:$G$11,MATCH($C8,属性耐性マスタ!$A$5:$A$11,0),3),0)+IFERROR(VLOOKUP($AM8,個性タイプマスタ!$A$5:$P$100,12,FALSE),0))) -> -0.025 | S8: =MAX(-10,MIN(0.8,IFERROR(INDEX(属性耐性マスタ!$B$5:$G$11,MATCH($C8,属性耐性マスタ!$A$5:$A$11,0),4),0)+IFERROR(VLOOKUP($AM8,個性タイプマスタ!$A$5:$P$100,12,FALSE),0))) -> -0.025 | T8: =MAX(-10,MIN(0.8,IFERROR(INDEX(属性耐性マスタ!$B$5:$G$11,MATCH($C8,属性耐性マスタ!$A$5:$A$11,0),5),0)+IFERROR(VLOOKUP($AM8,個性タイプマスタ!$A$5:$P$100,12,FALSE),0))) -> -0.025 | U8: =MAX(-10,MIN(0.8,IFERROR(INDEX(属性耐性マスタ!$B$5:$G$11,MATCH($C8,属性耐性マスタ!$A$5:$A$11,0),6),0)+IFERROR(VLOOKUP($AM8,個性タイプマスタ!$A$5:$P$100,12,FALSE),0))) -> -0.025 | V8: =ROUND(設定!$B$19*IFERROR(VLOOKUP($AM8,個性タイプマスタ!$A$5:$P$100,13,FALSE),1),2) -> 4.4 | W8: 1 | X8: =IFERROR(VLOOKUP($AM8,個性タイプマスタ!$A$5:$P$100,2,FALSE),"Ranged") -> Melee | Y8: =IFERROR(VLOOKUP($AM8,個性タイプマスタ!$A$5:$P$100,3,FALSE),1) -> 1.27 | Z8: =IFERROR(VLOOKUP($AM8,個性タイプマスタ!$A$5:$P$100,4,FALSE),1) -> 1.05 | AA8: =IFERROR(VLOOKUP($AM8,個性タイプマスタ!$A$5:$P$100,5,FALSE),1) -> 0.88 | AB8: =IFERROR(VLOOKUP($AM8,個性タイプマスタ!$A$5:$P$100,6,FALSE),1) -> 0.53 | AC8: =IFERROR(VLOOKUP($AM8,個性タイプマスタ!$A$5:$P$100,7,FALSE),1) -> 1.24 | AD8: =IFERROR(VLOOKUP($AM8,個性タイプマスタ!$A$5:$P$100,8,FALSE),1) -> 0.8 | AE8: =IFERROR(D8/設定!$B$5,1) -> 1 | AF8: =1+設定!$B$13*((I8/設定!$B$8+J8/設定!$B$9)/(2*AE8)) -> 1.28125 | AG8: =MAX(0.7,1+設定!$B$14*(O8/IF(X8="Melee",1.5,2.5)-1)) -> 1.0288 | AH8: =IF(X8="Melee",G8,H8)*N8*(1+K8*(L8-1))*AG8 -> 14.57218 | AI8: =E8*AF8*(1+設定!$B$18*AVERAGE(P8:U8)) -> 162.10855 | AJ8: =設定!$B$5*SQRT((AH8/(設定!$B$7*設定!$B$10*(1+設定!$B$11*(設定!$B$12-1))))*(AI8/(設定!$B$6*(1+設定!$B$13)))) -> 99.24197 | AK8: =IF(D8=0,0,AJ8/D8-1) -> -0.0075803037 | AL8: =D8*AD8 -> 80 | AM8: 近接・重撃 | AN8: =MAX(1,ROUND((設定!$B$7*設定!$B$10*(1+設定!$B$11*(設定!$B$12-1)))*AE8^2*(設定!$B$6*(1+設定!$B$13))/(AI8*N8*(1+K8*(L8-1))*AG8),0)) -> 25 | AO8: =IF($A8="","",IF(COUNTIF(個性タイプマスタ!$A$5:$A$100,$AM8)>0,"OK","未登録")) -> OK | AP8: =IF($A8="","",IF(COUNTIF(属性耐性マスタ!$A$5:$A$11,$C8)>0,"OK","未登録")) -> OK
A9: MON_005 | B9: ブルーボア | C9: 水 | D9: =ROUND(設定!$B$5*POWER($D$2,W9-1),2) -> 100 | E9: =MAX(1,ROUND(設定!$B$6*AE9*Y9,0)) -> 92 | F9: =MAX(0,ROUND(設定!$B$7*AE9*設定!$B$15*IF(X9="Melee",0.6,1.35)*IFERROR(VLOOKUP($AM9,個性タイプマスタ!$A$5:$P$100,14,FALSE),1),0)) -> 6 | G9: =IF(X9="Melee",AN9,MAX(1,ROUND(AN9*設定!$B$16*IFERROR(VLOOKUP($AM9,個性タイプマスタ!$A$5:$P$100,15,FALSE),1),0))) -> 19 | H9: =IF(X9="Ranged",AN9,MAX(1,ROUND(AN9*設定!$B$16*IFERROR(VLOOKUP($AM9,個性タイプマスタ!$A$5:$P$100,15,FALSE),1),0))) -> 7 | I9: =MAX(0,ROUND(設定!$B$8*AE9*Z9,0)) -> 7 | J9: =MAX(0,ROUND(設定!$B$9*AE9*AA9,0)) -> 7 | K9: =IFERROR(VLOOKUP($AM9,個性タイプマスタ!$A$5:$P$100,9,FALSE),0.05) -> 0.07 | L9: =IFERROR(VLOOKUP($AM9,個性タイプマスタ!$A$5:$P$100,10,FALSE),1.5) -> 1.6 | M9: =IFERROR(VLOOKUP($AM9,個性タイプマスタ!$A$5:$P$100,11,FALSE),2) -> 2.45 | N9: =MAX(0.1,ROUND(設定!$B$10*AB9,3)) -> 0.94 | O9: =MAX(0.1,ROUND(IF(X9="Melee",1.5,2.5)*AC9,3)) -> 2.73 | P9: =MAX(-10,MIN(0.8,IFERROR(INDEX(属性耐性マスタ!$B$5:$G$11,MATCH($C9,属性耐性マスタ!$A$5:$A$11,0),1),0)+IFERROR(VLOOKUP($AM9,個性タイプマスタ!$A$5:$P$100,12,FALSE),0))) -> -0.135 | Q9: =MAX(-10,MIN(0.8,IFERROR(INDEX(属性耐性マスタ!$B$5:$G$11,MATCH($C9,属性耐性マスタ!$A$5:$A$11,0),2),0)+IFERROR(VLOOKUP($AM9,個性タイプマスタ!$A$5:$P$100,12,FALSE),0))) -> 0.165 | R9: =MAX(-10,MIN(0.8,IFERROR(INDEX(属性耐性マスタ!$B$5:$G$11,MATCH($C9,属性耐性マスタ!$A$5:$A$11,0),3),0)+IFERROR(VLOOKUP($AM9,個性タイプマスタ!$A$5:$P$100,12,FALSE),0))) -> -0.035 | S9: =MAX(-10,MIN(0.8,IFERROR(INDEX(属性耐性マスタ!$B$5:$G$11,MATCH($C9,属性耐性マスタ!$A$5:$A$11,0),4),0)+IFERROR(VLOOKUP($AM9,個性タイプマスタ!$A$5:$P$100,12,FALSE),0))) -> -0.035 | T9: =MAX(-10,MIN(0.8,IFERROR(INDEX(属性耐性マスタ!$B$5:$G$11,MATCH($C9,属性耐性マスタ!$A$5:$A$11,0),5),0)+IFERROR(VLOOKUP($AM9,個性タイプマスタ!$A$5:$P$100,12,FALSE),0))) -> -0.035 | U9: =MAX(-10,MIN(0.8,IFERROR(INDEX(属性耐性マスタ!$B$5:$G$11,MATCH($C9,属性耐性マスタ!$A$5:$A$11,0),6),0)+IFERROR(VLOOKUP($AM9,個性タイプマスタ!$A$5:$P$100,12,FALSE),0))) -> -0.035 | V9: =ROUND(設定!$B$19*IFERROR(VLOOKUP($AM9,個性タイプマスタ!$A$5:$P$100,13,FALSE),1),2) -> 5.6 | W9: 1 | X9: =IFERROR(VLOOKUP($AM9,個性タイプマスタ!$A$5:$P$100,2,FALSE),"Ranged") -> Melee | Y9: =IFERROR(VLOOKUP($AM9,個性タイプマスタ!$A$5:$P$100,3,FALSE),1) -> 0.92 | Z9: =IFERROR(VLOOKUP($AM9,個性タイプマスタ!$A$5:$P$100,4,FALSE),1) -> 0.92 | AA9: =IFERROR(VLOOKUP($AM9,個性タイプマスタ!$A$5:$P$100,5,FALSE),1) -> 0.85 | AB9: =IFERROR(VLOOKUP($AM9,個性タイプマスタ!$A$5:$P$100,6,FALSE),1) -> 0.94 | AC9: =IFERROR(VLOOKUP($AM9,個性タイプマスタ!$A$5:$P$100,7,FALSE),1) -> 1.82 | AD9: =IFERROR(VLOOKUP($AM9,個性タイプマスタ!$A$5:$P$100,8,FALSE),1) -> 0.74 | AE9: =IFERROR(D9/設定!$B$5,1) -> 1 | AF9: =1+設定!$B$13*((I9/設定!$B$8+J9/設定!$B$9)/(2*AE9)) -> 1.2625 | AG9: =MAX(0.7,1+設定!$B$14*(O9/IF(X9="Melee",1.5,2.5)-1)) -> 1.0984 | AH9: =IF(X9="Melee",G9,H9)*N9*(1+K9*(L9-1))*AG9 -> 20.441356 | AI9: =E9*AF9*(1+設定!$B$18*AVERAGE(P9:U9)) -> 115.19176 | AJ9: =設定!$B$5*SQRT((AH9/(設定!$B$7*設定!$B$10*(1+設定!$B$11*(設定!$B$12-1))))*(AI9/(設定!$B$6*(1+設定!$B$13)))) -> 99.082213 | AK9: =IF(D9=0,0,AJ9/D9-1) -> -0.0091778674 | AL9: =D9*AD9 -> 74 | AM9: 近接・長柄 | AN9: =MAX(1,ROUND((設定!$B$7*設定!$B$10*(1+設定!$B$11*(設定!$B$12-1)))*AE9^2*(設定!$B$6*(1+設定!$B$13))/(AI9*N9*(1+K9*(L9-1))*AG9),0)) -> 19 | AO9: =IF($A9="","",IF(COUNTIF(個性タイプマスタ!$A$5:$A$100,$AM9)>0,"OK","未登録")) -> OK | AP9: =IF($A9="","",IF(COUNTIF(属性耐性マスタ!$A$5:$A$11,$C9)>0,"OK","未登録")) -> OK
A10: MON_006 | B10: スライムフォース | C10: 光 | D10: =ROUND(設定!$B$5*POWER($D$2,W10-1),2) -> 100 | E10: =MAX(1,ROUND(設定!$B$6*AE10*Y10,0)) -> 172 | F10: =MAX(0,ROUND(設定!$B$7*AE10*設定!$B$15*IF(X10="Melee",0.6,1.35)*IFERROR(VLOOKUP($AM10,個性タイプマスタ!$A$5:$P$100,14,FALSE),1),0)) -> 20 | G10: =IF(X10="Melee",AN10,MAX(1,ROUND(AN10*設定!$B$16*IFERROR(VLOOKUP($AM10,個性タイプマスタ!$A$5:$P$100,15,FALSE),1),0))) -> 4 | H10: =IF(X10="Ranged",AN10,MAX(1,ROUND(AN10*設定!$B$16*IFERROR(VLOOKUP($AM10,個性タイプマスタ!$A$5:$P$100,15,FALSE),1),0))) -> 14 | I10: =MAX(0,ROUND(設定!$B$8*AE10*Z10,0)) -> 13 | J10: =MAX(0,ROUND(設定!$B$9*AE10*AA10,0)) -> 12 | K10: =IFERROR(VLOOKUP($AM10,個性タイプマスタ!$A$5:$P$100,9,FALSE),0.05) -> 0.035 | L10: =IFERROR(VLOOKUP($AM10,個性タイプマスタ!$A$5:$P$100,10,FALSE),1.5) -> 1.4 | M10: =IFERROR(VLOOKUP($AM10,個性タイプマスタ!$A$5:$P$100,11,FALSE),2) -> 1.5 | N10: =MAX(0.1,ROUND(設定!$B$10*AB10,3)) -> 0.6 | O10: =MAX(0.1,ROUND(IF(X10="Melee",1.5,2.5)*AC10,3)) -> 3.1 | P10: =MAX(-10,MIN(0.8,IFERROR(INDEX(属性耐性マスタ!$B$5:$G$11,MATCH($C10,属性耐性マスタ!$A$5:$A$11,0),1),0)+IFERROR(VLOOKUP($AM10,個性タイプマスタ!$A$5:$P$100,12,FALSE),0))) -> 0.12 | Q10: =MAX(-10,MIN(0.8,IFERROR(INDEX(属性耐性マスタ!$B$5:$G$11,MATCH($C10,属性耐性マスタ!$A$5:$A$11,0),2),0)+IFERROR(VLOOKUP($AM10,個性タイプマスタ!$A$5:$P$100,12,FALSE),0))) -> 0.12 | R10: =MAX(-10,MIN(0.8,IFERROR(INDEX(属性耐性マスタ!$B$5:$G$11,MATCH($C10,属性耐性マスタ!$A$5:$A$11,0),3),0)+IFERROR(VLOOKUP($AM10,個性タイプマスタ!$A$5:$P$100,12,FALSE),0))) -> 0.12 | S10: =MAX(-10,MIN(0.8,IFERROR(INDEX(属性耐性マスタ!$B$5:$G$11,MATCH($C10,属性耐性マスタ!$A$5:$A$11,0),4),0)+IFERROR(VLOOKUP($AM10,個性タイプマスタ!$A$5:$P$100,12,FALSE),0))) -> 0.12 | T10: =MAX(-10,MIN(0.8,IFERROR(INDEX(属性耐性マスタ!$B$5:$G$11,MATCH($C10,属性耐性マスタ!$A$5:$A$11,0),5),0)+IFERROR(VLOOKUP($AM10,個性タイプマスタ!$A$5:$P$100,12,FALSE),0))) -> 0.32 | U10: =MAX(-10,MIN(0.8,IFERROR(INDEX(属性耐性マスタ!$B$5:$G$11,MATCH($C10,属性耐性マスタ!$A$5:$A$11,0),6),0)+IFERROR(VLOOKUP($AM10,個性タイプマスタ!$A$5:$P$100,12,FALSE),0))) -> 0.02 | V10: =ROUND(設定!$B$19*IFERROR(VLOOKUP($AM10,個性タイプマスタ!$A$5:$P$100,13,FALSE),1),2) -> 4.12 | W10: 1 | X10: =IFERROR(VLOOKUP($AM10,個性タイプマスタ!$A$5:$P$100,2,FALSE),"Ranged") -> Ranged | Y10: =IFERROR(VLOOKUP($AM10,個性タイプマスタ!$A$5:$P$100,3,FALSE),1) -> 1.72 | Z10: =IFERROR(VLOOKUP($AM10,個性タイプマスタ!$A$5:$P$100,4,FALSE),1) -> 1.64 | AA10: =IFERROR(VLOOKUP($AM10,個性タイプマスタ!$A$5:$P$100,5,FALSE),1) -> 1.55 | AB10: =IFERROR(VLOOKUP($AM10,個性タイプマスタ!$A$5:$P$100,6,FALSE),1) -> 0.6 | AC10: =IFERROR(VLOOKUP($AM10,個性タイプマスタ!$A$5:$P$100,7,FALSE),1) -> 1.24 | AD10: =IFERROR(VLOOKUP($AM10,個性タイプマスタ!$A$5:$P$100,8,FALSE),1) -> 0.91 | AE10: =IFERROR(D10/設定!$B$5,1) -> 1 | AF10: =1+設定!$B$13*((I10/設定!$B$8+J10/設定!$B$9)/(2*AE10)) -> 1.46875 | AG10: =MAX(0.7,1+設定!$B$14*(O10/IF(X10="Melee",1.5,2.5)-1)) -> 1.0288 | AH10: =IF(X10="Melee",G10,H10)*N10*(1+K10*(L10-1))*AG10 -> 8.7629069 | AI10: =E10*AF10*(1+設定!$B$18*AVERAGE(P10:U10)) -> 268.16144 | AJ10: =設定!$B$5*SQRT((AH10/(設定!$B$7*設定!$B$10*(1+設定!$B$11*(設定!$B$12-1))))*(AI10/(設定!$B$6*(1+設定!$B$13)))) -> 98.981128 | AK10: =IF(D10=0,0,AJ10/D10-1) -> -0.010188718 | AL10: =D10*AD10 -> 91 | AM10: 魔法・重装砲 | AN10: =MAX(1,ROUND((設定!$B$7*設定!$B$10*(1+設定!$B$11*(設定!$B$12-1)))*AE10^2*(設定!$B$6*(1+設定!$B$13))/(AI10*N10*(1+K10*(L10-1))*AG10),0)) -> 14 | AO10: =IF($A10="","",IF(COUNTIF(個性タイプマスタ!$A$5:$A$100,$AM10)>0,"OK","未登録")) -> OK | AP10: =IF($A10="","",IF(COUNTIF(属性耐性マスタ!$A$5:$A$11,$C10)>0,"OK","未登録")) -> OK
A11: MON_007 | B11: ゴブリン | C11: 風 | D11: =ROUND(設定!$B$5*POWER($D$2,W11-1),2) -> 110 | E11: =MAX(1,ROUND(設定!$B$6*AE11*Y11,0)) -> 117 | F11: =MAX(0,ROUND(設定!$B$7*AE11*設定!$B$15*IF(X11="Melee",0.6,1.35)*IFERROR(VLOOKUP($AM11,個性タイプマスタ!$A$5:$P$100,14,FALSE),1),0)) -> 28 | G11: =IF(X11="Melee",AN11,MAX(1,ROUND(AN11*設定!$B$16*IFERROR(VLOOKUP($AM11,個性タイプマスタ!$A$5:$P$100,15,FALSE),1),0))) -> 6 | H11: =IF(X11="Ranged",AN11,MAX(1,ROUND(AN11*設定!$B$16*IFERROR(VLOOKUP($AM11,個性タイプマスタ!$A$5:$P$100,15,FALSE),1),0))) -> 19 | I11: =MAX(0,ROUND(設定!$B$8*AE11*Z11,0)) -> 7 | J11: =MAX(0,ROUND(設定!$B$9*AE11*AA11,0)) -> 18 | K11: =IFERROR(VLOOKUP($AM11,個性タイプマスタ!$A$5:$P$100,9,FALSE),0.05) -> 0.045 | L11: =IFERROR(VLOOKUP($AM11,個性タイプマスタ!$A$5:$P$100,10,FALSE),1.5) -> 1.45 | M11: =IFERROR(VLOOKUP($AM11,個性タイプマスタ!$A$5:$P$100,11,FALSE),2) -> 1.9 | N11: =MAX(0.1,ROUND(設定!$B$10*AB11,3)) -> 0.84 | O11: =MAX(0.1,ROUND(IF(X11="Melee",1.5,2.5)*AC11,3)) -> 2.65 | P11: =MAX(-10,MIN(0.8,IFERROR(INDEX(属性耐性マスタ!$B$5:$G$11,MATCH($C11,属性耐性マスタ!$A$5:$A$11,0),1),0)+IFERROR(VLOOKUP($AM11,個性タイプマスタ!$A$5:$P$100,12,FALSE),0))) -> 0.09 | Q11: =MAX(-10,MIN(0.8,IFERROR(INDEX(属性耐性マスタ!$B$5:$G$11,MATCH($C11,属性耐性マスタ!$A$5:$A$11,0),2),0)+IFERROR(VLOOKUP($AM11,個性タイプマスタ!$A$5:$P$100,12,FALSE),0))) -> 0.09 | R11: =MAX(-10,MIN(0.8,IFERROR(INDEX(属性耐性マスタ!$B$5:$G$11,MATCH($C11,属性耐性マスタ!$A$5:$A$11,0),3),0)+IFERROR(VLOOKUP($AM11,個性タイプマスタ!$A$5:$P$100,12,FALSE),0))) -> 0.29 | S11: =MAX(-10,MIN(0.8,IFERROR(INDEX(属性耐性マスタ!$B$5:$G$11,MATCH($C11,属性耐性マスタ!$A$5:$A$11,0),4),0)+IFERROR(VLOOKUP($AM11,個性タイプマスタ!$A$5:$P$100,12,FALSE),0))) -> -0.01 | T11: =MAX(-10,MIN(0.8,IFERROR(INDEX(属性耐性マスタ!$B$5:$G$11,MATCH($C11,属性耐性マスタ!$A$5:$A$11,0),5),0)+IFERROR(VLOOKUP($AM11,個性タイプマスタ!$A$5:$P$100,12,FALSE),0))) -> 0.09 | U11: =MAX(-10,MIN(0.8,IFERROR(INDEX(属性耐性マスタ!$B$5:$G$11,MATCH($C11,属性耐性マスタ!$A$5:$A$11,0),6),0)+IFERROR(VLOOKUP($AM11,個性タイプマスタ!$A$5:$P$100,12,FALSE),0))) -> 0.09 | V11: =ROUND(設定!$B$19*IFERROR(VLOOKUP($AM11,個性タイプマスタ!$A$5:$P$100,13,FALSE),1),2) -> 4.4 | W11: 2 | X11: =IFERROR(VLOOKUP($AM11,個性タイプマスタ!$A$5:$P$100,2,FALSE),"Ranged") -> Ranged | Y11: =IFERROR(VLOOKUP($AM11,個性タイプマスタ!$A$5:$P$100,3,FALSE),1) -> 1.06 | Z11: =IFERROR(VLOOKUP($AM11,個性タイプマスタ!$A$5:$P$100,4,FALSE),1) -> 0.77 | AA11: =IFERROR(VLOOKUP($AM11,個性タイプマスタ!$A$5:$P$100,5,FALSE),1) -> 2.05 | AB11: =IFERROR(VLOOKUP($AM11,個性タイプマスタ!$A$5:$P$100,6,FALSE),1) -> 0.84 | AC11: =IFERROR(VLOOKUP($AM11,個性タイプマスタ!$A$5:$P$100,7,FALSE),1) -> 1.06 | AD11: =IFERROR(VLOOKUP($AM11,個性タイプマスタ!$A$5:$P$100,8,FALSE),1) -> 0.82 | AE11: =IFERROR(D11/設定!$B$5,1) -> 1.1 | AF11: =1+設定!$B$13*((I11/設定!$B$8+J11/設定!$B$9)/(2*AE11)) -> 1.4261364 | AG11: =MAX(0.7,1+設定!$B$14*(O11/IF(X11="Melee",1.5,2.5)-1)) -> 1.0072 | AH11: =IF(X11="Melee",G11,H11)*N11*(1+K11*(L11-1))*AG11 -> 16.400429 | AI11: =E11*AF11*(1+設定!$B$18*AVERAGE(P11:U11)) -> 174.86714 | AJ11: =設定!$B$5*SQRT((AH11/(設定!$B$7*設定!$B$10*(1+設定!$B$11*(設定!$B$12-1))))*(AI11/(設定!$B$6*(1+設定!$B$13)))) -> 109.34825 | AK11: =IF(D11=0,0,AJ11/D11-1) -> -0.0059249899 | AL11: =D11*AD11 -> 90.2 | AM11: 魔法・魔防障壁 | AN11: =MAX(1,ROUND((設定!$B$7*設定!$B$10*(1+設定!$B$11*(設定!$B$12-1)))*AE11^2*(設定!$B$6*(1+設定!$B$13))/(AI11*N11*(1+K11*(L11-1))*AG11),0)) -> 19 | AO11: =IF($A11="","",IF(COUNTIF(個性タイプマスタ!$A$5:$A$100,$AM11)>0,"OK","未登録")) -> OK | AP11: =IF($A11="","",IF(COUNTIF(属性耐性マスタ!$A$5:$A$11,$C11)>0,"OK","未登録")) -> OK
A12: MON_008 | B12: ゴブリンウォーリアー | C12: 火 | D12: =ROUND(設定!$B$5*POWER($D$2,W12-1),2) -> 110 | E12: =MAX(1,ROUND(設定!$B$6*AE12*Y12,0)) -> 61 | F12: =MAX(0,ROUND(設定!$B$7*AE12*設定!$B$15*IF(X12="Melee",0.6,1.35)*IFERROR(VLOOKUP($AM12,個性タイプマスタ!$A$5:$P$100,14,FALSE),1),0)) -> 24 | G12: =IF(X12="Melee",AN12,MAX(1,ROUND(AN12*設定!$B$16*IFERROR(VLOOKUP($AM12,個性タイプマスタ!$A$5:$P$100,15,FALSE),1),0))) -> 11 | H12: =IF(X12="Ranged",AN12,MAX(1,ROUND(AN12*設定!$B$16*IFERROR(VLOOKUP($AM12,個性タイプマスタ!$A$5:$P$100,15,FALSE),1),0))) -> 31 | I12: =MAX(0,ROUND(設定!$B$8*AE12*Z12,0)) -> 13 | J12: =MAX(0,ROUND(設定!$B$9*AE12*AA12,0)) -> 20 | K12: =IFERROR(VLOOKUP($AM12,個性タイプマスタ!$A$5:$P$100,9,FALSE),0.05) -> 0.04 | L12: =IFERROR(VLOOKUP($AM12,個性タイプマスタ!$A$5:$P$100,10,FALSE),1.5) -> 1.38 | M12: =IFERROR(VLOOKUP($AM12,個性タイプマスタ!$A$5:$P$100,11,FALSE),2) -> 2.2 | N12: =MAX(0.1,ROUND(設定!$B$10*AB12,3)) -> 0.88 | O12: =MAX(0.1,ROUND(IF(X12="Melee",1.5,2.5)*AC12,3)) -> 3.15 | P12: =MAX(-10,MIN(0.8,IFERROR(INDEX(属性耐性マスタ!$B$5:$G$11,MATCH($C12,属性耐性マスタ!$A$5:$A$11,0),1),0)+IFERROR(VLOOKUP($AM12,個性タイプマスタ!$A$5:$P$100,12,FALSE),0))) -> 0.33 | Q12: =MAX(-10,MIN(0.8,IFERROR(INDEX(属性耐性マスタ!$B$5:$G$11,MATCH($C12,属性耐性マスタ!$A$5:$A$11,0),2),0)+IFERROR(VLOOKUP($AM12,個性タイプマスタ!$A$5:$P$100,12,FALSE),0))) -> 0.03 | R12: =MAX(-10,MIN(0.8,IFERROR(INDEX(属性耐性マスタ!$B$5:$G$11,MATCH($C12,属性耐性マスタ!$A$5:$A$11,0),3),0)+IFERROR(VLOOKUP($AM12,個性タイプマスタ!$A$5:$P$100,12,FALSE),0))) -> 0.13 | S12: =MAX(-10,MIN(0.8,IFERROR(INDEX(属性耐性マスタ!$B$5:$G$11,MATCH($C12,属性耐性マスタ!$A$5:$A$11,0),4),0)+IFERROR(VLOOKUP($AM12,個性タイプマスタ!$A$5:$P$100,12,FALSE),0))) -> 0.13 | T12: =MAX(-10,MIN(0.8,IFERROR(INDEX(属性耐性マスタ!$B$5:$G$11,MATCH($C12,属性耐性マスタ!$A$5:$A$11,0),5),0)+IFERROR(VLOOKUP($AM12,個性タイプマスタ!$A$5:$P$100,12,FALSE),0))) -> 0.13 | U12: =MAX(-10,MIN(0.8,IFERROR(INDEX(属性耐性マスタ!$B$5:$G$11,MATCH($C12,属性耐性マスタ!$A$5:$A$11,0),6),0)+IFERROR(VLOOKUP($AM12,個性タイプマスタ!$A$5:$P$100,12,FALSE),0))) -> 0.13 | V12: =ROUND(設定!$B$19*IFERROR(VLOOKUP($AM12,個性タイプマスタ!$A$5:$P$100,13,FALSE),1),2) -> 4.48 | W12: 2 | X12: =IFERROR(VLOOKUP($AM12,個性タイプマスタ!$A$5:$P$100,2,FALSE),"Ranged") -> Ranged | Y12: =IFERROR(VLOOKUP($AM12,個性タイプマスタ!$A$5:$P$100,3,FALSE),1) -> 0.55 | Z12: =IFERROR(VLOOKUP($AM12,個性タイプマスタ!$A$5:$P$100,4,FALSE),1) -> 1.45 | AA12: =IFERROR(VLOOKUP($AM12,個性タイプマスタ!$A$5:$P$100,5,FALSE),1) -> 2.25 | AB12: =IFERROR(VLOOKUP($AM12,個性タイプマスタ!$A$5:$P$100,6,FALSE),1) -> 0.88 | AC12: =IFERROR(VLOOKUP($AM12,個性タイプマスタ!$A$5:$P$100,7,FALSE),1) -> 1.26 | AD12: =IFERROR(VLOOKUP($AM12,個性タイプマスタ!$A$5:$P$100,8,FALSE),1) -> 0.75 | AE12: =IFERROR(D12/設定!$B$5,1) -> 1.1 | AF12: =1+設定!$B$13*((I12/設定!$B$8+J12/設定!$B$9)/(2*AE12)) -> 1.5625 | AG12: =MAX(0.7,1+設定!$B$14*(O12/IF(X12="Melee",1.5,2.5)-1)) -> 1.0312 | AH12: =IF(X12="Melee",G12,H12)*N12*(1+K12*(L12-1))*AG12 -> 28.558729 | AI12: =E12*AF12*(1+設定!$B$18*AVERAGE(P12:U12)) -> 101.60313 | AJ12: =設定!$B$5*SQRT((AH12/(設定!$B$7*設定!$B$10*(1+設定!$B$11*(設定!$B$12-1))))*(AI12/(設定!$B$6*(1+設定!$B$13)))) -> 109.98998 | AK12: =IF(D12=0,0,AJ12/D12-1) -> -9.1118333e-05 | AL12: =D12*AD12 -> 82.5 | AM12: 魔法・薄命結界 | AN12: =MAX(1,ROUND((設定!$B$7*設定!$B$10*(1+設定!$B$11*(設定!$B$12-1)))*AE12^2*(設定!$B$6*(1+設定!$B$13))/(AI12*N12*(1+K12*(L12-1))*AG12),0)) -> 31 | AO12: =IF($A12="","",IF(COUNTIF(個性タイプマスタ!$A$5:$A$100,$AM12)>0,"OK","未登録")) -> OK | AP12: =IF($A12="","",IF(COUNTIF(属性耐性マスタ!$A$5:$A$11,$C12)>0,"OK","未登録")) -> OK
A13: MON_009 | B13: ゴブリンメイジ | C13: 雷 | D13: =ROUND(設定!$B$5*POWER($D$2,W13-1),2) -> 110 | E13: =MAX(1,ROUND(設定!$B$6*AE13*Y13,0)) -> 110 | F13: =MAX(0,ROUND(設定!$B$7*AE13*設定!$B$15*IF(X13="Melee",0.6,1.35)*IFERROR(VLOOKUP($AM13,個性タイプマスタ!$A$5:$P$100,14,FALSE),1),0)) -> 23 | G13: =IF(X13="Melee",AN13,MAX(1,ROUND(AN13*設定!$B$16*IFERROR(VLOOKUP($AM13,個性タイプマスタ!$A$5:$P$100,15,FALSE),1),0))) -> 9 | H13: =IF(X13="Ranged",AN13,MAX(1,ROUND(AN13*設定!$B$16*IFERROR(VLOOKUP($AM13,個性タイプマスタ!$A$5:$P$100,15,FALSE),1),0))) -> 19 | I13: =MAX(0,ROUND(設定!$B$8*AE13*Z13,0)) -> 9 | J13: =MAX(0,ROUND(設定!$B$9*AE13*AA13,0)) -> 11 | K13: =IFERROR(VLOOKUP($AM13,個性タイプマスタ!$A$5:$P$100,9,FALSE),0.05) -> 0.06 | L13: =IFERROR(VLOOKUP($AM13,個性タイプマスタ!$A$5:$P$100,10,FALSE),1.5) -> 1.4 | M13: =IFERROR(VLOOKUP($AM13,個性タイプマスタ!$A$5:$P$100,11,FALSE),2) -> 2.1 | N13: =MAX(0.1,ROUND(設定!$B$10*AB13,3)) -> 0.95 | O13: =MAX(0.1,ROUND(IF(X13="Melee",1.5,2.5)*AC13,3)) -> 2.875 | P13: =MAX(-10,MIN(0.8,IFERROR(INDEX(属性耐性マスタ!$B$5:$G$11,MATCH($C13,属性耐性マスタ!$A$5:$A$11,0),1),0)+IFERROR(VLOOKUP($AM13,個性タイプマスタ!$A$5:$P$100,12,FALSE),0))) -> 0.03 | Q13: =MAX(-10,MIN(0.8,IFERROR(INDEX(属性耐性マスタ!$B$5:$G$11,MATCH($C13,属性耐性マスタ!$A$5:$A$11,0),2),0)+IFERROR(VLOOKUP($AM13,個性タイプマスタ!$A$5:$P$100,12,FALSE),0))) -> 0.03 | R13: =MAX(-10,MIN(0.8,IFERROR(INDEX(属性耐性マスタ!$B$5:$G$11,MATCH($C13,属性耐性マスタ!$A$5:$A$11,0),3),0)+IFERROR(VLOOKUP($AM13,個性タイプマスタ!$A$5:$P$100,12,FALSE),0))) -> -0.07 | S13: =MAX(-10,MIN(0.8,IFERROR(INDEX(属性耐性マスタ!$B$5:$G$11,MATCH($C13,属性耐性マスタ!$A$5:$A$11,0),4),0)+IFERROR(VLOOKUP($AM13,個性タイプマスタ!$A$5:$P$100,12,FALSE),0))) -> 0.23 | T13: =MAX(-10,MIN(0.8,IFERROR(INDEX(属性耐性マスタ!$B$5:$G$11,MATCH($C13,属性耐性マスタ!$A$5:$A$11,0),5),0)+IFERROR(VLOOKUP($AM13,個性タイプマスタ!$A$5:$P$100,12,FALSE),0))) -> 0.03 | U13: =MAX(-10,MIN(0.8,IFERROR(INDEX(属性耐性マスタ!$B$5:$G$11,MATCH($C13,属性耐性マスタ!$A$5:$A$11,0),6),0)+IFERROR(VLOOKUP($AM13,個性タイプマスタ!$A$5:$P$100,12,FALSE),0))) -> 0.03 | V13: =ROUND(設定!$B$19*IFERROR(VLOOKUP($AM13,個性タイプマスタ!$A$5:$P$100,13,FALSE),1),2) -> 4.8 | W13: 2 | X13: =IFERROR(VLOOKUP($AM13,個性タイプマスタ!$A$5:$P$100,2,FALSE),"Ranged") -> Ranged | Y13: =IFERROR(VLOOKUP($AM13,個性タイプマスタ!$A$5:$P$100,3,FALSE),1) -> 1 | Z13: =IFERROR(VLOOKUP($AM13,個性タイプマスタ!$A$5:$P$100,4,FALSE),1) -> 1 | AA13: =IFERROR(VLOOKUP($AM13,個性タイプマスタ!$A$5:$P$100,5,FALSE),1) -> 1.2 | AB13: =IFERROR(VLOOKUP($AM13,個性タイプマスタ!$A$5:$P$100,6,FALSE),1) -> 0.95 | AC13: =IFERROR(VLOOKUP($AM13,個性タイプマスタ!$A$5:$P$100,7,FALSE),1) -> 1.15 | AD13: =IFERROR(VLOOKUP($AM13,個性タイプマスタ!$A$5:$P$100,8,FALSE),1) -> 0.84 | AE13: =IFERROR(D13/設定!$B$5,1) -> 1.1 | AF13: =1+設定!$B$13*((I13/設定!$B$8+J13/設定!$B$9)/(2*AE13)) -> 1.3409091 | AG13: =MAX(0.7,1+設定!$B$14*(O13/IF(X13="Melee",1.5,2.5)-1)) -> 1.018 | AH13: =IF(X13="Melee",G13,H13)*N13*(1+K13*(L13-1))*AG13 -> 18.815898 | AI13: =E13*AF13*(1+設定!$B$18*AVERAGE(P13:U13)) -> 150.5975 | AJ13: =設定!$B$5*SQRT((AH13/(設定!$B$7*設定!$B$10*(1+設定!$B$11*(設定!$B$12-1))))*(AI13/(設定!$B$6*(1+設定!$B$13)))) -> 108.69298 | AK13: =IF(D13=0,0,AJ13/D13-1) -> -0.011882013 | AL13: =D13*AD13 -> 92.4 | AM13: 魔法・支援 | AN13: =MAX(1,ROUND((設定!$B$7*設定!$B$10*(1+設定!$B$11*(設定!$B$12-1)))*AE13^2*(設定!$B$6*(1+設定!$B$13))/(AI13*N13*(1+K13*(L13-1))*AG13),0)) -> 19 | AO13: =IF($A13="","",IF(COUNTIF(個性タイプマスタ!$A$5:$A$100,$AM13)>0,"OK","未登録")) -> OK | AP13: =IF($A13="","",IF(COUNTIF(属性耐性マスタ!$A$5:$A$11,$C13)>0,"OK","未登録")) -> OK
A14: MON_010 | B14: ボブゴブリン | C14: 雷 | D14: =ROUND(設定!$B$5*POWER($D$2,W14-1),2) -> 110 | E14: =MAX(1,ROUND(設定!$B$6*AE14*Y14,0)) -> 130 | F14: =MAX(0,ROUND(設定!$B$7*AE14*設定!$B$15*IF(X14="Melee",0.6,1.35)*IFERROR(VLOOKUP($AM14,個性タイプマスタ!$A$5:$P$100,14,FALSE),1),0)) -> 7 | G14: =IF(X14="Melee",AN14,MAX(1,ROUND(AN14*設定!$B$16*IFERROR(VLOOKUP($AM14,個性タイプマスタ!$A$5:$P$100,15,FALSE),1),0))) -> 17 | H14: =IF(X14="Ranged",AN14,MAX(1,ROUND(AN14*設定!$B$16*IFERROR(VLOOKUP($AM14,個性タイプマスタ!$A$5:$P$100,15,FALSE),1),0))) -> 5 | I14: =MAX(0,ROUND(設定!$B$8*AE14*Z14,0)) -> 10 | J14: =MAX(0,ROUND(設定!$B$9*AE14*AA14,0)) -> 10 | K14: =IFERROR(VLOOKUP($AM14,個性タイプマスタ!$A$5:$P$100,9,FALSE),0.05) -> 0.04 | L14: =IFERROR(VLOOKUP($AM14,個性タイプマスタ!$A$5:$P$100,10,FALSE),1.5) -> 1.43 | M14: =IFERROR(VLOOKUP($AM14,個性タイプマスタ!$A$5:$P$100,11,FALSE),2) -> 2.15 | N14: =MAX(0.1,ROUND(設定!$B$10*AB14,3)) -> 0.88 | O14: =MAX(0.1,ROUND(IF(X14="Melee",1.5,2.5)*AC14,3)) -> 1.425 | P14: =MAX(-10,MIN(0.8,IFERROR(INDEX(属性耐性マスタ!$B$5:$G$11,MATCH($C14,属性耐性マスタ!$A$5:$A$11,0),1),0)+IFERROR(VLOOKUP($AM14,個性タイプマスタ!$A$5:$P$100,12,FALSE),0))) -> 0.19 | Q14: =MAX(-10,MIN(0.8,IFERROR(INDEX(属性耐性マスタ!$B$5:$G$11,MATCH($C14,属性耐性マスタ!$A$5:$A$11,0),2),0)+IFERROR(VLOOKUP($AM14,個性タイプマスタ!$A$5:$P$100,12,FALSE),0))) -> 0.19 | R14: =MAX(-10,MIN(0.8,IFERROR(INDEX(属性耐性マスタ!$B$5:$G$11,MATCH($C14,属性耐性マスタ!$A$5:$A$11,0),3),0)+IFERROR(VLOOKUP($AM14,個性タイプマスタ!$A$5:$P$100,12,FALSE),0))) -> 0.09 | S14: =MAX(-10,MIN(0.8,IFERROR(INDEX(属性耐性マスタ!$B$5:$G$11,MATCH($C14,属性耐性マスタ!$A$5:$A$11,0),4),0)+IFERROR(VLOOKUP($AM14,個性タイプマスタ!$A$5:$P$100,12,FALSE),0))) -> 0.39 | T14: =MAX(-10,MIN(0.8,IFERROR(INDEX(属性耐性マスタ!$B$5:$G$11,MATCH($C14,属性耐性マスタ!$A$5:$A$11,0),5),0)+IFERROR(VLOOKUP($AM14,個性タイプマスタ!$A$5:$P$100,12,FALSE),0))) -> 0.19 | U14: =MAX(-10,MIN(0.8,IFERROR(INDEX(属性耐性マスタ!$B$5:$G$11,MATCH($C14,属性耐性マスタ!$A$5:$A$11,0),6),0)+IFERROR(VLOOKUP($AM14,個性タイプマスタ!$A$5:$P$100,12,FALSE),0))) -> 0.19 | V14: =ROUND(設定!$B$19*IFERROR(VLOOKUP($AM14,個性タイプマスタ!$A$5:$P$100,13,FALSE),1),2) -> 3.8 | W14: 2 | X14: =IFERROR(VLOOKUP($AM14,個性タイプマスタ!$A$5:$P$100,2,FALSE),"Ranged") -> Melee | Y14: =IFERROR(VLOOKUP($AM14,個性タイプマスタ!$A$5:$P$100,3,FALSE),1) -> 1.18 | Z14: =IFERROR(VLOOKUP($AM14,個性タイプマスタ!$A$5:$P$100,4,FALSE),1) -> 1.14 | AA14: =IFERROR(VLOOKUP($AM14,個性タイプマスタ!$A$5:$P$100,5,FALSE),1) -> 1.14 | AB14: =IFERROR(VLOOKUP($AM14,個性タイプマスタ!$A$5:$P$100,6,FALSE),1) -> 0.88 | AC14: =IFERROR(VLOOKUP($AM14,個性タイプマスタ!$A$5:$P$100,7,FALSE),1) -> 0.95 | AD14: =IFERROR(VLOOKUP($AM14,個性タイプマスタ!$A$5:$P$100,8,FALSE),1) -> 0.88 | AE14: =IFERROR(D14/設定!$B$5,1) -> 1.1 | AF14: =1+設定!$B$13*((I14/設定!$B$8+J14/設定!$B$9)/(2*AE14)) -> 1.3409091 | AG14: =MAX(0.7,1+設定!$B$14*(O14/IF(X14="Melee",1.5,2.5)-1)) -> 0.994 | AH14: =IF(X14="Melee",G14,H14)*N14*(1+K14*(L14-1))*AG14 -> 15.126008 | AI14: =E14*AF14*(1+設定!$B$18*AVERAGE(P14:U14)) -> 190.52977 | AJ14: =設定!$B$5*SQRT((AH14/(設定!$B$7*設定!$B$10*(1+設定!$B$11*(設定!$B$12-1))))*(AI14/(設定!$B$6*(1+設定!$B$13)))) -> 109.61594 | AK14: =IF(D14=0,0,AJ14/D14-1) -> -0.0034914188 | AL14: =D14*AD14 -> 96.8 | AM14: 近接・耐性鎧 | AN14: =MAX(1,ROUND((設定!$B$7*設定!$B$10*(1+設定!$B$11*(設定!$B$12-1)))*AE14^2*(設定!$B$6*(1+設定!$B$13))/(AI14*N14*(1+K14*(L14-1))*AG14),0)) -> 17 | AO14: =IF($A14="","",IF(COUNTIF(個性タイプマスタ!$A$5:$A$100,$AM14)>0,"OK","未登録")) -> OK | AP14: =IF($A14="","",IF(COUNTIF(属性耐性マスタ!$A$5:$A$11,$C14)>0,"OK","未登録")) -> OK
A15: MON_011 | B15: マテリアスライム | C15: 雷 | D15: =ROUND(設定!$B$5*POWER($D$2,W15-1),2) -> 110 | E15: =MAX(1,ROUND(設定!$B$6*AE15*Y15,0)) -> 96 | F15: =MAX(0,ROUND(設定!$B$7*AE15*設定!$B$15*IF(X15="Melee",0.6,1.35)*IFERROR(VLOOKUP($AM15,個性タイプマスタ!$A$5:$P$100,14,FALSE),1),0)) -> 5 | G15: =IF(X15="Melee",AN15,MAX(1,ROUND(AN15*設定!$B$16*IFERROR(VLOOKUP($AM15,個性タイプマスタ!$A$5:$P$100,15,FALSE),1),0))) -> 18 | H15: =IF(X15="Ranged",AN15,MAX(1,ROUND(AN15*設定!$B$16*IFERROR(VLOOKUP($AM15,個性タイプマスタ!$A$5:$P$100,15,FALSE),1),0))) -> 5 | I15: =MAX(0,ROUND(設定!$B$8*AE15*Z15,0)) -> 8 | J15: =MAX(0,ROUND(設定!$B$9*AE15*AA15,0)) -> 7 | K15: =IFERROR(VLOOKUP($AM15,個性タイプマスタ!$A$5:$P$100,9,FALSE),0.05) -> 0.27 | L15: =IFERROR(VLOOKUP($AM15,個性タイプマスタ!$A$5:$P$100,10,FALSE),1.5) -> 2.03 | M15: =IFERROR(VLOOKUP($AM15,個性タイプマスタ!$A$5:$P$100,11,FALSE),2) -> 2.75 | N15: =MAX(0.1,ROUND(設定!$B$10*AB15,3)) -> 1.04 | O15: =MAX(0.1,ROUND(IF(X15="Melee",1.5,2.5)*AC15,3)) -> 1.53 | P15: =MAX(-10,MIN(0.8,IFERROR(INDEX(属性耐性マスタ!$B$5:$G$11,MATCH($C15,属性耐性マスタ!$A$5:$A$11,0),1),0)+IFERROR(VLOOKUP($AM15,個性タイプマスタ!$A$5:$P$100,12,FALSE),0))) -> -0.06 | Q15: =MAX(-10,MIN(0.8,IFERROR(INDEX(属性耐性マスタ!$B$5:$G$11,MATCH($C15,属性耐性マスタ!$A$5:$A$11,0),2),0)+IFERROR(VLOOKUP($AM15,個性タイプマスタ!$A$5:$P$100,12,FALSE),0))) -> -0.06 | R15: =MAX(-10,MIN(0.8,IFERROR(INDEX(属性耐性マスタ!$B$5:$G$11,MATCH($C15,属性耐性マスタ!$A$5:$A$11,0),3),0)+IFERROR(VLOOKUP($AM15,個性タイプマスタ!$A$5:$P$100,12,FALSE),0))) -> -0.16 | S15: =MAX(-10,MIN(0.8,IFERROR(INDEX(属性耐性マスタ!$B$5:$G$11,MATCH($C15,属性耐性マスタ!$A$5:$A$11,0),4),0)+IFERROR(VLOOKUP($AM15,個性タイプマスタ!$A$5:$P$100,12,FALSE),0))) -> 0.14 | T15: =MAX(-10,MIN(0.8,IFERROR(INDEX(属性耐性マスタ!$B$5:$G$11,MATCH($C15,属性耐性マスタ!$A$5:$A$11,0),5),0)+IFERROR(VLOOKUP($AM15,個性タイプマスタ!$A$5:$P$100,12,FALSE),0))) -> -0.06 | U15: =MAX(-10,MIN(0.8,IFERROR(INDEX(属性耐性マスタ!$B$5:$G$11,MATCH($C15,属性耐性マスタ!$A$5:$A$11,0),6),0)+IFERROR(VLOOKUP($AM15,個性タイプマスタ!$A$5:$P$100,12,FALSE),0))) -> -0.06 | V15: =ROUND(設定!$B$19*IFERROR(VLOOKUP($AM15,個性タイプマスタ!$A$5:$P$100,13,FALSE),1),2) -> 4.2 | W15: 2 | X15: =IFERROR(VLOOKUP($AM15,個性タイプマスタ!$A$5:$P$100,2,FALSE),"Ranged") -> Melee | Y15: =IFERROR(VLOOKUP($AM15,個性タイプマスタ!$A$5:$P$100,3,FALSE),1) -> 0.87 | Z15: =IFERROR(VLOOKUP($AM15,個性タイプマスタ!$A$5:$P$100,4,FALSE),1) -> 0.86 | AA15: =IFERROR(VLOOKUP($AM15,個性タイプマスタ!$A$5:$P$100,5,FALSE),1) -> 0.77 | AB15: =IFERROR(VLOOKUP($AM15,個性タイプマスタ!$A$5:$P$100,6,FALSE),1) -> 1.04 | AC15: =IFERROR(VLOOKUP($AM15,個性タイプマスタ!$A$5:$P$100,7,FALSE),1) -> 1.02 | AD15: =IFERROR(VLOOKUP($AM15,個性タイプマスタ!$A$5:$P$100,8,FALSE),1) -> 0.7 | AE15: =IFERROR(D15/設定!$B$5,1) -> 1.1 | AF15: =1+設定!$B$13*((I15/設定!$B$8+J15/設定!$B$9)/(2*AE15)) -> 1.2556818 | AG15: =MAX(0.7,1+設定!$B$14*(O15/IF(X15="Melee",1.5,2.5)-1)) -> 1.0024 | AH15: =IF(X15="Melee",G15,H15)*N15*(1+K15*(L15-1))*AG15 -> 23.983454 | AI15: =E15*AF15*(1+設定!$B$18*AVERAGE(P15:U15)) -> 118.19482 | AJ15: =設定!$B$5*SQRT((AH15/(設定!$B$7*設定!$B$10*(1+設定!$B$11*(設定!$B$12-1))))*(AI15/(設定!$B$6*(1+設定!$B$13)))) -> 108.71394 | AK15: =IF(D15=0,0,AJ15/D15-1) -> -0.011691477 | AL15: =D15*AD15 -> 77 | AM15: 近接・会心 | AN15: =MAX(1,ROUND((設定!$B$7*設定!$B$10*(1+設定!$B$11*(設定!$B$12-1)))*AE15^2*(設定!$B$6*(1+設定!$B$13))/(AI15*N15*(1+K15*(L15-1))*AG15),0)) -> 18 | AO15: =IF($A15="","",IF(COUNTIF(個性タイプマスタ!$A$5:$A$100,$AM15)>0,"OK","未登録")) -> OK | AP15: =IF($A15="","",IF(COUNTIF(属性耐性マスタ!$A$5:$A$11,$C15)>0,"OK","未登録")) -> OK
A16: MON_012 | B16: ゴブリンキング | C16: 闇 | D16: =ROUND(設定!$B$5*POWER($D$2,W16-1),2) -> 110 | E16: =MAX(1,ROUND(設定!$B$6*AE16*Y16,0)) -> 110 | F16: =MAX(0,ROUND(設定!$B$7*AE16*設定!$B$15*IF(X16="Melee",0.6,1.35)*IFERROR(VLOOKUP($AM16,個性タイプマスタ!$A$5:$P$100,14,FALSE),1),0)) -> 18 | G16: =IF(X16="Melee",AN16,MAX(1,ROUND(AN16*設定!$B$16*IFERROR(VLOOKUP($AM16,個性タイプマスタ!$A$5:$P$100,15,FALSE),1),0))) -> 8 | H16: =IF(X16="Ranged",AN16,MAX(1,ROUND(AN16*設定!$B$16*IFERROR(VLOOKUP($AM16,個性タイプマスタ!$A$5:$P$100,15,FALSE),1),0))) -> 18 | I16: =MAX(0,ROUND(設定!$B$8*AE16*Z16,0)) -> 8 | J16: =MAX(0,ROUND(設定!$B$9*AE16*AA16,0)) -> 10 | K16: =IFERROR(VLOOKUP($AM16,個性タイプマスタ!$A$5:$P$100,9,FALSE),0.05) -> 0.07 | L16: =IFERROR(VLOOKUP($AM16,個性タイプマスタ!$A$5:$P$100,10,FALSE),1.5) -> 1.55 | M16: =IFERROR(VLOOKUP($AM16,個性タイプマスタ!$A$5:$P$100,11,FALSE),2) -> 2.3 | N16: =MAX(0.1,ROUND(設定!$B$10*AB16,3)) -> 1.1 | O16: =MAX(0.1,ROUND(IF(X16="Melee",1.5,2.5)*AC16,3)) -> 2.7 | P16: =MAX(-10,MIN(0.8,IFERROR(INDEX(属性耐性マスタ!$B$5:$G$11,MATCH($C16,属性耐性マスタ!$A$5:$A$11,0),1),0)+IFERROR(VLOOKUP($AM16,個性タイプマスタ!$A$5:$P$100,12,FALSE),0))) -> -0.03 | Q16: =MAX(-10,MIN(0.8,IFERROR(INDEX(属性耐性マスタ!$B$5:$G$11,MATCH($C16,属性耐性マスタ!$A$5:$A$11,0),2),0)+IFERROR(VLOOKUP($AM16,個性タイプマスタ!$A$5:$P$100,12,FALSE),0))) -> -0.03 | R16: =MAX(-10,MIN(0.8,IFERROR(INDEX(属性耐性マスタ!$B$5:$G$11,MATCH($C16,属性耐性マスタ!$A$5:$A$11,0),3),0)+IFERROR(VLOOKUP($AM16,個性タイプマスタ!$A$5:$P$100,12,FALSE),0))) -> -0.03 | S16: =MAX(-10,MIN(0.8,IFERROR(INDEX(属性耐性マスタ!$B$5:$G$11,MATCH($C16,属性耐性マスタ!$A$5:$A$11,0),4),0)+IFERROR(VLOOKUP($AM16,個性タイプマスタ!$A$5:$P$100,12,FALSE),0))) -> -0.03 | T16: =MAX(-10,MIN(0.8,IFERROR(INDEX(属性耐性マスタ!$B$5:$G$11,MATCH($C16,属性耐性マスタ!$A$5:$A$11,0),5),0)+IFERROR(VLOOKUP($AM16,個性タイプマスタ!$A$5:$P$100,12,FALSE),0))) -> -0.13 | U16: =MAX(-10,MIN(0.8,IFERROR(INDEX(属性耐性マスタ!$B$5:$G$11,MATCH($C16,属性耐性マスタ!$A$5:$A$11,0),6),0)+IFERROR(VLOOKUP($AM16,個性タイプマスタ!$A$5:$P$100,12,FALSE),0))) -> 0.17 | V16: =ROUND(設定!$B$19*IFERROR(VLOOKUP($AM16,個性タイプマスタ!$A$5:$P$100,13,FALSE),1),2) -> 4 | W16: 2 | X16: =IFERROR(VLOOKUP($AM16,個性タイプマスタ!$A$5:$P$100,2,FALSE),"Ranged") -> Ranged | Y16: =IFERROR(VLOOKUP($AM16,個性タイプマスタ!$A$5:$P$100,3,FALSE),1) -> 1 | Z16: =IFERROR(VLOOKUP($AM16,個性タイプマスタ!$A$5:$P$100,4,FALSE),1) -> 0.95 | AA16: =IFERROR(VLOOKUP($AM16,個性タイプマスタ!$A$5:$P$100,5,FALSE),1) -> 1.1 | AB16: =IFERROR(VLOOKUP($AM16,個性タイプマスタ!$A$5:$P$100,6,FALSE),1) -> 1.1 | AC16: =IFERROR(VLOOKUP($AM16,個性タイプマスタ!$A$5:$P$100,7,FALSE),1) -> 1.08 | AD16: =IFERROR(VLOOKUP($AM16,個性タイプマスタ!$A$5:$P$100,8,FALSE),1) -> 0.8 | AE16: =IFERROR(D16/設定!$B$5,1) -> 1.1 | AF16: =1+設定!$B$13*((I16/設定!$B$8+J16/設定!$B$9)/(2*AE16)) -> 1.3068182 | AG16: =MAX(0.7,1+設定!$B$14*(O16/IF(X16="Melee",1.5,2.5)-1)) -> 1.0096 | AH16: =IF(X16="Melee",G16,H16)*N16*(1+K16*(L16-1))*AG16 -> 20.759698 | AI16: =E16*AF16*(1+設定!$B$18*AVERAGE(P16:U16)) -> 142.8875 | AJ16: =設定!$B$5*SQRT((AH16/(設定!$B$7*設定!$B$10*(1+設定!$B$11*(設定!$B$12-1))))*(AI16/(設定!$B$6*(1+設定!$B$13)))) -> 111.20845 | AK16: =IF(D16=0,0,AJ16/D16-1) -> 0.010985877 | AL16: =D16*AD16 -> 88 | AM16: 魔法・速攻 | AN16: =MAX(1,ROUND((設定!$B$7*設定!$B$10*(1+設定!$B$11*(設定!$B$12-1)))*AE16^2*(設定!$B$6*(1+設定!$B$13))/(AI16*N16*(1+K16*(L16-1))*AG16),0)) -> 18 | AO16: =IF($A16="","",IF(COUNTIF(個性タイプマスタ!$A$5:$A$100,$AM16)>0,"OK","未登録")) -> OK | AP16: =IF($A16="","",IF(COUNTIF(属性耐性マスタ!$A$5:$A$11,$C16)>0,"OK","未登録")) -> OK
... A370: MON_366 | B370: アステルヴェイン | C370: 風 | D370: =ROUND(設定!$B$5*POWER($D$2,W370-1),2) -> 30448.16 | E370: =MAX(1,ROUND(設定!$B$6*AE370*Y370,0)) -> 30448 | F370: =MAX(0,ROUND(設定!$B$7*AE370*設定!$B$15*IF(X370="Melee",0.6,1.35)*IFERROR(VLOOKUP($AM370,個性タイプマスタ!$A$5:$P$100,14,FALSE),1),0)) -> 6437 | G370: =IF(X370="Melee",AN370,MAX(1,ROUND(AN370*設定!$B$16*IFERROR(VLOOKUP($AM370,個性タイプマスタ!$A$5:$P$100,15,FALSE),1),0))) -> 2444 | H370: =IF(X370="Ranged",AN370,MAX(1,ROUND(AN370*設定!$B$16*IFERROR(VLOOKUP($AM370,個性タイプマスタ!$A$5:$P$100,15,FALSE),1),0))) -> 5431 | I370: =MAX(0,ROUND(設定!$B$8*AE370*Z370,0)) -> 2436 | J370: =MAX(0,ROUND(設定!$B$9*AE370*AA370,0)) -> 2923 | K370: =IFERROR(VLOOKUP($AM370,個性タイプマスタ!$A$5:$P$100,9,FALSE),0.05) -> 0.06 | L370: =IFERROR(VLOOKUP($AM370,個性タイプマスタ!$A$5:$P$100,10,FALSE),1.5) -> 1.4 | M370: =IFERROR(VLOOKUP($AM370,個性タイプマスタ!$A$5:$P$100,11,FALSE),2) -> 2.1 | N370: =MAX(0.1,ROUND(設定!$B$10*AB370,3)) -> 0.95 | O370: =MAX(0.1,ROUND(IF(X370="Melee",1.5,2.5)*AC370,3)) -> 2.875 | P370: =MAX(-10,MIN(0.8,IFERROR(INDEX(属性耐性マスタ!$B$5:$G$11,MATCH($C370,属性耐性マスタ!$A$5:$A$11,0),1),0)+IFERROR(VLOOKUP($AM370,個性タイプマスタ!$A$5:$P$100,12,FALSE),0))) -> 0.03 | Q370: =MAX(-10,MIN(0.8,IFERROR(INDEX(属性耐性マスタ!$B$5:$G$11,MATCH($C370,属性耐性マスタ!$A$5:$A$11,0),2),0)+IFERROR(VLOOKUP($AM370,個性タイプマスタ!$A$5:$P$100,12,FALSE),0))) -> 0.03 | R370: =MAX(-10,MIN(0.8,IFERROR(INDEX(属性耐性マスタ!$B$5:$G$11,MATCH($C370,属性耐性マスタ!$A$5:$A$11,0),3),0)+IFERROR(VLOOKUP($AM370,個性タイプマスタ!$A$5:$P$100,12,FALSE),0))) -> 0.23 | S370: =MAX(-10,MIN(0.8,IFERROR(INDEX(属性耐性マスタ!$B$5:$G$11,MATCH($C370,属性耐性マスタ!$A$5:$A$11,0),4),0)+IFERROR(VLOOKUP($AM370,個性タイプマスタ!$A$5:$P$100,12,FALSE),0))) -> -0.07 | T370: =MAX(-10,MIN(0.8,IFERROR(INDEX(属性耐性マスタ!$B$5:$G$11,MATCH($C370,属性耐性マスタ!$A$5:$A$11,0),5),0)+IFERROR(VLOOKUP($AM370,個性タイプマスタ!$A$5:$P$100,12,FALSE),0))) -> 0.03 | U370: =MAX(-10,MIN(0.8,IFERROR(INDEX(属性耐性マスタ!$B$5:$G$11,MATCH($C370,属性耐性マスタ!$A$5:$A$11,0),6),0)+IFERROR(VLOOKUP($AM370,個性タイプマスタ!$A$5:$P$100,12,FALSE),0))) -> 0.03 | V370: =ROUND(設定!$B$19*IFERROR(VLOOKUP($AM370,個性タイプマスタ!$A$5:$P$100,13,FALSE),1),2) -> 4.8 | W370: 61 | X370: =IFERROR(VLOOKUP($AM370,個性タイプマスタ!$A$5:$P$100,2,FALSE),"Ranged") -> Ranged | Y370: =IFERROR(VLOOKUP($AM370,個性タイプマスタ!$A$5:$P$100,3,FALSE),1) -> 1 | Z370: =IFERROR(VLOOKUP($AM370,個性タイプマスタ!$A$5:$P$100,4,FALSE),1) -> 1 | AA370: =IFERROR(VLOOKUP($AM370,個性タイプマスタ!$A$5:$P$100,5,FALSE),1) -> 1.2 | AB370: =IFERROR(VLOOKUP($AM370,個性タイプマスタ!$A$5:$P$100,6,FALSE),1) -> 0.95 | AC370: =IFERROR(VLOOKUP($AM370,個性タイプマスタ!$A$5:$P$100,7,FALSE),1) -> 1.15 | AD370: =IFERROR(VLOOKUP($AM370,個性タイプマスタ!$A$5:$P$100,8,FALSE),1) -> 0.84 | AE370: =IFERROR(D370/設定!$B$5,1) -> 304.4816 | AF370: =1+設定!$B$13*((I370/設定!$B$8+J370/設定!$B$9)/(2*AE370)) -> 1.3300076 | AG370: =MAX(0.7,1+設定!$B$14*(O370/IF(X370="Melee",1.5,2.5)-1)) -> 1.018 | AH370: =IF(X370="Melee",G370,H370)*N370*(1+K370*(L370-1))*AG370 -> 5378.3758 | AI370: =E370*AF370*(1+設定!$B$18*AVERAGE(P370:U370)) -> 41346.49 | AJ370: =設定!$B$5*SQRT((AH370/(設定!$B$7*設定!$B$10*(1+設定!$B$11*(設定!$B$12-1))))*(AI370/(設定!$B$6*(1+設定!$B$13)))) -> 30449.14 | AK370: =IF(D370=0,0,AJ370/D370-1) -> 3.2188263e-05 | AL370: =D370*AD370 -> 25576.454 | AM370: 魔法・支援 | AN370: =MAX(1,ROUND((設定!$B$7*設定!$B$10*(1+設定!$B$11*(設定!$B$12-1)))*AE370^2*(設定!$B$6*(1+設定!$B$13))/(AI370*N370*(1+K370*(L370-1))*AG370),0)) -> 5431 | AO370: =IF($A370="","",IF(COUNTIF(個性タイプマスタ!$A$5:$A$100,$AM370)>0,"OK","未登録")) -> OK | AP370: =IF($A370="","",IF(COUNTIF(属性耐性マスタ!$A$5:$A$11,$C370)>0,"OK","未登録")) -> OK

Sheet Stage比較
A1: STAGE POWER OVERVIEW
A2: 同じステージの6体を目標値に合わせた検証。差率の目安: ±5%以内。
A4: Stage | B4: 目標戦闘力 | C4: 平均実測戦闘力 | D4: 最小実測 | E4: 最大実測 | F4: 最大差率(絶対) | G4: Lv1想定平均
A5: 1 | B5: =モンスター計算!D5 -> 100 | C5: =AVERAGE(モンスター計算!AJ5:AJ10) -> 98.968371 | D5: =MIN(モンスター計算!AJ5:AJ10) -> 98.539832 | E5: =MAX(モンスター計算!AJ5:AJ10) -> 99.311905 | F5: =MAX(ABS(モンスター計算!AK5),ABS(モンスター計算!AK6),ABS(モンスター計算!AK7),ABS(モンスター計算!AK8),ABS(モンスター計算!AK9),ABS(モンスター計算!AK10)) -> 0.01460168 | G5: =AVERAGE(モンスター計算!AL5:AL10) -> 78.166667
A6: 2 | B6: =モンスター計算!D11 -> 110 | C6: =AVERAGE(モンスター計算!AJ11:AJ16) -> 109.59492 | D6: =MIN(モンスター計算!AJ11:AJ16) -> 108.69298 | E6: =MAX(モンスター計算!AJ11:AJ16) -> 111.20845 | F6: =MAX(ABS(モンスター計算!AK11),ABS(モンスター計算!AK12),ABS(モンスター計算!AK13),ABS(モンスター計算!AK14),ABS(モンスター計算!AK15),ABS(モンスター計算!AK16)) -> 0.011882013 | G6: =AVERAGE(モンスター計算!AL11:AL16) -> 87.816667
A7: 3 | B7: =モンスター計算!D17 -> 121 | C7: =AVERAGE(モンスター計算!AJ17:AJ22) -> 120.93503 | D7: =MIN(モンスター計算!AJ17:AJ22) -> 119.99375 | E7: =MAX(モンスター計算!AJ17:AJ22) -> 121.82593 | F7: =MAX(ABS(モンスター計算!AK17),ABS(モンスター計算!AK18),ABS(モンスター計算!AK19),ABS(モンスター計算!AK20),ABS(モンスター計算!AK21),ABS(モンスター計算!AK22)) -> 0.008316156 | G7: =AVERAGE(モンスター計算!AL17:AL22) -> 99.825
A8: 4 | B8: =モンスター計算!D23 -> 133.1 | C8: =AVERAGE(モンスター計算!AJ23:AJ28) -> 133.42639 | D8: =MIN(モンスター計算!AJ23:AJ28) -> 132.52814 | E8: =MAX(モンスター計算!AJ23:AJ28) -> 134.98192 | F8: =MAX(ABS(モンスター計算!AK23),ABS(モンスター計算!AK24),ABS(モンスター計算!AK25),ABS(モンスター計算!AK26),ABS(モンスター計算!AK27),ABS(モンスター計算!AK28)) -> 0.014139143 | G8: =AVERAGE(モンスター計算!AL23:AL28) -> 104.03983
A9: 5 | B9: =モンスター計算!D29 -> 146.41 | C9: =AVERAGE(モンスター計算!AJ29:AJ34) -> 146.45584 | D9: =MIN(モンスター計算!AJ29:AJ34) -> 145.4402 | E9: =MAX(モンスター計算!AJ29:AJ34) -> 147.04753 | F9: =MAX(ABS(モンスター計算!AK29),ABS(モンスター計算!AK30),ABS(モンスター計算!AK31),ABS(モンスター計算!AK32),ABS(モンスター計算!AK33),ABS(モンスター計算!AK34)) -> 0.0066238585 | G9: =AVERAGE(モンスター計算!AL29:AL34) -> 111.2716
A10: 6 | B10: =モンスター計算!D35 -> 161.05 | C10: =AVERAGE(モンスター計算!AJ35:AJ40) -> 161.13475 | D10: =MIN(モンスター計算!AJ35:AJ40) -> 160.02682 | E10: =MAX(モンスター計算!AJ35:AJ40) -> 162.14769 | F10: =MAX(ABS(モンスター計算!AK35),ABS(モンスター計算!AK36),ABS(モンスター計算!AK37),ABS(モンスター計算!AK38),ABS(モンスター計算!AK39),ABS(モンスター計算!AK40)) -> 0.0068158441 | G10: =AVERAGE(モンスター計算!AL35:AL40) -> 128.84
A11: 7 | B11: =モンスター計算!D41 -> 177.16 | C11: =AVERAGE(モンスター計算!AJ41:AJ46) -> 177.48186 | D11: =MIN(モンスター計算!AJ41:AJ46) -> 176.12628 | E11: =MAX(モンスター計算!AJ41:AJ46) -> 178.47209 | F11: =MAX(ABS(モンスター計算!AK41),ABS(モンスター計算!AK42),ABS(モンスター計算!AK43),ABS(モンスター計算!AK44),ABS(モンスター計算!AK45),ABS(モンスター計算!AK46)) -> 0.0074062249 | G11: =AVERAGE(モンスター計算!AL41:AL46) -> 130.50787
A12: 8 | B12: =モンスター計算!D47 -> 194.87 | C12: =AVERAGE(モンスター計算!AJ47:AJ52) -> 195.16035 | D12: =MIN(モンスター計算!AJ47:AJ52) -> 194.37637 | E12: =MAX(モンスター計算!AJ47:AJ52) -> 196.15204 | F12: =MAX(ABS(モンスター計算!AK47),ABS(モンスター計算!AK48),ABS(モンスター計算!AK49),ABS(モンスター計算!AK50),ABS(モンスター計算!AK51),ABS(モンスター計算!AK52)) -> 0.0065789428 | G12: =AVERAGE(モンスター計算!AL47:AL52) -> 147.12685
A13: 9 | B13: =モンスター計算!D53 -> 214.36 | C13: =AVERAGE(モンスター計算!AJ53:AJ58) -> 214.46187 | D13: =MIN(モンスター計算!AJ53:AJ58) -> 212.85453 | E13: =MAX(モンスター計算!AJ53:AJ58) -> 215.14493 | F13: =MAX(ABS(モンスター計算!AK53),ABS(モンスター計算!AK54),ABS(モンスター計算!AK55),ABS(モンスター計算!AK56),ABS(モンスター計算!AK57),ABS(モンスター計算!AK58)) -> 0.0070230811 | G13: =AVERAGE(モンスター計算!AL53:AL58) -> 169.3444
A14: 10 | B14: =モンスター計算!D59 -> 235.79 | C14: =AVERAGE(モンスター計算!AJ59:AJ64) -> 235.39628 | D14: =MIN(モンスター計算!AJ59:AJ64) -> 233.96259 | E14: =MAX(モンスター計算!AJ59:AJ64) -> 236.80902 | F14: =MAX(ABS(モンスター計算!AK59),ABS(モンスター計算!AK60),ABS(モンスター計算!AK61),ABS(モンスター計算!AK62),ABS(モンスター計算!AK63),ABS(モンスター計算!AK64)) -> 0.0077501493 | G14: =AVERAGE(モンスター計算!AL59:AL64) -> 172.1267
A15: 11 | B15: =モンスター計算!D65 -> 259.37 | C15: =AVERAGE(モンスター計算!AJ65:AJ70) -> 259.74543 | D15: =MIN(モンスター計算!AJ65:AJ70) -> 258.70036 | E15: =MAX(モンスター計算!AJ65:AJ70) -> 260.6469 | F15: =MAX(ABS(モンスター計算!AK65),ABS(モンスター計算!AK66),ABS(モンスター計算!AK67),ABS(モンスター計算!AK68),ABS(モンスター計算!AK69),ABS(モンスター計算!AK70)) -> 0.004923079 | G15: =AVERAGE(モンスター計算!AL65:AL70) -> 207.06372
A16: 12 | B16: =モンスター計算!D71 -> 285.31 | C16: =AVERAGE(モンスター計算!AJ71:AJ76) -> 285.78664 | D16: =MIN(モンスター計算!AJ71:AJ76) -> 284.40997 | E16: =MAX(モンスター計算!AJ71:AJ76) -> 286.62183 | F16: =MAX(ABS(モンスター計算!AK71),ABS(モンスター計算!AK72),ABS(モンスター計算!AK73),ABS(モンスター計算!AK74),ABS(モンスター計算!AK75),ABS(モンスター計算!AK76)) -> 0.0045978943 | G16: =AVERAGE(モンスター計算!AL71:AL76) -> 227.29697
A17: 13 | B17: =モンスター計算!D77 -> 313.84 | C17: =AVERAGE(モンスター計算!AJ77:AJ82) -> 314.05029 | D17: =MIN(モンスター計算!AJ77:AJ82) -> 313.07327 | E17: =MAX(モンスター計算!AJ77:AJ82) -> 315.22068 | F17: =MAX(ABS(モンスター計算!AK77),ABS(モンスター計算!AK78),ABS(モンスター計算!AK79),ABS(モンスター計算!AK80),ABS(モンスター計算!AK81),ABS(モンスター計算!AK82)) -> 0.0043993002 | G17: =AVERAGE(モンスター計算!AL77:AL82) -> 225.9648
A18: 14 | B18: =モンスター計算!D83 -> 345.23 | C18: =AVERAGE(モンスター計算!AJ83:AJ88) -> 345.96816 | D18: =MIN(モンスター計算!AJ83:AJ88) -> 344.58315 | E18: =MAX(モンスター計算!AJ83:AJ88) -> 346.88339 | F18: =MAX(ABS(モンスター計算!AK83),ABS(モンスター計算!AK84),ABS(モンスター計算!AK85),ABS(モンスター計算!AK86),ABS(モンスター計算!AK87),ABS(モンスター計算!AK88)) -> 0.0047892298 | G18: =AVERAGE(モンスター計算!AL83:AL88) -> 272.15632
A19: 15 | B19: =モンスター計算!D89 -> 379.75 | C19: =AVERAGE(モンスター計算!AJ89:AJ94) -> 379.67802 | D19: =MIN(モンスター計算!AJ89:AJ94) -> 378.75651 | E19: =MAX(モンスター計算!AJ89:AJ94) -> 380.40504 | F19: =MAX(ABS(モンスター計算!AK89),ABS(モンスター計算!AK90),ABS(モンスター計算!AK91),ABS(モンスター計算!AK92),ABS(モンスター計算!AK93),ABS(モンスター計算!AK94)) -> 0.0026161727 | G19: =AVERAGE(モンスター計算!AL89:AL94) -> 276.58458
A20: 16 | B20: =モンスター計算!D95 -> 417.72 | C20: =AVERAGE(モンスター計算!AJ95:AJ100) -> 417.22389 | D20: =MIN(モンスター計算!AJ95:AJ100) -> 416.50409 | E20: =MAX(モンスター計算!AJ95:AJ100) -> 418.14365 | F20: =MAX(ABS(モンスター計算!AK95),ABS(モンスター計算!AK96),ABS(モンスター計算!AK97),ABS(モンスター計算!AK98),ABS(モンスター計算!AK99),ABS(モンスター計算!AK100)) -> 0.0029108265 | G20: =AVERAGE(モンスター計算!AL95:AL100) -> 276.3914
A21: 17 | B21: =モンスター計算!D101 -> 459.5 | C21: =AVERAGE(モンスター計算!AJ101:AJ106) -> 459.9537 | D21: =MIN(モンスター計算!AJ101:AJ106) -> 458.35817 | E21: =MAX(モンスター計算!AJ101:AJ106) -> 461.62892 | F21: =MAX(ABS(モンスター計算!AK101),ABS(モンスター計算!AK102),ABS(モンスター計算!AK103),ABS(モンスター計算!AK104),ABS(モンスター計算!AK105),ABS(モンスター計算!AK106)) -> 0.0046331229 | G21: =AVERAGE(モンスター計算!AL101:AL106) -> 350.75167
A22: 18 | B22: =モンスター計算!D107 -> 505.45 | C22: =AVERAGE(モンスター計算!AJ107:AJ112) -> 505.38892 | D22: =MIN(モンスター計算!AJ107:AJ112) -> 504.65277 | E22: =MAX(モンスター計算!AJ107:AJ112) -> 506.50327 | F22: =MAX(ABS(モンスター計算!AK107),ABS(モンスター計算!AK108),ABS(モンスター計算!AK109),ABS(モンスター計算!AK110),ABS(モンスター計算!AK111),ABS(モンスター計算!AK112)) -> 0.0020838288 | G22: =AVERAGE(モンスター計算!AL107:AL112) -> 370.66333
A23: 19 | B23: =モンスター計算!D113 -> 555.99 | C23: =AVERAGE(モンスター計算!AJ113:AJ118) -> 556.34894 | D23: =MIN(モンスター計算!AJ113:AJ118) -> 555.33574 | E23: =MAX(モンスター計算!AJ113:AJ118) -> 557.04845 | F23: =MAX(ABS(モンスター計算!AK113),ABS(モンスター計算!AK114),ABS(モンスター計算!AK115),ABS(モンスター計算!AK116),ABS(モンスター計算!AK117),ABS(モンスター計算!AK118)) -> 0.0019037138 | G23: =AVERAGE(モンスター計算!AL113:AL118) -> 404.0194
A24: 20 | B24: =モンスター計算!D119 -> 611.59 | C24: =AVERAGE(モンスター計算!AJ119:AJ124) -> 611.51037 | D24: =MIN(モンスター計算!AJ119:AJ124) -> 610.38507 | E24: =MAX(モンスター計算!AJ119:AJ124) -> 612.64816 | F24: =MAX(ABS(モンスター計算!AK119),ABS(モンスター計算!AK120),ABS(モンスター計算!AK121),ABS(モンスター計算!AK122),ABS(モンスター計算!AK123),ABS(モンスター計算!AK124)) -> 0.0019701673 | G24: =AVERAGE(モンスター計算!AL119:AL124) -> 471.94362
A25: 21 | B25: =モンスター計算!D125 -> 672.75 | C25: =AVERAGE(モンスター計算!AJ125:AJ130) -> 672.70483 | D25: =MIN(モンスター計算!AJ125:AJ130) -> 671.82632 | E25: =MAX(モンスター計算!AJ125:AJ130) -> 673.32337 | F25: =MAX(ABS(モンスター計算!AK125),ABS(モンスター計算!AK126),ABS(モンスター計算!AK127),ABS(モンスター計算!AK128),ABS(モンスター計算!AK129),ABS(モンスター計算!AK130)) -> 0.0013729846 | G25: =AVERAGE(モンスター計算!AL125:AL130) -> 498.95625
A26: 22 | B26: =モンスター計算!D131 -> 740.02 | C26: =AVERAGE(モンスター計算!AJ131:AJ136) -> 739.8638 | D26: =MIN(モンスター計算!AJ131:AJ136) -> 738.77908 | E26: =MAX(モンスター計算!AJ131:AJ136) -> 741.0425 | F26: =MAX(ABS(モンスター計算!AK131),ABS(モンスター計算!AK132),ABS(モンスター計算!AK133),ABS(モンスター計算!AK134),ABS(モンスター計算!AK135),ABS(モンスター計算!AK136)) -> 0.0016768674 | G26: =AVERAGE(モンスター計算!AL131:AL136) -> 547.6148
A27: 23 | B27: =モンスター計算!D137 -> 814.03 | C27: =AVERAGE(モンスター計算!AJ137:AJ142) -> 813.66945 | D27: =MIN(モンスター計算!AJ137:AJ142) -> 812.98834 | E27: =MAX(モンスター計算!AJ137:AJ142) -> 815.31888 | F27: =MAX(ABS(モンスター計算!AK137),ABS(モンスター計算!AK138),ABS(モンスター計算!AK139),ABS(モンスター計算!AK140),ABS(モンスター計算!AK141),ABS(モンスター計算!AK142)) -> 0.0015833264 | G27: =AVERAGE(モンスター計算!AL137:AL142) -> 667.5046
A28: 24 | B28: =モンスター計算!D143 -> 895.43 | C28: =AVERAGE(モンスター計算!AJ143:AJ148) -> 895.66371 | D28: =MIN(モンスター計算!AJ143:AJ148) -> 894.89806 | E28: =MAX(モンスター計算!AJ143:AJ148) -> 896.32228 | F28: =MAX(ABS(モンスター計算!AK143),ABS(モンスター計算!AK144),ABS(モンスター計算!AK145),ABS(モンスター計算!AK146),ABS(モンスター計算!AK147),ABS(モンスター計算!AK148)) -> 0.00099648607 | G28: =AVERAGE(モンスター計算!AL143:AL148) -> 656.64867
A29: 25 | B29: =モンスター計算!D149 -> 984.97 | C29: =AVERAGE(モンスター計算!AJ149:AJ154) -> 984.8666 | D29: =MIN(モンスター計算!AJ149:AJ154) -> 983.70016 | E29: =MAX(モンスター計算!AJ149:AJ154) -> 986.86309 | F29: =MAX(ABS(モンスター計算!AK149),ABS(モンスター計算!AK150),ABS(モンスター計算!AK151),ABS(モンスター計算!AK152),ABS(モンスター計算!AK153),ABS(モンスター計算!AK154)) -> 0.0019219731 | G29: =AVERAGE(モンスター計算!AL149:AL154) -> 779.76792
A30: 26 | B30: =モンスター計算!D155 -> 1083.47 | C30: =AVERAGE(モンスター計算!AJ155:AJ160) -> 1083.1383 | D30: =MIN(モンスター計算!AJ155:AJ160) -> 1082.711 | E30: =MAX(モンスター計算!AJ155:AJ160) -> 1084.2784 | F30: =MAX(ABS(モンスター計算!AK155),ABS(モンスター計算!AK156),ABS(モンスター計算!AK157),ABS(モンスター計算!AK158),ABS(モンスター計算!AK159),ABS(モンスター計算!AK160)) -> 0.00074611507 | G30: =AVERAGE(モンスター計算!AL155:AL160) -> 785.51575
A31: 27 | B31: =モンスター計算!D161 -> 1191.82 | C31: =AVERAGE(モンスター計算!AJ161:AJ166) -> 1192.4548 | D31: =MIN(モンスター計算!AJ161:AJ166) -> 1191.3039 | E31: =MAX(モンスター計算!AJ161:AJ166) -> 1193.3259 | F31: =MAX(ABS(モンスター計算!AK161),ABS(モンスター計算!AK162),ABS(モンスター計算!AK163),ABS(モンスター計算!AK164),ABS(モンスター計算!AK165),ABS(モンスター計算!AK166)) -> 0.0012635092 | G31: =AVERAGE(モンスター計算!AL161:AL166) -> 951.46963
A32: 28 | B32: =モンスター計算!D167 -> 1311 | C32: =AVERAGE(モンスター計算!AJ167:AJ172) -> 1311.0019 | D32: =MIN(モンスター計算!AJ167:AJ172) -> 1310.1389 | E32: =MAX(モンスター計算!AJ167:AJ172) -> 1312.0475 | F32: =MAX(ABS(モンスター計算!AK167),ABS(モンスター計算!AK168),ABS(モンスター計算!AK169),ABS(モンスター計算!AK170),ABS(モンスター計算!AK171),ABS(モンスター計算!AK172)) -> 0.00079902413 | G32: =AVERAGE(モンスター計算!AL167:AL172) -> 1081.575
A33: 29 | B33: =モンスター計算!D173 -> 1442.1 | C33: =AVERAGE(モンスター計算!AJ173:AJ178) -> 1442.6261 | D33: =MIN(モンスター計算!AJ173:AJ178) -> 1441.4375 | E33: =MAX(モンスター計算!AJ173:AJ178) -> 1444.0532 | F33: =MAX(ABS(モンスター計算!AK173),ABS(モンスター計算!AK174),ABS(モンスター計算!AK175),ABS(モンスター計算!AK176),ABS(モンスター計算!AK177),ABS(モンスター計算!AK178)) -> 0.0013544389 | G33: =AVERAGE(モンスター計算!AL173:AL178) -> 1127.2415
A34: 30 | B34: =モンスター計算!D179 -> 1586.31 | C34: =AVERAGE(モンスター計算!AJ179:AJ184) -> 1586.5913 | D34: =MIN(モンスター計算!AJ179:AJ184) -> 1586.046 | E34: =MAX(モンスター計算!AJ179:AJ184) -> 1587.3171 | F34: =MAX(ABS(モンスター計算!AK179),ABS(モンスター計算!AK180),ABS(モンスター計算!AK181),ABS(モンスター計算!AK182),ABS(モンスター計算!AK183),ABS(モンスター計算!AK184)) -> 0.00063488416 | G34: =AVERAGE(モンスター計算!AL179:AL184) -> 1205.5956
A35: 31 | B35: =モンスター計算!D185 -> 1744.94 | C35: =AVERAGE(モンスター計算!AJ185:AJ190) -> 1745.1473 | D35: =MIN(モンスター計算!AJ185:AJ190) -> 1744.0324 | E35: =MAX(モンスター計算!AJ185:AJ190) -> 1746.0833 | F35: =MAX(ABS(モンスター計算!AK185),ABS(モンスター計算!AK186),ABS(モンスター計算!AK187),ABS(モンスター計算!AK188),ABS(モンスター計算!AK189),ABS(モンスター計算!AK190)) -> 0.00065522935 | G35: =AVERAGE(モンスター計算!AL185:AL190) -> 1395.952
A36: 32 | B36: =モンスター計算!D191 -> 1919.43 | C36: =AVERAGE(モンスター計算!AJ191:AJ196) -> 1919.2488 | D36: =MIN(モンスター計算!AJ191:AJ196) -> 1918.1415 | E36: =MAX(モンスター計算!AJ191:AJ196) -> 1920.2024 | F36: =MAX(ABS(モンスター計算!AK191),ABS(モンスター計算!AK192),ABS(モンスター計算!AK193),ABS(モンスター計算!AK194),ABS(モンスター計算!AK195),ABS(モンスター計算!AK196)) -> 0.00067129518 | G36: =AVERAGE(モンスター計算!AL191:AL196) -> 1413.9801
A37: 33 | B37: =モンスター計算!D197 -> 2111.38 | C37: =AVERAGE(モンスター計算!AJ197:AJ202) -> 2111.3437 | D37: =MIN(モンスター計算!AJ197:AJ202) -> 2110.5368 | E37: =MAX(モンスター計算!AJ197:AJ202) -> 2112.7899 | F37: =MAX(ABS(モンスター計算!AK197),ABS(モンスター計算!AK198),ABS(モンスター計算!AK199),ABS(モンスター計算!AK200),ABS(モンスター計算!AK201),ABS(モンスター計算!AK202)) -> 0.00066774697 | G37: =AVERAGE(モンスター計算!AL197:AL202) -> 1594.0919
A38: 34 | B38: =モンスター計算!D203 -> 2322.52 | C38: =AVERAGE(モンスター計算!AJ203:AJ208) -> 2322.4564 | D38: =MIN(モンスター計算!AJ203:AJ208) -> 2321.7524 | E38: =MAX(モンスター計算!AJ203:AJ208) -> 2323.3053 | F38: =MAX(ABS(モンスター計算!AK203),ABS(モンスター計算!AK204),ABS(モンスター計算!AK205),ABS(モンスター計算!AK206),ABS(モンスター計算!AK207),ABS(モンスター計算!AK208)) -> 0.00033811289 | G38: =AVERAGE(モンスター計算!AL203:AL208) -> 1834.7908
A39: 35 | B39: =モンスター計算!D209 -> 2554.77 | C39: =AVERAGE(モンスター計算!AJ209:AJ214) -> 2554.9068 | D39: =MIN(モンスター計算!AJ209:AJ214) -> 2553.2426 | E39: =MAX(モンスター計算!AJ209:AJ214) -> 2555.8087 | F39: =MAX(ABS(モンスター計算!AK209),ABS(モンスター計算!AK210),ABS(モンスター計算!AK211),ABS(モンスター計算!AK212),ABS(モンスター計算!AK213),ABS(モンスター計算!AK214)) -> 0.00059785276 | G39: =AVERAGE(モンスター計算!AL209:AL214) -> 1864.9821
A40: 36 | B40: =モンスター計算!D215 -> 2810.24 | C40: =AVERAGE(モンスター計算!AJ215:AJ220) -> 2809.9372 | D40: =MIN(モンスター計算!AJ215:AJ220) -> 2809.062 | E40: =MAX(モンスター計算!AJ215:AJ220) -> 2810.5931 | F40: =MAX(ABS(モンスター計算!AK215),ABS(モンスター計算!AK216),ABS(モンスター計算!AK217),ABS(モンスター計算!AK218),ABS(モンスター計算!AK219),ABS(モンスター計算!AK220)) -> 0.00041918595 | G40: =AVERAGE(モンスター計算!AL215:AL220) -> 2243.5083
A41: 37 | B41: =モンスター計算!D221 -> 3091.27 | C41: =AVERAGE(モンスター計算!AJ221:AJ226) -> 3091.0607 | D41: =MIN(モンスター計算!AJ221:AJ226) -> 3089.379 | E41: =MAX(モンスター計算!AJ221:AJ226) -> 3092.2439 | F41: =MAX(ABS(モンスター計算!AK221),ABS(モンスター計算!AK222),ABS(モンスター計算!AK223),ABS(モンスター計算!AK224),ABS(モンスター計算!AK225),ABS(モンスター計算!AK226)) -> 0.00061171149 | G41: =AVERAGE(モンスター計算!AL221:AL226) -> 2462.7118
...

Sheet 個性タイプマスタ
A1: PERSONALITY MASTER | 個性タイプの数値を調整すると対象モンスターが全員更新
A2: 青いセル＝設定値。倍率1.0は標準。耐性補正0.05＝＋5％ポイント。青いタイプ名を変更するとドロップダウンに反映。
A4: 個性タイプ（ドロップダウン） | B4: 攻撃方式 | C4: HP倍率 | D4: 物防倍率 | E4: 魔防倍率 | F4: 攻速倍率 | G4: 射程倍率 | H4: 親密Lv1比 | I4: クリ率 | J4: クリ倍 | K4: 移動速度 | L4: 耐性一律補正 | M4: 索敵倍率 | N4: MP倍率 | O4: 副攻撃倍率 | P4: 設計メモ
A5: 魔法・軽量 | B5: Ranged | C5: 0.82 | D5: 0.85 | E5: 1 | F5: 1 | G5: 1 | H5: 0.68 | I5: 0.05 | J5: 1.5 | K5: 2 | L5: -0.02 | M5: 1 | N5: 0.9 | O5: 1 | P5: 軽快な魔法型。耐久控えめ・成長余地大
A6: 魔法・均衡 | B6: Ranged | C6: 0.92 | D6: 0.95 | E6: 1.05 | F6: 1.05 | G6: 1 | H6: 0.74 | I6: 0.05 | J6: 1.5 | K6: 2 | L6: 0 | M6: 1 | N6: 1 | O6: 1 | P6: 標準的な魔法型
A7: 魔法・速攻 | B7: Ranged | C7: 1 | D7: 0.95 | E7: 1.1 | F7: 1.1 | G7: 1.08 | H7: 0.8 | I7: 0.07 | J7: 1.55 | K7: 2.3 | L7: -0.03 | M7: 1 | N7: 1.1 | O7: 1 | P7: 高速の魔法型。攻速と射程が優秀
A8: 近接・耐久 | B8: Melee | C8: 1.2 | D8: 1.3 | E8: 0.85 | F8: 1 | G8: 0.8 | H8: 0.85 | I8: 0.08 | J8: 1.6 | K8: 2.8 | L8: 0.035 | M8: 1 | N8: 0.85 | O8: 1 | P8: HP・物防寄りの近接型
A9: 近接・重装 | B9: Melee | C9: 1.35 | D9: 1.4 | E9: 1 | F9: 1.05 | G9: 0.8 | H9: 0.9 | I9: 0.08 | J9: 1.6 | K9: 2.7 | L9: 0.065 | M9: 1 | N9: 0.9 | O9: 1 | P9: 高耐久の近接型。耐性も高め
A10: 魔法・守護 | B10: Ranged | C10: 1.5 | D10: 1.5 | E10: 1.4 | F10: 1.2 | G10: 1.2 | H10: 1 | I10: 0.1 | J10: 1.75 | K10: 2.4 | L10: 0.08 | M10: 1 | N10: 1.25 | O10: 1 | P10: HP・防御・耐性の高い魔法型
